[2024-11-26T23:11:46.723+0000] {processor.py:161} INFO - Started process (PID=180) to work on /opt/airflow/dags/postgres_to_bigquery_dag.py
[2024-11-26T23:11:46.726+0000] {processor.py:830} INFO - Processing file /opt/airflow/dags/postgres_to_bigquery_dag.py for tasks to queue
[2024-11-26T23:11:46.742+0000] {logging_mixin.py:188} INFO - [2024-11-26T23:11:46.741+0000] {dagbag.py:545} INFO - Filling up the DagBag from /opt/airflow/dags/postgres_to_bigquery_dag.py
[2024-11-26T23:11:52.736+0000] {logging_mixin.py:188} INFO - [2024-11-26T23:11:52.268+0000] {dagbag.py:355} ERROR - Failed to import: /opt/airflow/dags/postgres_to_bigquery_dag.py
Traceback (most recent call last):
  File "/home/airflow/.local/lib/python3.12/site-packages/airflow/models/dagbag.py", line 351, in parse
    loader.exec_module(new_module)
  File "<frozen importlib._bootstrap_external>", line 995, in exec_module
  File "<frozen importlib._bootstrap>", line 488, in _call_with_frames_removed
  File "/opt/airflow/dags/postgres_to_bigquery_dag.py", line 40, in <module>
    credentials = service_account.Credentials.from_service_account_file(f"/opt/airflow/data/key/{getenv('key')}")
                  ^^^^^^^^^^^^^^^^^^^^^^^^^^^^^^^^^^^^^^^^^^^^^^^^^^^^^^^^^^^^^^^^^^^^^^^^^^^^^^^^^^^^^^^^^^^^^^^
  File "/home/airflow/.local/lib/python3.12/site-packages/google/oauth2/service_account.py", line 259, in from_service_account_file
    info, signer = _service_account_info.from_filename(
                   ^^^^^^^^^^^^^^^^^^^^^^^^^^^^^^^^^^^^
  File "/home/airflow/.local/lib/python3.12/site-packages/google/auth/_service_account_info.py", line 78, in from_filename
    with io.open(filename, "r", encoding="utf-8") as json_file:
         ^^^^^^^^^^^^^^^^^^^^^^^^^^^^^^^^^^^^^^^^
FileNotFoundError: [Errno 2] No such file or directory: '/opt/airflow/data/key/None'
[2024-11-26T23:11:52.744+0000] {processor.py:842} WARNING - No viable dags retrieved from /opt/airflow/dags/postgres_to_bigquery_dag.py
[2024-11-26T23:11:52.807+0000] {processor.py:183} INFO - Processing /opt/airflow/dags/postgres_to_bigquery_dag.py took 6.120 seconds
[2024-11-26T23:12:23.086+0000] {processor.py:161} INFO - Started process (PID=205) to work on /opt/airflow/dags/postgres_to_bigquery_dag.py
[2024-11-26T23:12:23.087+0000] {processor.py:830} INFO - Processing file /opt/airflow/dags/postgres_to_bigquery_dag.py for tasks to queue
[2024-11-26T23:12:23.091+0000] {logging_mixin.py:188} INFO - [2024-11-26T23:12:23.090+0000] {dagbag.py:545} INFO - Filling up the DagBag from /opt/airflow/dags/postgres_to_bigquery_dag.py
[2024-11-26T23:12:24.426+0000] {logging_mixin.py:188} INFO - [2024-11-26T23:12:24.417+0000] {dagbag.py:355} ERROR - Failed to import: /opt/airflow/dags/postgres_to_bigquery_dag.py
Traceback (most recent call last):
  File "/home/airflow/.local/lib/python3.12/site-packages/airflow/models/dagbag.py", line 351, in parse
    loader.exec_module(new_module)
  File "<frozen importlib._bootstrap_external>", line 995, in exec_module
  File "<frozen importlib._bootstrap>", line 488, in _call_with_frames_removed
  File "/opt/airflow/dags/postgres_to_bigquery_dag.py", line 40, in <module>
    credentials = service_account.Credentials.from_service_account_file(f"/opt/airflow/data/key/{getenv('key')}")
                  ^^^^^^^^^^^^^^^^^^^^^^^^^^^^^^^^^^^^^^^^^^^^^^^^^^^^^^^^^^^^^^^^^^^^^^^^^^^^^^^^^^^^^^^^^^^^^^^
  File "/home/airflow/.local/lib/python3.12/site-packages/google/oauth2/service_account.py", line 259, in from_service_account_file
    info, signer = _service_account_info.from_filename(
                   ^^^^^^^^^^^^^^^^^^^^^^^^^^^^^^^^^^^^
  File "/home/airflow/.local/lib/python3.12/site-packages/google/auth/_service_account_info.py", line 78, in from_filename
    with io.open(filename, "r", encoding="utf-8") as json_file:
         ^^^^^^^^^^^^^^^^^^^^^^^^^^^^^^^^^^^^^^^^
FileNotFoundError: [Errno 2] No such file or directory: '/opt/airflow/data/key/None'
[2024-11-26T23:12:24.428+0000] {processor.py:842} WARNING - No viable dags retrieved from /opt/airflow/dags/postgres_to_bigquery_dag.py
[2024-11-26T23:12:24.481+0000] {processor.py:183} INFO - Processing /opt/airflow/dags/postgres_to_bigquery_dag.py took 1.408 seconds
[2024-11-26T23:12:54.743+0000] {processor.py:161} INFO - Started process (PID=229) to work on /opt/airflow/dags/postgres_to_bigquery_dag.py
[2024-11-26T23:12:54.744+0000] {processor.py:830} INFO - Processing file /opt/airflow/dags/postgres_to_bigquery_dag.py for tasks to queue
[2024-11-26T23:12:54.746+0000] {logging_mixin.py:188} INFO - [2024-11-26T23:12:54.746+0000] {dagbag.py:545} INFO - Filling up the DagBag from /opt/airflow/dags/postgres_to_bigquery_dag.py
[2024-11-26T23:12:55.754+0000] {logging_mixin.py:188} INFO - [2024-11-26T23:12:55.749+0000] {dagbag.py:355} ERROR - Failed to import: /opt/airflow/dags/postgres_to_bigquery_dag.py
Traceback (most recent call last):
  File "/home/airflow/.local/lib/python3.12/site-packages/airflow/models/dagbag.py", line 351, in parse
    loader.exec_module(new_module)
  File "<frozen importlib._bootstrap_external>", line 995, in exec_module
  File "<frozen importlib._bootstrap>", line 488, in _call_with_frames_removed
  File "/opt/airflow/dags/postgres_to_bigquery_dag.py", line 40, in <module>
    credentials = service_account.Credentials.from_service_account_file(f"/opt/airflow/data/key/{getenv('key')}")
                  ^^^^^^^^^^^^^^^^^^^^^^^^^^^^^^^^^^^^^^^^^^^^^^^^^^^^^^^^^^^^^^^^^^^^^^^^^^^^^^^^^^^^^^^^^^^^^^^
  File "/home/airflow/.local/lib/python3.12/site-packages/google/oauth2/service_account.py", line 259, in from_service_account_file
    info, signer = _service_account_info.from_filename(
                   ^^^^^^^^^^^^^^^^^^^^^^^^^^^^^^^^^^^^
  File "/home/airflow/.local/lib/python3.12/site-packages/google/auth/_service_account_info.py", line 78, in from_filename
    with io.open(filename, "r", encoding="utf-8") as json_file:
         ^^^^^^^^^^^^^^^^^^^^^^^^^^^^^^^^^^^^^^^^
FileNotFoundError: [Errno 2] No such file or directory: '/opt/airflow/data/key/None'
[2024-11-26T23:12:55.756+0000] {processor.py:842} WARNING - No viable dags retrieved from /opt/airflow/dags/postgres_to_bigquery_dag.py
[2024-11-26T23:12:55.791+0000] {processor.py:183} INFO - Processing /opt/airflow/dags/postgres_to_bigquery_dag.py took 1.056 seconds
[2024-11-26T23:13:26.311+0000] {processor.py:161} INFO - Started process (PID=248) to work on /opt/airflow/dags/postgres_to_bigquery_dag.py
[2024-11-26T23:13:26.312+0000] {processor.py:830} INFO - Processing file /opt/airflow/dags/postgres_to_bigquery_dag.py for tasks to queue
[2024-11-26T23:13:26.314+0000] {logging_mixin.py:188} INFO - [2024-11-26T23:13:26.314+0000] {dagbag.py:545} INFO - Filling up the DagBag from /opt/airflow/dags/postgres_to_bigquery_dag.py
[2024-11-26T23:13:27.644+0000] {logging_mixin.py:188} INFO - [2024-11-26T23:13:27.638+0000] {dagbag.py:355} ERROR - Failed to import: /opt/airflow/dags/postgres_to_bigquery_dag.py
Traceback (most recent call last):
  File "/home/airflow/.local/lib/python3.12/site-packages/airflow/models/dagbag.py", line 351, in parse
    loader.exec_module(new_module)
  File "<frozen importlib._bootstrap_external>", line 995, in exec_module
  File "<frozen importlib._bootstrap>", line 488, in _call_with_frames_removed
  File "/opt/airflow/dags/postgres_to_bigquery_dag.py", line 40, in <module>
    credentials = service_account.Credentials.from_service_account_file(f"/opt/airflow/data/key/{getenv('key')}")
                  ^^^^^^^^^^^^^^^^^^^^^^^^^^^^^^^^^^^^^^^^^^^^^^^^^^^^^^^^^^^^^^^^^^^^^^^^^^^^^^^^^^^^^^^^^^^^^^^
  File "/home/airflow/.local/lib/python3.12/site-packages/google/oauth2/service_account.py", line 259, in from_service_account_file
    info, signer = _service_account_info.from_filename(
                   ^^^^^^^^^^^^^^^^^^^^^^^^^^^^^^^^^^^^
  File "/home/airflow/.local/lib/python3.12/site-packages/google/auth/_service_account_info.py", line 78, in from_filename
    with io.open(filename, "r", encoding="utf-8") as json_file:
         ^^^^^^^^^^^^^^^^^^^^^^^^^^^^^^^^^^^^^^^^
FileNotFoundError: [Errno 2] No such file or directory: '/opt/airflow/data/key/None'
[2024-11-26T23:13:27.646+0000] {processor.py:842} WARNING - No viable dags retrieved from /opt/airflow/dags/postgres_to_bigquery_dag.py
[2024-11-26T23:13:27.681+0000] {processor.py:183} INFO - Processing /opt/airflow/dags/postgres_to_bigquery_dag.py took 1.377 seconds
[2024-11-26T23:13:58.159+0000] {processor.py:161} INFO - Started process (PID=266) to work on /opt/airflow/dags/postgres_to_bigquery_dag.py
[2024-11-26T23:13:58.164+0000] {processor.py:830} INFO - Processing file /opt/airflow/dags/postgres_to_bigquery_dag.py for tasks to queue
[2024-11-26T23:13:58.178+0000] {logging_mixin.py:188} INFO - [2024-11-26T23:13:58.177+0000] {dagbag.py:545} INFO - Filling up the DagBag from /opt/airflow/dags/postgres_to_bigquery_dag.py
[2024-11-26T23:13:59.524+0000] {logging_mixin.py:188} INFO - [2024-11-26T23:13:59.518+0000] {dagbag.py:355} ERROR - Failed to import: /opt/airflow/dags/postgres_to_bigquery_dag.py
Traceback (most recent call last):
  File "/home/airflow/.local/lib/python3.12/site-packages/airflow/models/dagbag.py", line 351, in parse
    loader.exec_module(new_module)
  File "<frozen importlib._bootstrap_external>", line 995, in exec_module
  File "<frozen importlib._bootstrap>", line 488, in _call_with_frames_removed
  File "/opt/airflow/dags/postgres_to_bigquery_dag.py", line 40, in <module>
    credentials = service_account.Credentials.from_service_account_file(f"/opt/airflow/data/key/{getenv('key')}")
                  ^^^^^^^^^^^^^^^^^^^^^^^^^^^^^^^^^^^^^^^^^^^^^^^^^^^^^^^^^^^^^^^^^^^^^^^^^^^^^^^^^^^^^^^^^^^^^^^
  File "/home/airflow/.local/lib/python3.12/site-packages/google/oauth2/service_account.py", line 259, in from_service_account_file
    info, signer = _service_account_info.from_filename(
                   ^^^^^^^^^^^^^^^^^^^^^^^^^^^^^^^^^^^^
  File "/home/airflow/.local/lib/python3.12/site-packages/google/auth/_service_account_info.py", line 78, in from_filename
    with io.open(filename, "r", encoding="utf-8") as json_file:
         ^^^^^^^^^^^^^^^^^^^^^^^^^^^^^^^^^^^^^^^^
FileNotFoundError: [Errno 2] No such file or directory: '/opt/airflow/data/key/None'
[2024-11-26T23:13:59.525+0000] {processor.py:842} WARNING - No viable dags retrieved from /opt/airflow/dags/postgres_to_bigquery_dag.py
[2024-11-26T23:13:59.551+0000] {processor.py:183} INFO - Processing /opt/airflow/dags/postgres_to_bigquery_dag.py took 1.414 seconds
[2024-11-26T23:14:29.883+0000] {processor.py:161} INFO - Started process (PID=284) to work on /opt/airflow/dags/postgres_to_bigquery_dag.py
[2024-11-26T23:14:29.884+0000] {processor.py:830} INFO - Processing file /opt/airflow/dags/postgres_to_bigquery_dag.py for tasks to queue
[2024-11-26T23:14:29.887+0000] {logging_mixin.py:188} INFO - [2024-11-26T23:14:29.886+0000] {dagbag.py:545} INFO - Filling up the DagBag from /opt/airflow/dags/postgres_to_bigquery_dag.py
[2024-11-26T23:14:31.027+0000] {logging_mixin.py:188} INFO - [2024-11-26T23:14:31.019+0000] {dagbag.py:355} ERROR - Failed to import: /opt/airflow/dags/postgres_to_bigquery_dag.py
Traceback (most recent call last):
  File "/home/airflow/.local/lib/python3.12/site-packages/airflow/models/dagbag.py", line 351, in parse
    loader.exec_module(new_module)
  File "<frozen importlib._bootstrap_external>", line 995, in exec_module
  File "<frozen importlib._bootstrap>", line 488, in _call_with_frames_removed
  File "/opt/airflow/dags/postgres_to_bigquery_dag.py", line 40, in <module>
    credentials = service_account.Credentials.from_service_account_file(f"/opt/airflow/data/key/{getenv('key')}")
                  ^^^^^^^^^^^^^^^^^^^^^^^^^^^^^^^^^^^^^^^^^^^^^^^^^^^^^^^^^^^^^^^^^^^^^^^^^^^^^^^^^^^^^^^^^^^^^^^
  File "/home/airflow/.local/lib/python3.12/site-packages/google/oauth2/service_account.py", line 259, in from_service_account_file
    info, signer = _service_account_info.from_filename(
                   ^^^^^^^^^^^^^^^^^^^^^^^^^^^^^^^^^^^^
  File "/home/airflow/.local/lib/python3.12/site-packages/google/auth/_service_account_info.py", line 78, in from_filename
    with io.open(filename, "r", encoding="utf-8") as json_file:
         ^^^^^^^^^^^^^^^^^^^^^^^^^^^^^^^^^^^^^^^^
FileNotFoundError: [Errno 2] No such file or directory: '/opt/airflow/data/key/None'
[2024-11-26T23:14:31.029+0000] {processor.py:842} WARNING - No viable dags retrieved from /opt/airflow/dags/postgres_to_bigquery_dag.py
[2024-11-26T23:14:31.084+0000] {processor.py:183} INFO - Processing /opt/airflow/dags/postgres_to_bigquery_dag.py took 1.209 seconds
[2024-11-26T23:15:01.447+0000] {processor.py:161} INFO - Started process (PID=302) to work on /opt/airflow/dags/postgres_to_bigquery_dag.py
[2024-11-26T23:15:01.449+0000] {processor.py:830} INFO - Processing file /opt/airflow/dags/postgres_to_bigquery_dag.py for tasks to queue
[2024-11-26T23:15:01.463+0000] {logging_mixin.py:188} INFO - [2024-11-26T23:15:01.462+0000] {dagbag.py:545} INFO - Filling up the DagBag from /opt/airflow/dags/postgres_to_bigquery_dag.py
[2024-11-26T23:15:03.079+0000] {logging_mixin.py:188} INFO - [2024-11-26T23:15:03.070+0000] {dagbag.py:355} ERROR - Failed to import: /opt/airflow/dags/postgres_to_bigquery_dag.py
Traceback (most recent call last):
  File "/home/airflow/.local/lib/python3.12/site-packages/airflow/models/dagbag.py", line 351, in parse
    loader.exec_module(new_module)
  File "<frozen importlib._bootstrap_external>", line 995, in exec_module
  File "<frozen importlib._bootstrap>", line 488, in _call_with_frames_removed
  File "/opt/airflow/dags/postgres_to_bigquery_dag.py", line 40, in <module>
    credentials = service_account.Credentials.from_service_account_file(f"/opt/airflow/data/key/{getenv('key')}")
                  ^^^^^^^^^^^^^^^^^^^^^^^^^^^^^^^^^^^^^^^^^^^^^^^^^^^^^^^^^^^^^^^^^^^^^^^^^^^^^^^^^^^^^^^^^^^^^^^
  File "/home/airflow/.local/lib/python3.12/site-packages/google/oauth2/service_account.py", line 259, in from_service_account_file
    info, signer = _service_account_info.from_filename(
                   ^^^^^^^^^^^^^^^^^^^^^^^^^^^^^^^^^^^^
  File "/home/airflow/.local/lib/python3.12/site-packages/google/auth/_service_account_info.py", line 78, in from_filename
    with io.open(filename, "r", encoding="utf-8") as json_file:
         ^^^^^^^^^^^^^^^^^^^^^^^^^^^^^^^^^^^^^^^^
FileNotFoundError: [Errno 2] No such file or directory: '/opt/airflow/data/key/None'
[2024-11-26T23:15:03.080+0000] {processor.py:842} WARNING - No viable dags retrieved from /opt/airflow/dags/postgres_to_bigquery_dag.py
[2024-11-26T23:15:03.118+0000] {processor.py:183} INFO - Processing /opt/airflow/dags/postgres_to_bigquery_dag.py took 1.693 seconds
[2024-11-26T23:15:33.494+0000] {processor.py:161} INFO - Started process (PID=321) to work on /opt/airflow/dags/postgres_to_bigquery_dag.py
[2024-11-26T23:15:33.495+0000] {processor.py:830} INFO - Processing file /opt/airflow/dags/postgres_to_bigquery_dag.py for tasks to queue
[2024-11-26T23:15:33.498+0000] {logging_mixin.py:188} INFO - [2024-11-26T23:15:33.497+0000] {dagbag.py:545} INFO - Filling up the DagBag from /opt/airflow/dags/postgres_to_bigquery_dag.py
[2024-11-26T23:15:35.104+0000] {logging_mixin.py:188} INFO - [2024-11-26T23:15:35.078+0000] {dagbag.py:355} ERROR - Failed to import: /opt/airflow/dags/postgres_to_bigquery_dag.py
Traceback (most recent call last):
  File "/home/airflow/.local/lib/python3.12/site-packages/airflow/models/dagbag.py", line 351, in parse
    loader.exec_module(new_module)
  File "<frozen importlib._bootstrap_external>", line 995, in exec_module
  File "<frozen importlib._bootstrap>", line 488, in _call_with_frames_removed
  File "/opt/airflow/dags/postgres_to_bigquery_dag.py", line 40, in <module>
    credentials = service_account.Credentials.from_service_account_file(f"/opt/airflow/data/key/{getenv('key')}")
                  ^^^^^^^^^^^^^^^^^^^^^^^^^^^^^^^^^^^^^^^^^^^^^^^^^^^^^^^^^^^^^^^^^^^^^^^^^^^^^^^^^^^^^^^^^^^^^^^
  File "/home/airflow/.local/lib/python3.12/site-packages/google/oauth2/service_account.py", line 259, in from_service_account_file
    info, signer = _service_account_info.from_filename(
                   ^^^^^^^^^^^^^^^^^^^^^^^^^^^^^^^^^^^^
  File "/home/airflow/.local/lib/python3.12/site-packages/google/auth/_service_account_info.py", line 78, in from_filename
    with io.open(filename, "r", encoding="utf-8") as json_file:
         ^^^^^^^^^^^^^^^^^^^^^^^^^^^^^^^^^^^^^^^^
FileNotFoundError: [Errno 2] No such file or directory: '/opt/airflow/data/key/None'
[2024-11-26T23:15:35.106+0000] {processor.py:842} WARNING - No viable dags retrieved from /opt/airflow/dags/postgres_to_bigquery_dag.py
[2024-11-26T23:15:35.160+0000] {processor.py:183} INFO - Processing /opt/airflow/dags/postgres_to_bigquery_dag.py took 1.675 seconds
[2024-11-26T23:16:05.726+0000] {processor.py:161} INFO - Started process (PID=339) to work on /opt/airflow/dags/postgres_to_bigquery_dag.py
[2024-11-26T23:16:05.728+0000] {processor.py:830} INFO - Processing file /opt/airflow/dags/postgres_to_bigquery_dag.py for tasks to queue
[2024-11-26T23:16:05.731+0000] {logging_mixin.py:188} INFO - [2024-11-26T23:16:05.730+0000] {dagbag.py:545} INFO - Filling up the DagBag from /opt/airflow/dags/postgres_to_bigquery_dag.py
[2024-11-26T23:16:06.813+0000] {logging_mixin.py:188} INFO - [2024-11-26T23:16:06.805+0000] {dagbag.py:355} ERROR - Failed to import: /opt/airflow/dags/postgres_to_bigquery_dag.py
Traceback (most recent call last):
  File "/home/airflow/.local/lib/python3.12/site-packages/airflow/models/dagbag.py", line 351, in parse
    loader.exec_module(new_module)
  File "<frozen importlib._bootstrap_external>", line 995, in exec_module
  File "<frozen importlib._bootstrap>", line 488, in _call_with_frames_removed
  File "/opt/airflow/dags/postgres_to_bigquery_dag.py", line 40, in <module>
    credentials = service_account.Credentials.from_service_account_file(f"/opt/airflow/data/key/{getenv('key')}")
                  ^^^^^^^^^^^^^^^^^^^^^^^^^^^^^^^^^^^^^^^^^^^^^^^^^^^^^^^^^^^^^^^^^^^^^^^^^^^^^^^^^^^^^^^^^^^^^^^
  File "/home/airflow/.local/lib/python3.12/site-packages/google/oauth2/service_account.py", line 259, in from_service_account_file
    info, signer = _service_account_info.from_filename(
                   ^^^^^^^^^^^^^^^^^^^^^^^^^^^^^^^^^^^^
  File "/home/airflow/.local/lib/python3.12/site-packages/google/auth/_service_account_info.py", line 78, in from_filename
    with io.open(filename, "r", encoding="utf-8") as json_file:
         ^^^^^^^^^^^^^^^^^^^^^^^^^^^^^^^^^^^^^^^^
FileNotFoundError: [Errno 2] No such file or directory: '/opt/airflow/data/key/None'
[2024-11-26T23:16:06.815+0000] {processor.py:842} WARNING - No viable dags retrieved from /opt/airflow/dags/postgres_to_bigquery_dag.py
[2024-11-26T23:16:06.853+0000] {processor.py:183} INFO - Processing /opt/airflow/dags/postgres_to_bigquery_dag.py took 1.136 seconds
[2024-11-26T23:16:37.254+0000] {processor.py:161} INFO - Started process (PID=357) to work on /opt/airflow/dags/postgres_to_bigquery_dag.py
[2024-11-26T23:16:37.256+0000] {processor.py:830} INFO - Processing file /opt/airflow/dags/postgres_to_bigquery_dag.py for tasks to queue
[2024-11-26T23:16:37.259+0000] {logging_mixin.py:188} INFO - [2024-11-26T23:16:37.258+0000] {dagbag.py:545} INFO - Filling up the DagBag from /opt/airflow/dags/postgres_to_bigquery_dag.py
[2024-11-26T23:16:38.634+0000] {logging_mixin.py:188} INFO - [2024-11-26T23:16:38.629+0000] {dagbag.py:355} ERROR - Failed to import: /opt/airflow/dags/postgres_to_bigquery_dag.py
Traceback (most recent call last):
  File "/home/airflow/.local/lib/python3.12/site-packages/airflow/models/dagbag.py", line 351, in parse
    loader.exec_module(new_module)
  File "<frozen importlib._bootstrap_external>", line 995, in exec_module
  File "<frozen importlib._bootstrap>", line 488, in _call_with_frames_removed
  File "/opt/airflow/dags/postgres_to_bigquery_dag.py", line 40, in <module>
    credentials = service_account.Credentials.from_service_account_file(f"/opt/airflow/data/key/{getenv('key')}")
                  ^^^^^^^^^^^^^^^^^^^^^^^^^^^^^^^^^^^^^^^^^^^^^^^^^^^^^^^^^^^^^^^^^^^^^^^^^^^^^^^^^^^^^^^^^^^^^^^
  File "/home/airflow/.local/lib/python3.12/site-packages/google/oauth2/service_account.py", line 259, in from_service_account_file
    info, signer = _service_account_info.from_filename(
                   ^^^^^^^^^^^^^^^^^^^^^^^^^^^^^^^^^^^^
  File "/home/airflow/.local/lib/python3.12/site-packages/google/auth/_service_account_info.py", line 78, in from_filename
    with io.open(filename, "r", encoding="utf-8") as json_file:
         ^^^^^^^^^^^^^^^^^^^^^^^^^^^^^^^^^^^^^^^^
FileNotFoundError: [Errno 2] No such file or directory: '/opt/airflow/data/key/None'
[2024-11-26T23:16:38.635+0000] {processor.py:842} WARNING - No viable dags retrieved from /opt/airflow/dags/postgres_to_bigquery_dag.py
[2024-11-26T23:16:38.653+0000] {processor.py:183} INFO - Processing /opt/airflow/dags/postgres_to_bigquery_dag.py took 1.411 seconds
[2024-11-26T23:17:08.990+0000] {processor.py:161} INFO - Started process (PID=375) to work on /opt/airflow/dags/postgres_to_bigquery_dag.py
[2024-11-26T23:17:08.993+0000] {processor.py:830} INFO - Processing file /opt/airflow/dags/postgres_to_bigquery_dag.py for tasks to queue
[2024-11-26T23:17:08.997+0000] {logging_mixin.py:188} INFO - [2024-11-26T23:17:08.996+0000] {dagbag.py:545} INFO - Filling up the DagBag from /opt/airflow/dags/postgres_to_bigquery_dag.py
[2024-11-26T23:17:11.586+0000] {logging_mixin.py:188} INFO - [2024-11-26T23:17:11.578+0000] {dagbag.py:355} ERROR - Failed to import: /opt/airflow/dags/postgres_to_bigquery_dag.py
Traceback (most recent call last):
  File "/home/airflow/.local/lib/python3.12/site-packages/airflow/models/dagbag.py", line 351, in parse
    loader.exec_module(new_module)
  File "<frozen importlib._bootstrap_external>", line 995, in exec_module
  File "<frozen importlib._bootstrap>", line 488, in _call_with_frames_removed
  File "/opt/airflow/dags/postgres_to_bigquery_dag.py", line 40, in <module>
    credentials = service_account.Credentials.from_service_account_file(f"/opt/airflow/data/key/{getenv('key')}")
                  ^^^^^^^^^^^^^^^^^^^^^^^^^^^^^^^^^^^^^^^^^^^^^^^^^^^^^^^^^^^^^^^^^^^^^^^^^^^^^^^^^^^^^^^^^^^^^^^
  File "/home/airflow/.local/lib/python3.12/site-packages/google/oauth2/service_account.py", line 259, in from_service_account_file
    info, signer = _service_account_info.from_filename(
                   ^^^^^^^^^^^^^^^^^^^^^^^^^^^^^^^^^^^^
  File "/home/airflow/.local/lib/python3.12/site-packages/google/auth/_service_account_info.py", line 78, in from_filename
    with io.open(filename, "r", encoding="utf-8") as json_file:
         ^^^^^^^^^^^^^^^^^^^^^^^^^^^^^^^^^^^^^^^^
FileNotFoundError: [Errno 2] No such file or directory: '/opt/airflow/data/key/None'
[2024-11-26T23:17:11.588+0000] {processor.py:842} WARNING - No viable dags retrieved from /opt/airflow/dags/postgres_to_bigquery_dag.py
[2024-11-26T23:17:11.669+0000] {processor.py:183} INFO - Processing /opt/airflow/dags/postgres_to_bigquery_dag.py took 2.697 seconds
[2024-11-26T23:17:42.059+0000] {processor.py:161} INFO - Started process (PID=393) to work on /opt/airflow/dags/postgres_to_bigquery_dag.py
[2024-11-26T23:17:42.060+0000] {processor.py:830} INFO - Processing file /opt/airflow/dags/postgres_to_bigquery_dag.py for tasks to queue
[2024-11-26T23:17:42.062+0000] {logging_mixin.py:188} INFO - [2024-11-26T23:17:42.062+0000] {dagbag.py:545} INFO - Filling up the DagBag from /opt/airflow/dags/postgres_to_bigquery_dag.py
[2024-11-26T23:17:43.012+0000] {logging_mixin.py:188} INFO - [2024-11-26T23:17:43.003+0000] {dagbag.py:355} ERROR - Failed to import: /opt/airflow/dags/postgres_to_bigquery_dag.py
Traceback (most recent call last):
  File "/home/airflow/.local/lib/python3.12/site-packages/airflow/models/dagbag.py", line 351, in parse
    loader.exec_module(new_module)
  File "<frozen importlib._bootstrap_external>", line 995, in exec_module
  File "<frozen importlib._bootstrap>", line 488, in _call_with_frames_removed
  File "/opt/airflow/dags/postgres_to_bigquery_dag.py", line 40, in <module>
    credentials = service_account.Credentials.from_service_account_file(f"/opt/airflow/data/key/{getenv('key')}")
                  ^^^^^^^^^^^^^^^^^^^^^^^^^^^^^^^^^^^^^^^^^^^^^^^^^^^^^^^^^^^^^^^^^^^^^^^^^^^^^^^^^^^^^^^^^^^^^^^
  File "/home/airflow/.local/lib/python3.12/site-packages/google/oauth2/service_account.py", line 259, in from_service_account_file
    info, signer = _service_account_info.from_filename(
                   ^^^^^^^^^^^^^^^^^^^^^^^^^^^^^^^^^^^^
  File "/home/airflow/.local/lib/python3.12/site-packages/google/auth/_service_account_info.py", line 78, in from_filename
    with io.open(filename, "r", encoding="utf-8") as json_file:
         ^^^^^^^^^^^^^^^^^^^^^^^^^^^^^^^^^^^^^^^^
FileNotFoundError: [Errno 2] No such file or directory: '/opt/airflow/data/key/None'
[2024-11-26T23:17:43.014+0000] {processor.py:842} WARNING - No viable dags retrieved from /opt/airflow/dags/postgres_to_bigquery_dag.py
[2024-11-26T23:17:43.048+0000] {processor.py:183} INFO - Processing /opt/airflow/dags/postgres_to_bigquery_dag.py took 0.996 seconds
[2024-11-26T23:18:13.232+0000] {processor.py:161} INFO - Started process (PID=411) to work on /opt/airflow/dags/postgres_to_bigquery_dag.py
[2024-11-26T23:18:13.234+0000] {processor.py:830} INFO - Processing file /opt/airflow/dags/postgres_to_bigquery_dag.py for tasks to queue
[2024-11-26T23:18:13.238+0000] {logging_mixin.py:188} INFO - [2024-11-26T23:18:13.237+0000] {dagbag.py:545} INFO - Filling up the DagBag from /opt/airflow/dags/postgres_to_bigquery_dag.py
[2024-11-26T23:18:14.309+0000] {logging_mixin.py:188} INFO - [2024-11-26T23:18:14.303+0000] {dagbag.py:355} ERROR - Failed to import: /opt/airflow/dags/postgres_to_bigquery_dag.py
Traceback (most recent call last):
  File "/home/airflow/.local/lib/python3.12/site-packages/airflow/models/dagbag.py", line 351, in parse
    loader.exec_module(new_module)
  File "<frozen importlib._bootstrap_external>", line 995, in exec_module
  File "<frozen importlib._bootstrap>", line 488, in _call_with_frames_removed
  File "/opt/airflow/dags/postgres_to_bigquery_dag.py", line 40, in <module>
    credentials = service_account.Credentials.from_service_account_file(f"/opt/airflow/data/key/{getenv('key')}")
                  ^^^^^^^^^^^^^^^^^^^^^^^^^^^^^^^^^^^^^^^^^^^^^^^^^^^^^^^^^^^^^^^^^^^^^^^^^^^^^^^^^^^^^^^^^^^^^^^
  File "/home/airflow/.local/lib/python3.12/site-packages/google/oauth2/service_account.py", line 259, in from_service_account_file
    info, signer = _service_account_info.from_filename(
                   ^^^^^^^^^^^^^^^^^^^^^^^^^^^^^^^^^^^^
  File "/home/airflow/.local/lib/python3.12/site-packages/google/auth/_service_account_info.py", line 78, in from_filename
    with io.open(filename, "r", encoding="utf-8") as json_file:
         ^^^^^^^^^^^^^^^^^^^^^^^^^^^^^^^^^^^^^^^^
FileNotFoundError: [Errno 2] No such file or directory: '/opt/airflow/data/key/None'
[2024-11-26T23:18:14.310+0000] {processor.py:842} WARNING - No viable dags retrieved from /opt/airflow/dags/postgres_to_bigquery_dag.py
[2024-11-26T23:18:14.340+0000] {processor.py:183} INFO - Processing /opt/airflow/dags/postgres_to_bigquery_dag.py took 1.120 seconds
[2024-11-26T23:18:44.657+0000] {processor.py:161} INFO - Started process (PID=429) to work on /opt/airflow/dags/postgres_to_bigquery_dag.py
[2024-11-26T23:18:44.658+0000] {processor.py:830} INFO - Processing file /opt/airflow/dags/postgres_to_bigquery_dag.py for tasks to queue
[2024-11-26T23:18:44.660+0000] {logging_mixin.py:188} INFO - [2024-11-26T23:18:44.660+0000] {dagbag.py:545} INFO - Filling up the DagBag from /opt/airflow/dags/postgres_to_bigquery_dag.py
[2024-11-26T23:18:45.731+0000] {logging_mixin.py:188} INFO - [2024-11-26T23:18:45.726+0000] {dagbag.py:355} ERROR - Failed to import: /opt/airflow/dags/postgres_to_bigquery_dag.py
Traceback (most recent call last):
  File "/home/airflow/.local/lib/python3.12/site-packages/airflow/models/dagbag.py", line 351, in parse
    loader.exec_module(new_module)
  File "<frozen importlib._bootstrap_external>", line 995, in exec_module
  File "<frozen importlib._bootstrap>", line 488, in _call_with_frames_removed
  File "/opt/airflow/dags/postgres_to_bigquery_dag.py", line 40, in <module>
    credentials = service_account.Credentials.from_service_account_file(f"/opt/airflow/data/key/{getenv('key')}")
                  ^^^^^^^^^^^^^^^^^^^^^^^^^^^^^^^^^^^^^^^^^^^^^^^^^^^^^^^^^^^^^^^^^^^^^^^^^^^^^^^^^^^^^^^^^^^^^^^
  File "/home/airflow/.local/lib/python3.12/site-packages/google/oauth2/service_account.py", line 259, in from_service_account_file
    info, signer = _service_account_info.from_filename(
                   ^^^^^^^^^^^^^^^^^^^^^^^^^^^^^^^^^^^^
  File "/home/airflow/.local/lib/python3.12/site-packages/google/auth/_service_account_info.py", line 78, in from_filename
    with io.open(filename, "r", encoding="utf-8") as json_file:
         ^^^^^^^^^^^^^^^^^^^^^^^^^^^^^^^^^^^^^^^^
FileNotFoundError: [Errno 2] No such file or directory: '/opt/airflow/data/key/None'
[2024-11-26T23:18:45.732+0000] {processor.py:842} WARNING - No viable dags retrieved from /opt/airflow/dags/postgres_to_bigquery_dag.py
[2024-11-26T23:18:45.758+0000] {processor.py:183} INFO - Processing /opt/airflow/dags/postgres_to_bigquery_dag.py took 1.109 seconds
[2024-11-26T23:19:16.138+0000] {processor.py:161} INFO - Started process (PID=447) to work on /opt/airflow/dags/postgres_to_bigquery_dag.py
[2024-11-26T23:19:16.141+0000] {processor.py:830} INFO - Processing file /opt/airflow/dags/postgres_to_bigquery_dag.py for tasks to queue
[2024-11-26T23:19:16.144+0000] {logging_mixin.py:188} INFO - [2024-11-26T23:19:16.143+0000] {dagbag.py:545} INFO - Filling up the DagBag from /opt/airflow/dags/postgres_to_bigquery_dag.py
[2024-11-26T23:19:17.328+0000] {logging_mixin.py:188} INFO - [2024-11-26T23:19:17.321+0000] {dagbag.py:355} ERROR - Failed to import: /opt/airflow/dags/postgres_to_bigquery_dag.py
Traceback (most recent call last):
  File "/home/airflow/.local/lib/python3.12/site-packages/airflow/models/dagbag.py", line 351, in parse
    loader.exec_module(new_module)
  File "<frozen importlib._bootstrap_external>", line 995, in exec_module
  File "<frozen importlib._bootstrap>", line 488, in _call_with_frames_removed
  File "/opt/airflow/dags/postgres_to_bigquery_dag.py", line 40, in <module>
    credentials = service_account.Credentials.from_service_account_file(f"/opt/airflow/data/key/{getenv('key')}")
                  ^^^^^^^^^^^^^^^^^^^^^^^^^^^^^^^^^^^^^^^^^^^^^^^^^^^^^^^^^^^^^^^^^^^^^^^^^^^^^^^^^^^^^^^^^^^^^^^
  File "/home/airflow/.local/lib/python3.12/site-packages/google/oauth2/service_account.py", line 259, in from_service_account_file
    info, signer = _service_account_info.from_filename(
                   ^^^^^^^^^^^^^^^^^^^^^^^^^^^^^^^^^^^^
  File "/home/airflow/.local/lib/python3.12/site-packages/google/auth/_service_account_info.py", line 78, in from_filename
    with io.open(filename, "r", encoding="utf-8") as json_file:
         ^^^^^^^^^^^^^^^^^^^^^^^^^^^^^^^^^^^^^^^^
FileNotFoundError: [Errno 2] No such file or directory: '/opt/airflow/data/key/None'
[2024-11-26T23:19:17.329+0000] {processor.py:842} WARNING - No viable dags retrieved from /opt/airflow/dags/postgres_to_bigquery_dag.py
[2024-11-26T23:19:17.355+0000] {processor.py:183} INFO - Processing /opt/airflow/dags/postgres_to_bigquery_dag.py took 1.230 seconds
[2024-11-26T23:19:47.589+0000] {processor.py:161} INFO - Started process (PID=465) to work on /opt/airflow/dags/postgres_to_bigquery_dag.py
[2024-11-26T23:19:47.590+0000] {processor.py:830} INFO - Processing file /opt/airflow/dags/postgres_to_bigquery_dag.py for tasks to queue
[2024-11-26T23:19:47.593+0000] {logging_mixin.py:188} INFO - [2024-11-26T23:19:47.592+0000] {dagbag.py:545} INFO - Filling up the DagBag from /opt/airflow/dags/postgres_to_bigquery_dag.py
[2024-11-26T23:19:49.008+0000] {logging_mixin.py:188} INFO - [2024-11-26T23:19:48.998+0000] {dagbag.py:355} ERROR - Failed to import: /opt/airflow/dags/postgres_to_bigquery_dag.py
Traceback (most recent call last):
  File "/home/airflow/.local/lib/python3.12/site-packages/airflow/models/dagbag.py", line 351, in parse
    loader.exec_module(new_module)
  File "<frozen importlib._bootstrap_external>", line 995, in exec_module
  File "<frozen importlib._bootstrap>", line 488, in _call_with_frames_removed
  File "/opt/airflow/dags/postgres_to_bigquery_dag.py", line 40, in <module>
    credentials = service_account.Credentials.from_service_account_file(f"/opt/airflow/data/key/{getenv('key')}")
                  ^^^^^^^^^^^^^^^^^^^^^^^^^^^^^^^^^^^^^^^^^^^^^^^^^^^^^^^^^^^^^^^^^^^^^^^^^^^^^^^^^^^^^^^^^^^^^^^
  File "/home/airflow/.local/lib/python3.12/site-packages/google/oauth2/service_account.py", line 259, in from_service_account_file
    info, signer = _service_account_info.from_filename(
                   ^^^^^^^^^^^^^^^^^^^^^^^^^^^^^^^^^^^^
  File "/home/airflow/.local/lib/python3.12/site-packages/google/auth/_service_account_info.py", line 78, in from_filename
    with io.open(filename, "r", encoding="utf-8") as json_file:
         ^^^^^^^^^^^^^^^^^^^^^^^^^^^^^^^^^^^^^^^^
FileNotFoundError: [Errno 2] No such file or directory: '/opt/airflow/data/key/None'
[2024-11-26T23:19:49.013+0000] {processor.py:842} WARNING - No viable dags retrieved from /opt/airflow/dags/postgres_to_bigquery_dag.py
[2024-11-26T23:19:49.050+0000] {processor.py:183} INFO - Processing /opt/airflow/dags/postgres_to_bigquery_dag.py took 1.468 seconds
[2024-11-26T23:20:19.927+0000] {processor.py:161} INFO - Started process (PID=483) to work on /opt/airflow/dags/postgres_to_bigquery_dag.py
[2024-11-26T23:20:19.928+0000] {processor.py:830} INFO - Processing file /opt/airflow/dags/postgres_to_bigquery_dag.py for tasks to queue
[2024-11-26T23:20:19.936+0000] {logging_mixin.py:188} INFO - [2024-11-26T23:20:19.934+0000] {dagbag.py:545} INFO - Filling up the DagBag from /opt/airflow/dags/postgres_to_bigquery_dag.py
[2024-11-26T23:20:22.108+0000] {logging_mixin.py:188} INFO - [2024-11-26T23:20:22.094+0000] {dagbag.py:355} ERROR - Failed to import: /opt/airflow/dags/postgres_to_bigquery_dag.py
Traceback (most recent call last):
  File "/home/airflow/.local/lib/python3.12/site-packages/airflow/models/dagbag.py", line 351, in parse
    loader.exec_module(new_module)
  File "<frozen importlib._bootstrap_external>", line 995, in exec_module
  File "<frozen importlib._bootstrap>", line 488, in _call_with_frames_removed
  File "/opt/airflow/dags/postgres_to_bigquery_dag.py", line 40, in <module>
    credentials = service_account.Credentials.from_service_account_file(f"/opt/airflow/data/key/{getenv('key')}")
                  ^^^^^^^^^^^^^^^^^^^^^^^^^^^^^^^^^^^^^^^^^^^^^^^^^^^^^^^^^^^^^^^^^^^^^^^^^^^^^^^^^^^^^^^^^^^^^^^
  File "/home/airflow/.local/lib/python3.12/site-packages/google/oauth2/service_account.py", line 259, in from_service_account_file
    info, signer = _service_account_info.from_filename(
                   ^^^^^^^^^^^^^^^^^^^^^^^^^^^^^^^^^^^^
  File "/home/airflow/.local/lib/python3.12/site-packages/google/auth/_service_account_info.py", line 78, in from_filename
    with io.open(filename, "r", encoding="utf-8") as json_file:
         ^^^^^^^^^^^^^^^^^^^^^^^^^^^^^^^^^^^^^^^^
FileNotFoundError: [Errno 2] No such file or directory: '/opt/airflow/data/key/None'
[2024-11-26T23:20:22.110+0000] {processor.py:842} WARNING - No viable dags retrieved from /opt/airflow/dags/postgres_to_bigquery_dag.py
[2024-11-26T23:20:22.192+0000] {processor.py:183} INFO - Processing /opt/airflow/dags/postgres_to_bigquery_dag.py took 2.287 seconds
[2024-11-26T23:20:52.902+0000] {processor.py:161} INFO - Started process (PID=501) to work on /opt/airflow/dags/postgres_to_bigquery_dag.py
[2024-11-26T23:20:52.904+0000] {processor.py:830} INFO - Processing file /opt/airflow/dags/postgres_to_bigquery_dag.py for tasks to queue
[2024-11-26T23:20:52.908+0000] {logging_mixin.py:188} INFO - [2024-11-26T23:20:52.907+0000] {dagbag.py:545} INFO - Filling up the DagBag from /opt/airflow/dags/postgres_to_bigquery_dag.py
[2024-11-26T23:20:54.064+0000] {logging_mixin.py:188} INFO - [2024-11-26T23:20:54.056+0000] {dagbag.py:355} ERROR - Failed to import: /opt/airflow/dags/postgres_to_bigquery_dag.py
Traceback (most recent call last):
  File "/home/airflow/.local/lib/python3.12/site-packages/airflow/models/dagbag.py", line 351, in parse
    loader.exec_module(new_module)
  File "<frozen importlib._bootstrap_external>", line 995, in exec_module
  File "<frozen importlib._bootstrap>", line 488, in _call_with_frames_removed
  File "/opt/airflow/dags/postgres_to_bigquery_dag.py", line 40, in <module>
    credentials = service_account.Credentials.from_service_account_file(f"/opt/airflow/data/key/{getenv('key')}")
                  ^^^^^^^^^^^^^^^^^^^^^^^^^^^^^^^^^^^^^^^^^^^^^^^^^^^^^^^^^^^^^^^^^^^^^^^^^^^^^^^^^^^^^^^^^^^^^^^
  File "/home/airflow/.local/lib/python3.12/site-packages/google/oauth2/service_account.py", line 259, in from_service_account_file
    info, signer = _service_account_info.from_filename(
                   ^^^^^^^^^^^^^^^^^^^^^^^^^^^^^^^^^^^^
  File "/home/airflow/.local/lib/python3.12/site-packages/google/auth/_service_account_info.py", line 78, in from_filename
    with io.open(filename, "r", encoding="utf-8") as json_file:
         ^^^^^^^^^^^^^^^^^^^^^^^^^^^^^^^^^^^^^^^^
FileNotFoundError: [Errno 2] No such file or directory: '/opt/airflow/data/key/None'
[2024-11-26T23:20:54.066+0000] {processor.py:842} WARNING - No viable dags retrieved from /opt/airflow/dags/postgres_to_bigquery_dag.py
[2024-11-26T23:20:54.116+0000] {processor.py:183} INFO - Processing /opt/airflow/dags/postgres_to_bigquery_dag.py took 1.226 seconds
[2024-11-26T23:21:24.257+0000] {processor.py:161} INFO - Started process (PID=519) to work on /opt/airflow/dags/postgres_to_bigquery_dag.py
[2024-11-26T23:21:24.258+0000] {processor.py:830} INFO - Processing file /opt/airflow/dags/postgres_to_bigquery_dag.py for tasks to queue
[2024-11-26T23:21:24.261+0000] {logging_mixin.py:188} INFO - [2024-11-26T23:21:24.261+0000] {dagbag.py:545} INFO - Filling up the DagBag from /opt/airflow/dags/postgres_to_bigquery_dag.py
[2024-11-26T23:21:25.582+0000] {logging_mixin.py:188} INFO - [2024-11-26T23:21:25.576+0000] {dagbag.py:355} ERROR - Failed to import: /opt/airflow/dags/postgres_to_bigquery_dag.py
Traceback (most recent call last):
  File "/home/airflow/.local/lib/python3.12/site-packages/airflow/models/dagbag.py", line 351, in parse
    loader.exec_module(new_module)
  File "<frozen importlib._bootstrap_external>", line 995, in exec_module
  File "<frozen importlib._bootstrap>", line 488, in _call_with_frames_removed
  File "/opt/airflow/dags/postgres_to_bigquery_dag.py", line 40, in <module>
    credentials = service_account.Credentials.from_service_account_file(f"/opt/airflow/data/key/{getenv('key')}")
                  ^^^^^^^^^^^^^^^^^^^^^^^^^^^^^^^^^^^^^^^^^^^^^^^^^^^^^^^^^^^^^^^^^^^^^^^^^^^^^^^^^^^^^^^^^^^^^^^
  File "/home/airflow/.local/lib/python3.12/site-packages/google/oauth2/service_account.py", line 259, in from_service_account_file
    info, signer = _service_account_info.from_filename(
                   ^^^^^^^^^^^^^^^^^^^^^^^^^^^^^^^^^^^^
  File "/home/airflow/.local/lib/python3.12/site-packages/google/auth/_service_account_info.py", line 78, in from_filename
    with io.open(filename, "r", encoding="utf-8") as json_file:
         ^^^^^^^^^^^^^^^^^^^^^^^^^^^^^^^^^^^^^^^^
FileNotFoundError: [Errno 2] No such file or directory: '/opt/airflow/data/key/None'
[2024-11-26T23:21:25.584+0000] {processor.py:842} WARNING - No viable dags retrieved from /opt/airflow/dags/postgres_to_bigquery_dag.py
[2024-11-26T23:21:25.648+0000] {processor.py:183} INFO - Processing /opt/airflow/dags/postgres_to_bigquery_dag.py took 1.399 seconds
[2024-11-26T23:21:55.997+0000] {processor.py:161} INFO - Started process (PID=543) to work on /opt/airflow/dags/postgres_to_bigquery_dag.py
[2024-11-26T23:21:55.998+0000] {processor.py:830} INFO - Processing file /opt/airflow/dags/postgres_to_bigquery_dag.py for tasks to queue
[2024-11-26T23:21:56.000+0000] {logging_mixin.py:188} INFO - [2024-11-26T23:21:56.000+0000] {dagbag.py:545} INFO - Filling up the DagBag from /opt/airflow/dags/postgres_to_bigquery_dag.py
[2024-11-26T23:21:56.993+0000] {logging_mixin.py:188} INFO - [2024-11-26T23:21:56.984+0000] {dagbag.py:355} ERROR - Failed to import: /opt/airflow/dags/postgres_to_bigquery_dag.py
Traceback (most recent call last):
  File "/home/airflow/.local/lib/python3.12/site-packages/airflow/models/dagbag.py", line 351, in parse
    loader.exec_module(new_module)
  File "<frozen importlib._bootstrap_external>", line 995, in exec_module
  File "<frozen importlib._bootstrap>", line 488, in _call_with_frames_removed
  File "/opt/airflow/dags/postgres_to_bigquery_dag.py", line 40, in <module>
    credentials = service_account.Credentials.from_service_account_file(f"/opt/airflow/data/key/{getenv('key')}")
                  ^^^^^^^^^^^^^^^^^^^^^^^^^^^^^^^^^^^^^^^^^^^^^^^^^^^^^^^^^^^^^^^^^^^^^^^^^^^^^^^^^^^^^^^^^^^^^^^
  File "/home/airflow/.local/lib/python3.12/site-packages/google/oauth2/service_account.py", line 259, in from_service_account_file
    info, signer = _service_account_info.from_filename(
                   ^^^^^^^^^^^^^^^^^^^^^^^^^^^^^^^^^^^^
  File "/home/airflow/.local/lib/python3.12/site-packages/google/auth/_service_account_info.py", line 78, in from_filename
    with io.open(filename, "r", encoding="utf-8") as json_file:
         ^^^^^^^^^^^^^^^^^^^^^^^^^^^^^^^^^^^^^^^^
FileNotFoundError: [Errno 2] No such file or directory: '/opt/airflow/data/key/None'
[2024-11-26T23:21:56.995+0000] {processor.py:842} WARNING - No viable dags retrieved from /opt/airflow/dags/postgres_to_bigquery_dag.py
[2024-11-26T23:21:57.037+0000] {processor.py:183} INFO - Processing /opt/airflow/dags/postgres_to_bigquery_dag.py took 1.047 seconds
[2024-11-26T23:22:27.530+0000] {processor.py:161} INFO - Started process (PID=561) to work on /opt/airflow/dags/postgres_to_bigquery_dag.py
[2024-11-26T23:22:27.531+0000] {processor.py:830} INFO - Processing file /opt/airflow/dags/postgres_to_bigquery_dag.py for tasks to queue
[2024-11-26T23:22:27.533+0000] {logging_mixin.py:188} INFO - [2024-11-26T23:22:27.533+0000] {dagbag.py:545} INFO - Filling up the DagBag from /opt/airflow/dags/postgres_to_bigquery_dag.py
[2024-11-26T23:22:28.713+0000] {logging_mixin.py:188} INFO - [2024-11-26T23:22:28.707+0000] {dagbag.py:355} ERROR - Failed to import: /opt/airflow/dags/postgres_to_bigquery_dag.py
Traceback (most recent call last):
  File "/home/airflow/.local/lib/python3.12/site-packages/airflow/models/dagbag.py", line 351, in parse
    loader.exec_module(new_module)
  File "<frozen importlib._bootstrap_external>", line 995, in exec_module
  File "<frozen importlib._bootstrap>", line 488, in _call_with_frames_removed
  File "/opt/airflow/dags/postgres_to_bigquery_dag.py", line 40, in <module>
    credentials = service_account.Credentials.from_service_account_file(f"/opt/airflow/data/key/{getenv('key')}")
                  ^^^^^^^^^^^^^^^^^^^^^^^^^^^^^^^^^^^^^^^^^^^^^^^^^^^^^^^^^^^^^^^^^^^^^^^^^^^^^^^^^^^^^^^^^^^^^^^
  File "/home/airflow/.local/lib/python3.12/site-packages/google/oauth2/service_account.py", line 259, in from_service_account_file
    info, signer = _service_account_info.from_filename(
                   ^^^^^^^^^^^^^^^^^^^^^^^^^^^^^^^^^^^^
  File "/home/airflow/.local/lib/python3.12/site-packages/google/auth/_service_account_info.py", line 78, in from_filename
    with io.open(filename, "r", encoding="utf-8") as json_file:
         ^^^^^^^^^^^^^^^^^^^^^^^^^^^^^^^^^^^^^^^^
FileNotFoundError: [Errno 2] No such file or directory: '/opt/airflow/data/key/None'
[2024-11-26T23:22:28.715+0000] {processor.py:842} WARNING - No viable dags retrieved from /opt/airflow/dags/postgres_to_bigquery_dag.py
[2024-11-26T23:22:28.747+0000] {processor.py:183} INFO - Processing /opt/airflow/dags/postgres_to_bigquery_dag.py took 1.224 seconds
[2024-11-26T23:22:59.008+0000] {processor.py:161} INFO - Started process (PID=579) to work on /opt/airflow/dags/postgres_to_bigquery_dag.py
[2024-11-26T23:22:59.009+0000] {processor.py:830} INFO - Processing file /opt/airflow/dags/postgres_to_bigquery_dag.py for tasks to queue
[2024-11-26T23:22:59.012+0000] {logging_mixin.py:188} INFO - [2024-11-26T23:22:59.011+0000] {dagbag.py:545} INFO - Filling up the DagBag from /opt/airflow/dags/postgres_to_bigquery_dag.py
[2024-11-26T23:22:59.863+0000] {logging_mixin.py:188} INFO - [2024-11-26T23:22:59.856+0000] {dagbag.py:355} ERROR - Failed to import: /opt/airflow/dags/postgres_to_bigquery_dag.py
Traceback (most recent call last):
  File "/home/airflow/.local/lib/python3.12/site-packages/airflow/models/dagbag.py", line 351, in parse
    loader.exec_module(new_module)
  File "<frozen importlib._bootstrap_external>", line 995, in exec_module
  File "<frozen importlib._bootstrap>", line 488, in _call_with_frames_removed
  File "/opt/airflow/dags/postgres_to_bigquery_dag.py", line 40, in <module>
    credentials = service_account.Credentials.from_service_account_file(f"/opt/airflow/data/key/{getenv('key')}")
                  ^^^^^^^^^^^^^^^^^^^^^^^^^^^^^^^^^^^^^^^^^^^^^^^^^^^^^^^^^^^^^^^^^^^^^^^^^^^^^^^^^^^^^^^^^^^^^^^
  File "/home/airflow/.local/lib/python3.12/site-packages/google/oauth2/service_account.py", line 259, in from_service_account_file
    info, signer = _service_account_info.from_filename(
                   ^^^^^^^^^^^^^^^^^^^^^^^^^^^^^^^^^^^^
  File "/home/airflow/.local/lib/python3.12/site-packages/google/auth/_service_account_info.py", line 78, in from_filename
    with io.open(filename, "r", encoding="utf-8") as json_file:
         ^^^^^^^^^^^^^^^^^^^^^^^^^^^^^^^^^^^^^^^^
FileNotFoundError: [Errno 2] No such file or directory: '/opt/airflow/data/key/None'
[2024-11-26T23:22:59.865+0000] {processor.py:842} WARNING - No viable dags retrieved from /opt/airflow/dags/postgres_to_bigquery_dag.py
[2024-11-26T23:22:59.909+0000] {processor.py:183} INFO - Processing /opt/airflow/dags/postgres_to_bigquery_dag.py took 0.910 seconds
[2024-11-26T23:23:30.136+0000] {processor.py:161} INFO - Started process (PID=597) to work on /opt/airflow/dags/postgres_to_bigquery_dag.py
[2024-11-26T23:23:30.139+0000] {processor.py:830} INFO - Processing file /opt/airflow/dags/postgres_to_bigquery_dag.py for tasks to queue
[2024-11-26T23:23:30.149+0000] {logging_mixin.py:188} INFO - [2024-11-26T23:23:30.147+0000] {dagbag.py:545} INFO - Filling up the DagBag from /opt/airflow/dags/postgres_to_bigquery_dag.py
[2024-11-26T23:23:31.136+0000] {logging_mixin.py:188} INFO - [2024-11-26T23:23:31.119+0000] {dagbag.py:355} ERROR - Failed to import: /opt/airflow/dags/postgres_to_bigquery_dag.py
Traceback (most recent call last):
  File "/home/airflow/.local/lib/python3.12/site-packages/airflow/models/dagbag.py", line 351, in parse
    loader.exec_module(new_module)
  File "<frozen importlib._bootstrap_external>", line 995, in exec_module
  File "<frozen importlib._bootstrap>", line 488, in _call_with_frames_removed
  File "/opt/airflow/dags/postgres_to_bigquery_dag.py", line 40, in <module>
    credentials = service_account.Credentials.from_service_account_file(f"/opt/airflow/data/key/{getenv('key')}")
                  ^^^^^^^^^^^^^^^^^^^^^^^^^^^^^^^^^^^^^^^^^^^^^^^^^^^^^^^^^^^^^^^^^^^^^^^^^^^^^^^^^^^^^^^^^^^^^^^
  File "/home/airflow/.local/lib/python3.12/site-packages/google/oauth2/service_account.py", line 259, in from_service_account_file
    info, signer = _service_account_info.from_filename(
                   ^^^^^^^^^^^^^^^^^^^^^^^^^^^^^^^^^^^^
  File "/home/airflow/.local/lib/python3.12/site-packages/google/auth/_service_account_info.py", line 78, in from_filename
    with io.open(filename, "r", encoding="utf-8") as json_file:
         ^^^^^^^^^^^^^^^^^^^^^^^^^^^^^^^^^^^^^^^^
FileNotFoundError: [Errno 2] No such file or directory: '/opt/airflow/data/key/None'
[2024-11-26T23:23:31.138+0000] {processor.py:842} WARNING - No viable dags retrieved from /opt/airflow/dags/postgres_to_bigquery_dag.py
[2024-11-26T23:23:31.171+0000] {processor.py:183} INFO - Processing /opt/airflow/dags/postgres_to_bigquery_dag.py took 1.049 seconds
[2024-11-26T23:24:01.525+0000] {processor.py:161} INFO - Started process (PID=615) to work on /opt/airflow/dags/postgres_to_bigquery_dag.py
[2024-11-26T23:24:01.527+0000] {processor.py:830} INFO - Processing file /opt/airflow/dags/postgres_to_bigquery_dag.py for tasks to queue
[2024-11-26T23:24:01.530+0000] {logging_mixin.py:188} INFO - [2024-11-26T23:24:01.530+0000] {dagbag.py:545} INFO - Filling up the DagBag from /opt/airflow/dags/postgres_to_bigquery_dag.py
[2024-11-26T23:24:02.785+0000] {logging_mixin.py:188} INFO - [2024-11-26T23:24:02.780+0000] {dagbag.py:355} ERROR - Failed to import: /opt/airflow/dags/postgres_to_bigquery_dag.py
Traceback (most recent call last):
  File "/home/airflow/.local/lib/python3.12/site-packages/airflow/models/dagbag.py", line 351, in parse
    loader.exec_module(new_module)
  File "<frozen importlib._bootstrap_external>", line 995, in exec_module
  File "<frozen importlib._bootstrap>", line 488, in _call_with_frames_removed
  File "/opt/airflow/dags/postgres_to_bigquery_dag.py", line 40, in <module>
    credentials = service_account.Credentials.from_service_account_file(f"/opt/airflow/data/key/{getenv('key')}")
                  ^^^^^^^^^^^^^^^^^^^^^^^^^^^^^^^^^^^^^^^^^^^^^^^^^^^^^^^^^^^^^^^^^^^^^^^^^^^^^^^^^^^^^^^^^^^^^^^
  File "/home/airflow/.local/lib/python3.12/site-packages/google/oauth2/service_account.py", line 259, in from_service_account_file
    info, signer = _service_account_info.from_filename(
                   ^^^^^^^^^^^^^^^^^^^^^^^^^^^^^^^^^^^^
  File "/home/airflow/.local/lib/python3.12/site-packages/google/auth/_service_account_info.py", line 78, in from_filename
    with io.open(filename, "r", encoding="utf-8") as json_file:
         ^^^^^^^^^^^^^^^^^^^^^^^^^^^^^^^^^^^^^^^^
FileNotFoundError: [Errno 2] No such file or directory: '/opt/airflow/data/key/None'
[2024-11-26T23:24:02.787+0000] {processor.py:842} WARNING - No viable dags retrieved from /opt/airflow/dags/postgres_to_bigquery_dag.py
[2024-11-26T23:24:02.815+0000] {processor.py:183} INFO - Processing /opt/airflow/dags/postgres_to_bigquery_dag.py took 1.309 seconds
[2024-11-26T23:24:32.981+0000] {processor.py:161} INFO - Started process (PID=633) to work on /opt/airflow/dags/postgres_to_bigquery_dag.py
[2024-11-26T23:24:32.982+0000] {processor.py:830} INFO - Processing file /opt/airflow/dags/postgres_to_bigquery_dag.py for tasks to queue
[2024-11-26T23:24:32.985+0000] {logging_mixin.py:188} INFO - [2024-11-26T23:24:32.985+0000] {dagbag.py:545} INFO - Filling up the DagBag from /opt/airflow/dags/postgres_to_bigquery_dag.py
[2024-11-26T23:24:34.008+0000] {logging_mixin.py:188} INFO - [2024-11-26T23:24:34.003+0000] {dagbag.py:355} ERROR - Failed to import: /opt/airflow/dags/postgres_to_bigquery_dag.py
Traceback (most recent call last):
  File "/home/airflow/.local/lib/python3.12/site-packages/airflow/models/dagbag.py", line 351, in parse
    loader.exec_module(new_module)
  File "<frozen importlib._bootstrap_external>", line 995, in exec_module
  File "<frozen importlib._bootstrap>", line 488, in _call_with_frames_removed
  File "/opt/airflow/dags/postgres_to_bigquery_dag.py", line 40, in <module>
    credentials = service_account.Credentials.from_service_account_file(f"/opt/airflow/data/key/{getenv('key')}")
                  ^^^^^^^^^^^^^^^^^^^^^^^^^^^^^^^^^^^^^^^^^^^^^^^^^^^^^^^^^^^^^^^^^^^^^^^^^^^^^^^^^^^^^^^^^^^^^^^
  File "/home/airflow/.local/lib/python3.12/site-packages/google/oauth2/service_account.py", line 259, in from_service_account_file
    info, signer = _service_account_info.from_filename(
                   ^^^^^^^^^^^^^^^^^^^^^^^^^^^^^^^^^^^^
  File "/home/airflow/.local/lib/python3.12/site-packages/google/auth/_service_account_info.py", line 78, in from_filename
    with io.open(filename, "r", encoding="utf-8") as json_file:
         ^^^^^^^^^^^^^^^^^^^^^^^^^^^^^^^^^^^^^^^^
FileNotFoundError: [Errno 2] No such file or directory: '/opt/airflow/data/key/None'
[2024-11-26T23:24:34.009+0000] {processor.py:842} WARNING - No viable dags retrieved from /opt/airflow/dags/postgres_to_bigquery_dag.py
[2024-11-26T23:24:34.037+0000] {processor.py:183} INFO - Processing /opt/airflow/dags/postgres_to_bigquery_dag.py took 1.064 seconds
[2024-11-26T23:25:04.456+0000] {processor.py:161} INFO - Started process (PID=651) to work on /opt/airflow/dags/postgres_to_bigquery_dag.py
[2024-11-26T23:25:04.468+0000] {processor.py:830} INFO - Processing file /opt/airflow/dags/postgres_to_bigquery_dag.py for tasks to queue
[2024-11-26T23:25:04.472+0000] {logging_mixin.py:188} INFO - [2024-11-26T23:25:04.471+0000] {dagbag.py:545} INFO - Filling up the DagBag from /opt/airflow/dags/postgres_to_bigquery_dag.py
[2024-11-26T23:25:06.285+0000] {logging_mixin.py:188} INFO - [2024-11-26T23:25:06.278+0000] {dagbag.py:355} ERROR - Failed to import: /opt/airflow/dags/postgres_to_bigquery_dag.py
Traceback (most recent call last):
  File "/home/airflow/.local/lib/python3.12/site-packages/airflow/models/dagbag.py", line 351, in parse
    loader.exec_module(new_module)
  File "<frozen importlib._bootstrap_external>", line 995, in exec_module
  File "<frozen importlib._bootstrap>", line 488, in _call_with_frames_removed
  File "/opt/airflow/dags/postgres_to_bigquery_dag.py", line 40, in <module>
    credentials = service_account.Credentials.from_service_account_file(f"/opt/airflow/data/key/{getenv('key')}")
                  ^^^^^^^^^^^^^^^^^^^^^^^^^^^^^^^^^^^^^^^^^^^^^^^^^^^^^^^^^^^^^^^^^^^^^^^^^^^^^^^^^^^^^^^^^^^^^^^
  File "/home/airflow/.local/lib/python3.12/site-packages/google/oauth2/service_account.py", line 259, in from_service_account_file
    info, signer = _service_account_info.from_filename(
                   ^^^^^^^^^^^^^^^^^^^^^^^^^^^^^^^^^^^^
  File "/home/airflow/.local/lib/python3.12/site-packages/google/auth/_service_account_info.py", line 78, in from_filename
    with io.open(filename, "r", encoding="utf-8") as json_file:
         ^^^^^^^^^^^^^^^^^^^^^^^^^^^^^^^^^^^^^^^^
FileNotFoundError: [Errno 2] No such file or directory: '/opt/airflow/data/key/None'
[2024-11-26T23:25:06.287+0000] {processor.py:842} WARNING - No viable dags retrieved from /opt/airflow/dags/postgres_to_bigquery_dag.py
[2024-11-26T23:25:06.342+0000] {processor.py:183} INFO - Processing /opt/airflow/dags/postgres_to_bigquery_dag.py took 1.909 seconds
[2024-11-26T23:25:37.419+0000] {processor.py:161} INFO - Started process (PID=669) to work on /opt/airflow/dags/postgres_to_bigquery_dag.py
[2024-11-26T23:25:37.421+0000] {processor.py:830} INFO - Processing file /opt/airflow/dags/postgres_to_bigquery_dag.py for tasks to queue
[2024-11-26T23:25:37.430+0000] {logging_mixin.py:188} INFO - [2024-11-26T23:25:37.429+0000] {dagbag.py:545} INFO - Filling up the DagBag from /opt/airflow/dags/postgres_to_bigquery_dag.py
[2024-11-26T23:25:39.547+0000] {logging_mixin.py:188} INFO - [2024-11-26T23:25:39.538+0000] {dagbag.py:355} ERROR - Failed to import: /opt/airflow/dags/postgres_to_bigquery_dag.py
Traceback (most recent call last):
  File "/home/airflow/.local/lib/python3.12/site-packages/airflow/models/dagbag.py", line 351, in parse
    loader.exec_module(new_module)
  File "<frozen importlib._bootstrap_external>", line 995, in exec_module
  File "<frozen importlib._bootstrap>", line 488, in _call_with_frames_removed
  File "/opt/airflow/dags/postgres_to_bigquery_dag.py", line 40, in <module>
    credentials = service_account.Credentials.from_service_account_file(f"/opt/airflow/data/key/{getenv('key')}")
                  ^^^^^^^^^^^^^^^^^^^^^^^^^^^^^^^^^^^^^^^^^^^^^^^^^^^^^^^^^^^^^^^^^^^^^^^^^^^^^^^^^^^^^^^^^^^^^^^
  File "/home/airflow/.local/lib/python3.12/site-packages/google/oauth2/service_account.py", line 259, in from_service_account_file
    info, signer = _service_account_info.from_filename(
                   ^^^^^^^^^^^^^^^^^^^^^^^^^^^^^^^^^^^^
  File "/home/airflow/.local/lib/python3.12/site-packages/google/auth/_service_account_info.py", line 78, in from_filename
    with io.open(filename, "r", encoding="utf-8") as json_file:
         ^^^^^^^^^^^^^^^^^^^^^^^^^^^^^^^^^^^^^^^^
FileNotFoundError: [Errno 2] No such file or directory: '/opt/airflow/data/key/None'
[2024-11-26T23:25:39.548+0000] {processor.py:842} WARNING - No viable dags retrieved from /opt/airflow/dags/postgres_to_bigquery_dag.py
[2024-11-26T23:25:39.582+0000] {processor.py:183} INFO - Processing /opt/airflow/dags/postgres_to_bigquery_dag.py took 2.182 seconds
[2024-11-26T23:26:09.768+0000] {processor.py:161} INFO - Started process (PID=687) to work on /opt/airflow/dags/postgres_to_bigquery_dag.py
[2024-11-26T23:26:09.771+0000] {processor.py:830} INFO - Processing file /opt/airflow/dags/postgres_to_bigquery_dag.py for tasks to queue
[2024-11-26T23:26:09.775+0000] {logging_mixin.py:188} INFO - [2024-11-26T23:26:09.774+0000] {dagbag.py:545} INFO - Filling up the DagBag from /opt/airflow/dags/postgres_to_bigquery_dag.py
[2024-11-26T23:26:11.369+0000] {logging_mixin.py:188} INFO - [2024-11-26T23:26:11.361+0000] {dagbag.py:355} ERROR - Failed to import: /opt/airflow/dags/postgres_to_bigquery_dag.py
Traceback (most recent call last):
  File "/home/airflow/.local/lib/python3.12/site-packages/airflow/models/dagbag.py", line 351, in parse
    loader.exec_module(new_module)
  File "<frozen importlib._bootstrap_external>", line 995, in exec_module
  File "<frozen importlib._bootstrap>", line 488, in _call_with_frames_removed
  File "/opt/airflow/dags/postgres_to_bigquery_dag.py", line 40, in <module>
    credentials = service_account.Credentials.from_service_account_file(f"/opt/airflow/data/key/{getenv('key')}")
                  ^^^^^^^^^^^^^^^^^^^^^^^^^^^^^^^^^^^^^^^^^^^^^^^^^^^^^^^^^^^^^^^^^^^^^^^^^^^^^^^^^^^^^^^^^^^^^^^
  File "/home/airflow/.local/lib/python3.12/site-packages/google/oauth2/service_account.py", line 259, in from_service_account_file
    info, signer = _service_account_info.from_filename(
                   ^^^^^^^^^^^^^^^^^^^^^^^^^^^^^^^^^^^^
  File "/home/airflow/.local/lib/python3.12/site-packages/google/auth/_service_account_info.py", line 78, in from_filename
    with io.open(filename, "r", encoding="utf-8") as json_file:
         ^^^^^^^^^^^^^^^^^^^^^^^^^^^^^^^^^^^^^^^^
FileNotFoundError: [Errno 2] No such file or directory: '/opt/airflow/data/key/None'
[2024-11-26T23:26:11.371+0000] {processor.py:842} WARNING - No viable dags retrieved from /opt/airflow/dags/postgres_to_bigquery_dag.py
[2024-11-26T23:26:11.402+0000] {processor.py:183} INFO - Processing /opt/airflow/dags/postgres_to_bigquery_dag.py took 1.643 seconds
[2024-11-26T23:26:41.799+0000] {processor.py:161} INFO - Started process (PID=706) to work on /opt/airflow/dags/postgres_to_bigquery_dag.py
[2024-11-26T23:26:41.800+0000] {processor.py:830} INFO - Processing file /opt/airflow/dags/postgres_to_bigquery_dag.py for tasks to queue
[2024-11-26T23:26:41.803+0000] {logging_mixin.py:188} INFO - [2024-11-26T23:26:41.802+0000] {dagbag.py:545} INFO - Filling up the DagBag from /opt/airflow/dags/postgres_to_bigquery_dag.py
[2024-11-26T23:26:42.851+0000] {logging_mixin.py:188} INFO - [2024-11-26T23:26:42.846+0000] {dagbag.py:355} ERROR - Failed to import: /opt/airflow/dags/postgres_to_bigquery_dag.py
Traceback (most recent call last):
  File "/home/airflow/.local/lib/python3.12/site-packages/airflow/models/dagbag.py", line 351, in parse
    loader.exec_module(new_module)
  File "<frozen importlib._bootstrap_external>", line 995, in exec_module
  File "<frozen importlib._bootstrap>", line 488, in _call_with_frames_removed
  File "/opt/airflow/dags/postgres_to_bigquery_dag.py", line 40, in <module>
    credentials = service_account.Credentials.from_service_account_file(f"/opt/airflow/data/key/{getenv('key')}")
                  ^^^^^^^^^^^^^^^^^^^^^^^^^^^^^^^^^^^^^^^^^^^^^^^^^^^^^^^^^^^^^^^^^^^^^^^^^^^^^^^^^^^^^^^^^^^^^^^
  File "/home/airflow/.local/lib/python3.12/site-packages/google/oauth2/service_account.py", line 259, in from_service_account_file
    info, signer = _service_account_info.from_filename(
                   ^^^^^^^^^^^^^^^^^^^^^^^^^^^^^^^^^^^^
  File "/home/airflow/.local/lib/python3.12/site-packages/google/auth/_service_account_info.py", line 78, in from_filename
    with io.open(filename, "r", encoding="utf-8") as json_file:
         ^^^^^^^^^^^^^^^^^^^^^^^^^^^^^^^^^^^^^^^^
FileNotFoundError: [Errno 2] No such file or directory: '/opt/airflow/data/key/None'
[2024-11-26T23:26:42.852+0000] {processor.py:842} WARNING - No viable dags retrieved from /opt/airflow/dags/postgres_to_bigquery_dag.py
[2024-11-26T23:26:42.879+0000] {processor.py:183} INFO - Processing /opt/airflow/dags/postgres_to_bigquery_dag.py took 1.088 seconds
[2024-11-26T23:27:13.118+0000] {processor.py:161} INFO - Started process (PID=724) to work on /opt/airflow/dags/postgres_to_bigquery_dag.py
[2024-11-26T23:27:13.121+0000] {processor.py:830} INFO - Processing file /opt/airflow/dags/postgres_to_bigquery_dag.py for tasks to queue
[2024-11-26T23:27:13.127+0000] {logging_mixin.py:188} INFO - [2024-11-26T23:27:13.126+0000] {dagbag.py:545} INFO - Filling up the DagBag from /opt/airflow/dags/postgres_to_bigquery_dag.py
[2024-11-26T23:27:14.304+0000] {logging_mixin.py:188} INFO - [2024-11-26T23:27:14.299+0000] {dagbag.py:355} ERROR - Failed to import: /opt/airflow/dags/postgres_to_bigquery_dag.py
Traceback (most recent call last):
  File "/home/airflow/.local/lib/python3.12/site-packages/airflow/models/dagbag.py", line 351, in parse
    loader.exec_module(new_module)
  File "<frozen importlib._bootstrap_external>", line 995, in exec_module
  File "<frozen importlib._bootstrap>", line 488, in _call_with_frames_removed
  File "/opt/airflow/dags/postgres_to_bigquery_dag.py", line 40, in <module>
    credentials = service_account.Credentials.from_service_account_file(f"/opt/airflow/data/key/{getenv('key')}")
                  ^^^^^^^^^^^^^^^^^^^^^^^^^^^^^^^^^^^^^^^^^^^^^^^^^^^^^^^^^^^^^^^^^^^^^^^^^^^^^^^^^^^^^^^^^^^^^^^
  File "/home/airflow/.local/lib/python3.12/site-packages/google/oauth2/service_account.py", line 259, in from_service_account_file
    info, signer = _service_account_info.from_filename(
                   ^^^^^^^^^^^^^^^^^^^^^^^^^^^^^^^^^^^^
  File "/home/airflow/.local/lib/python3.12/site-packages/google/auth/_service_account_info.py", line 78, in from_filename
    with io.open(filename, "r", encoding="utf-8") as json_file:
         ^^^^^^^^^^^^^^^^^^^^^^^^^^^^^^^^^^^^^^^^
FileNotFoundError: [Errno 2] No such file or directory: '/opt/airflow/data/key/None'
[2024-11-26T23:27:14.305+0000] {processor.py:842} WARNING - No viable dags retrieved from /opt/airflow/dags/postgres_to_bigquery_dag.py
[2024-11-26T23:27:14.329+0000] {processor.py:183} INFO - Processing /opt/airflow/dags/postgres_to_bigquery_dag.py took 1.222 seconds
[2024-11-26T23:27:44.762+0000] {processor.py:161} INFO - Started process (PID=741) to work on /opt/airflow/dags/postgres_to_bigquery_dag.py
[2024-11-26T23:27:44.763+0000] {processor.py:830} INFO - Processing file /opt/airflow/dags/postgres_to_bigquery_dag.py for tasks to queue
[2024-11-26T23:27:44.765+0000] {logging_mixin.py:188} INFO - [2024-11-26T23:27:44.765+0000] {dagbag.py:545} INFO - Filling up the DagBag from /opt/airflow/dags/postgres_to_bigquery_dag.py
[2024-11-26T23:27:45.556+0000] {logging_mixin.py:188} INFO - [2024-11-26T23:27:45.551+0000] {dagbag.py:355} ERROR - Failed to import: /opt/airflow/dags/postgres_to_bigquery_dag.py
Traceback (most recent call last):
  File "/home/airflow/.local/lib/python3.12/site-packages/airflow/models/dagbag.py", line 351, in parse
    loader.exec_module(new_module)
  File "<frozen importlib._bootstrap_external>", line 995, in exec_module
  File "<frozen importlib._bootstrap>", line 488, in _call_with_frames_removed
  File "/opt/airflow/dags/postgres_to_bigquery_dag.py", line 40, in <module>
    credentials = service_account.Credentials.from_service_account_file(f"/opt/airflow/data/key/{getenv('key')}")
                  ^^^^^^^^^^^^^^^^^^^^^^^^^^^^^^^^^^^^^^^^^^^^^^^^^^^^^^^^^^^^^^^^^^^^^^^^^^^^^^^^^^^^^^^^^^^^^^^
  File "/home/airflow/.local/lib/python3.12/site-packages/google/oauth2/service_account.py", line 259, in from_service_account_file
    info, signer = _service_account_info.from_filename(
                   ^^^^^^^^^^^^^^^^^^^^^^^^^^^^^^^^^^^^
  File "/home/airflow/.local/lib/python3.12/site-packages/google/auth/_service_account_info.py", line 78, in from_filename
    with io.open(filename, "r", encoding="utf-8") as json_file:
         ^^^^^^^^^^^^^^^^^^^^^^^^^^^^^^^^^^^^^^^^
FileNotFoundError: [Errno 2] No such file or directory: '/opt/airflow/data/key/None'
[2024-11-26T23:27:45.557+0000] {processor.py:842} WARNING - No viable dags retrieved from /opt/airflow/dags/postgres_to_bigquery_dag.py
[2024-11-26T23:27:45.589+0000] {processor.py:183} INFO - Processing /opt/airflow/dags/postgres_to_bigquery_dag.py took 0.835 seconds
[2024-11-26T23:28:15.942+0000] {processor.py:161} INFO - Started process (PID=759) to work on /opt/airflow/dags/postgres_to_bigquery_dag.py
[2024-11-26T23:28:15.944+0000] {processor.py:830} INFO - Processing file /opt/airflow/dags/postgres_to_bigquery_dag.py for tasks to queue
[2024-11-26T23:28:15.947+0000] {logging_mixin.py:188} INFO - [2024-11-26T23:28:15.947+0000] {dagbag.py:545} INFO - Filling up the DagBag from /opt/airflow/dags/postgres_to_bigquery_dag.py
[2024-11-26T23:28:17.055+0000] {logging_mixin.py:188} INFO - [2024-11-26T23:28:17.048+0000] {dagbag.py:355} ERROR - Failed to import: /opt/airflow/dags/postgres_to_bigquery_dag.py
Traceback (most recent call last):
  File "/home/airflow/.local/lib/python3.12/site-packages/airflow/models/dagbag.py", line 351, in parse
    loader.exec_module(new_module)
  File "<frozen importlib._bootstrap_external>", line 995, in exec_module
  File "<frozen importlib._bootstrap>", line 488, in _call_with_frames_removed
  File "/opt/airflow/dags/postgres_to_bigquery_dag.py", line 40, in <module>
    credentials = service_account.Credentials.from_service_account_file(f"/opt/airflow/data/key/{getenv('key')}")
                  ^^^^^^^^^^^^^^^^^^^^^^^^^^^^^^^^^^^^^^^^^^^^^^^^^^^^^^^^^^^^^^^^^^^^^^^^^^^^^^^^^^^^^^^^^^^^^^^
  File "/home/airflow/.local/lib/python3.12/site-packages/google/oauth2/service_account.py", line 259, in from_service_account_file
    info, signer = _service_account_info.from_filename(
                   ^^^^^^^^^^^^^^^^^^^^^^^^^^^^^^^^^^^^
  File "/home/airflow/.local/lib/python3.12/site-packages/google/auth/_service_account_info.py", line 78, in from_filename
    with io.open(filename, "r", encoding="utf-8") as json_file:
         ^^^^^^^^^^^^^^^^^^^^^^^^^^^^^^^^^^^^^^^^
FileNotFoundError: [Errno 2] No such file or directory: '/opt/airflow/data/key/None'
[2024-11-26T23:28:17.057+0000] {processor.py:842} WARNING - No viable dags retrieved from /opt/airflow/dags/postgres_to_bigquery_dag.py
[2024-11-26T23:28:17.127+0000] {processor.py:183} INFO - Processing /opt/airflow/dags/postgres_to_bigquery_dag.py took 1.196 seconds
[2024-11-26T23:28:47.491+0000] {processor.py:161} INFO - Started process (PID=777) to work on /opt/airflow/dags/postgres_to_bigquery_dag.py
[2024-11-26T23:28:47.492+0000] {processor.py:830} INFO - Processing file /opt/airflow/dags/postgres_to_bigquery_dag.py for tasks to queue
[2024-11-26T23:28:47.496+0000] {logging_mixin.py:188} INFO - [2024-11-26T23:28:47.495+0000] {dagbag.py:545} INFO - Filling up the DagBag from /opt/airflow/dags/postgres_to_bigquery_dag.py
[2024-11-26T23:28:48.372+0000] {logging_mixin.py:188} INFO - [2024-11-26T23:28:48.365+0000] {dagbag.py:355} ERROR - Failed to import: /opt/airflow/dags/postgres_to_bigquery_dag.py
Traceback (most recent call last):
  File "/home/airflow/.local/lib/python3.12/site-packages/airflow/models/dagbag.py", line 351, in parse
    loader.exec_module(new_module)
  File "<frozen importlib._bootstrap_external>", line 995, in exec_module
  File "<frozen importlib._bootstrap>", line 488, in _call_with_frames_removed
  File "/opt/airflow/dags/postgres_to_bigquery_dag.py", line 40, in <module>
    credentials = service_account.Credentials.from_service_account_file(f"/opt/airflow/data/key/{getenv('key')}")
                  ^^^^^^^^^^^^^^^^^^^^^^^^^^^^^^^^^^^^^^^^^^^^^^^^^^^^^^^^^^^^^^^^^^^^^^^^^^^^^^^^^^^^^^^^^^^^^^^
  File "/home/airflow/.local/lib/python3.12/site-packages/google/oauth2/service_account.py", line 259, in from_service_account_file
    info, signer = _service_account_info.from_filename(
                   ^^^^^^^^^^^^^^^^^^^^^^^^^^^^^^^^^^^^
  File "/home/airflow/.local/lib/python3.12/site-packages/google/auth/_service_account_info.py", line 78, in from_filename
    with io.open(filename, "r", encoding="utf-8") as json_file:
         ^^^^^^^^^^^^^^^^^^^^^^^^^^^^^^^^^^^^^^^^
FileNotFoundError: [Errno 2] No such file or directory: '/opt/airflow/data/key/None'
[2024-11-26T23:28:48.373+0000] {processor.py:842} WARNING - No viable dags retrieved from /opt/airflow/dags/postgres_to_bigquery_dag.py
[2024-11-26T23:28:48.395+0000] {processor.py:183} INFO - Processing /opt/airflow/dags/postgres_to_bigquery_dag.py took 0.914 seconds
[2024-11-26T23:29:19.077+0000] {processor.py:161} INFO - Started process (PID=795) to work on /opt/airflow/dags/postgres_to_bigquery_dag.py
[2024-11-26T23:29:19.083+0000] {processor.py:830} INFO - Processing file /opt/airflow/dags/postgres_to_bigquery_dag.py for tasks to queue
[2024-11-26T23:29:19.104+0000] {logging_mixin.py:188} INFO - [2024-11-26T23:29:19.103+0000] {dagbag.py:545} INFO - Filling up the DagBag from /opt/airflow/dags/postgres_to_bigquery_dag.py
[2024-11-26T23:29:20.399+0000] {logging_mixin.py:188} INFO - [2024-11-26T23:29:20.390+0000] {dagbag.py:355} ERROR - Failed to import: /opt/airflow/dags/postgres_to_bigquery_dag.py
Traceback (most recent call last):
  File "/home/airflow/.local/lib/python3.12/site-packages/airflow/models/dagbag.py", line 351, in parse
    loader.exec_module(new_module)
  File "<frozen importlib._bootstrap_external>", line 995, in exec_module
  File "<frozen importlib._bootstrap>", line 488, in _call_with_frames_removed
  File "/opt/airflow/dags/postgres_to_bigquery_dag.py", line 40, in <module>
    credentials = service_account.Credentials.from_service_account_file(f"/opt/airflow/data/key/{getenv('key')}")
                  ^^^^^^^^^^^^^^^^^^^^^^^^^^^^^^^^^^^^^^^^^^^^^^^^^^^^^^^^^^^^^^^^^^^^^^^^^^^^^^^^^^^^^^^^^^^^^^^
  File "/home/airflow/.local/lib/python3.12/site-packages/google/oauth2/service_account.py", line 259, in from_service_account_file
    info, signer = _service_account_info.from_filename(
                   ^^^^^^^^^^^^^^^^^^^^^^^^^^^^^^^^^^^^
  File "/home/airflow/.local/lib/python3.12/site-packages/google/auth/_service_account_info.py", line 78, in from_filename
    with io.open(filename, "r", encoding="utf-8") as json_file:
         ^^^^^^^^^^^^^^^^^^^^^^^^^^^^^^^^^^^^^^^^
FileNotFoundError: [Errno 2] No such file or directory: '/opt/airflow/data/key/None'
[2024-11-26T23:29:20.400+0000] {processor.py:842} WARNING - No viable dags retrieved from /opt/airflow/dags/postgres_to_bigquery_dag.py
[2024-11-26T23:29:20.437+0000] {processor.py:183} INFO - Processing /opt/airflow/dags/postgres_to_bigquery_dag.py took 1.395 seconds
[2024-11-26T23:29:50.773+0000] {processor.py:161} INFO - Started process (PID=812) to work on /opt/airflow/dags/postgres_to_bigquery_dag.py
[2024-11-26T23:29:50.775+0000] {processor.py:830} INFO - Processing file /opt/airflow/dags/postgres_to_bigquery_dag.py for tasks to queue
[2024-11-26T23:29:50.780+0000] {logging_mixin.py:188} INFO - [2024-11-26T23:29:50.779+0000] {dagbag.py:545} INFO - Filling up the DagBag from /opt/airflow/dags/postgres_to_bigquery_dag.py
[2024-11-26T23:29:52.600+0000] {logging_mixin.py:188} INFO - [2024-11-26T23:29:52.588+0000] {dagbag.py:355} ERROR - Failed to import: /opt/airflow/dags/postgres_to_bigquery_dag.py
Traceback (most recent call last):
  File "/home/airflow/.local/lib/python3.12/site-packages/airflow/models/dagbag.py", line 351, in parse
    loader.exec_module(new_module)
  File "<frozen importlib._bootstrap_external>", line 995, in exec_module
  File "<frozen importlib._bootstrap>", line 488, in _call_with_frames_removed
  File "/opt/airflow/dags/postgres_to_bigquery_dag.py", line 40, in <module>
    credentials = service_account.Credentials.from_service_account_file(f"/opt/airflow/data/key/{getenv('key')}")
                  ^^^^^^^^^^^^^^^^^^^^^^^^^^^^^^^^^^^^^^^^^^^^^^^^^^^^^^^^^^^^^^^^^^^^^^^^^^^^^^^^^^^^^^^^^^^^^^^
  File "/home/airflow/.local/lib/python3.12/site-packages/google/oauth2/service_account.py", line 259, in from_service_account_file
    info, signer = _service_account_info.from_filename(
                   ^^^^^^^^^^^^^^^^^^^^^^^^^^^^^^^^^^^^
  File "/home/airflow/.local/lib/python3.12/site-packages/google/auth/_service_account_info.py", line 78, in from_filename
    with io.open(filename, "r", encoding="utf-8") as json_file:
         ^^^^^^^^^^^^^^^^^^^^^^^^^^^^^^^^^^^^^^^^
FileNotFoundError: [Errno 2] No such file or directory: '/opt/airflow/data/key/None'
[2024-11-26T23:29:52.610+0000] {processor.py:842} WARNING - No viable dags retrieved from /opt/airflow/dags/postgres_to_bigquery_dag.py
[2024-11-26T23:29:52.656+0000] {processor.py:183} INFO - Processing /opt/airflow/dags/postgres_to_bigquery_dag.py took 1.894 seconds
[2024-11-26T23:30:23.101+0000] {processor.py:161} INFO - Started process (PID=830) to work on /opt/airflow/dags/postgres_to_bigquery_dag.py
[2024-11-26T23:30:23.102+0000] {processor.py:830} INFO - Processing file /opt/airflow/dags/postgres_to_bigquery_dag.py for tasks to queue
[2024-11-26T23:30:23.106+0000] {logging_mixin.py:188} INFO - [2024-11-26T23:30:23.105+0000] {dagbag.py:545} INFO - Filling up the DagBag from /opt/airflow/dags/postgres_to_bigquery_dag.py
[2024-11-26T23:30:24.557+0000] {logging_mixin.py:188} INFO - [2024-11-26T23:30:24.550+0000] {dagbag.py:355} ERROR - Failed to import: /opt/airflow/dags/postgres_to_bigquery_dag.py
Traceback (most recent call last):
  File "/home/airflow/.local/lib/python3.12/site-packages/airflow/models/dagbag.py", line 351, in parse
    loader.exec_module(new_module)
  File "<frozen importlib._bootstrap_external>", line 995, in exec_module
  File "<frozen importlib._bootstrap>", line 488, in _call_with_frames_removed
  File "/opt/airflow/dags/postgres_to_bigquery_dag.py", line 40, in <module>
    credentials = service_account.Credentials.from_service_account_file(f"/opt/airflow/data/key/{getenv('key')}")
                  ^^^^^^^^^^^^^^^^^^^^^^^^^^^^^^^^^^^^^^^^^^^^^^^^^^^^^^^^^^^^^^^^^^^^^^^^^^^^^^^^^^^^^^^^^^^^^^^
  File "/home/airflow/.local/lib/python3.12/site-packages/google/oauth2/service_account.py", line 259, in from_service_account_file
    info, signer = _service_account_info.from_filename(
                   ^^^^^^^^^^^^^^^^^^^^^^^^^^^^^^^^^^^^
  File "/home/airflow/.local/lib/python3.12/site-packages/google/auth/_service_account_info.py", line 78, in from_filename
    with io.open(filename, "r", encoding="utf-8") as json_file:
         ^^^^^^^^^^^^^^^^^^^^^^^^^^^^^^^^^^^^^^^^
FileNotFoundError: [Errno 2] No such file or directory: '/opt/airflow/data/key/None'
[2024-11-26T23:30:24.559+0000] {processor.py:842} WARNING - No viable dags retrieved from /opt/airflow/dags/postgres_to_bigquery_dag.py
[2024-11-26T23:30:24.600+0000] {processor.py:183} INFO - Processing /opt/airflow/dags/postgres_to_bigquery_dag.py took 1.509 seconds
[2024-11-26T23:30:55.010+0000] {processor.py:161} INFO - Started process (PID=849) to work on /opt/airflow/dags/postgres_to_bigquery_dag.py
[2024-11-26T23:30:55.011+0000] {processor.py:830} INFO - Processing file /opt/airflow/dags/postgres_to_bigquery_dag.py for tasks to queue
[2024-11-26T23:30:55.014+0000] {logging_mixin.py:188} INFO - [2024-11-26T23:30:55.013+0000] {dagbag.py:545} INFO - Filling up the DagBag from /opt/airflow/dags/postgres_to_bigquery_dag.py
[2024-11-26T23:30:55.859+0000] {logging_mixin.py:188} INFO - [2024-11-26T23:30:55.853+0000] {dagbag.py:355} ERROR - Failed to import: /opt/airflow/dags/postgres_to_bigquery_dag.py
Traceback (most recent call last):
  File "/home/airflow/.local/lib/python3.12/site-packages/airflow/models/dagbag.py", line 351, in parse
    loader.exec_module(new_module)
  File "<frozen importlib._bootstrap_external>", line 995, in exec_module
  File "<frozen importlib._bootstrap>", line 488, in _call_with_frames_removed
  File "/opt/airflow/dags/postgres_to_bigquery_dag.py", line 40, in <module>
    credentials = service_account.Credentials.from_service_account_file(f"/opt/airflow/data/key/{getenv('key')}")
                  ^^^^^^^^^^^^^^^^^^^^^^^^^^^^^^^^^^^^^^^^^^^^^^^^^^^^^^^^^^^^^^^^^^^^^^^^^^^^^^^^^^^^^^^^^^^^^^^
  File "/home/airflow/.local/lib/python3.12/site-packages/google/oauth2/service_account.py", line 259, in from_service_account_file
    info, signer = _service_account_info.from_filename(
                   ^^^^^^^^^^^^^^^^^^^^^^^^^^^^^^^^^^^^
  File "/home/airflow/.local/lib/python3.12/site-packages/google/auth/_service_account_info.py", line 78, in from_filename
    with io.open(filename, "r", encoding="utf-8") as json_file:
         ^^^^^^^^^^^^^^^^^^^^^^^^^^^^^^^^^^^^^^^^
FileNotFoundError: [Errno 2] No such file or directory: '/opt/airflow/data/key/None'
[2024-11-26T23:30:55.860+0000] {processor.py:842} WARNING - No viable dags retrieved from /opt/airflow/dags/postgres_to_bigquery_dag.py
[2024-11-26T23:30:55.898+0000] {processor.py:183} INFO - Processing /opt/airflow/dags/postgres_to_bigquery_dag.py took 0.894 seconds
[2024-11-26T23:31:26.274+0000] {processor.py:161} INFO - Started process (PID=867) to work on /opt/airflow/dags/postgres_to_bigquery_dag.py
[2024-11-26T23:31:26.275+0000] {processor.py:830} INFO - Processing file /opt/airflow/dags/postgres_to_bigquery_dag.py for tasks to queue
[2024-11-26T23:31:26.278+0000] {logging_mixin.py:188} INFO - [2024-11-26T23:31:26.277+0000] {dagbag.py:545} INFO - Filling up the DagBag from /opt/airflow/dags/postgres_to_bigquery_dag.py
[2024-11-26T23:31:27.134+0000] {logging_mixin.py:188} INFO - [2024-11-26T23:31:27.128+0000] {dagbag.py:355} ERROR - Failed to import: /opt/airflow/dags/postgres_to_bigquery_dag.py
Traceback (most recent call last):
  File "/home/airflow/.local/lib/python3.12/site-packages/airflow/models/dagbag.py", line 351, in parse
    loader.exec_module(new_module)
  File "<frozen importlib._bootstrap_external>", line 995, in exec_module
  File "<frozen importlib._bootstrap>", line 488, in _call_with_frames_removed
  File "/opt/airflow/dags/postgres_to_bigquery_dag.py", line 40, in <module>
    credentials = service_account.Credentials.from_service_account_file(f"/opt/airflow/data/key/{getenv('key')}")
                  ^^^^^^^^^^^^^^^^^^^^^^^^^^^^^^^^^^^^^^^^^^^^^^^^^^^^^^^^^^^^^^^^^^^^^^^^^^^^^^^^^^^^^^^^^^^^^^^
  File "/home/airflow/.local/lib/python3.12/site-packages/google/oauth2/service_account.py", line 259, in from_service_account_file
    info, signer = _service_account_info.from_filename(
                   ^^^^^^^^^^^^^^^^^^^^^^^^^^^^^^^^^^^^
  File "/home/airflow/.local/lib/python3.12/site-packages/google/auth/_service_account_info.py", line 78, in from_filename
    with io.open(filename, "r", encoding="utf-8") as json_file:
         ^^^^^^^^^^^^^^^^^^^^^^^^^^^^^^^^^^^^^^^^
FileNotFoundError: [Errno 2] No such file or directory: '/opt/airflow/data/key/None'
[2024-11-26T23:31:27.135+0000] {processor.py:842} WARNING - No viable dags retrieved from /opt/airflow/dags/postgres_to_bigquery_dag.py
[2024-11-26T23:31:27.163+0000] {processor.py:183} INFO - Processing /opt/airflow/dags/postgres_to_bigquery_dag.py took 0.896 seconds
[2024-11-26T23:31:57.371+0000] {processor.py:161} INFO - Started process (PID=891) to work on /opt/airflow/dags/postgres_to_bigquery_dag.py
[2024-11-26T23:31:57.373+0000] {processor.py:830} INFO - Processing file /opt/airflow/dags/postgres_to_bigquery_dag.py for tasks to queue
[2024-11-26T23:31:57.377+0000] {logging_mixin.py:188} INFO - [2024-11-26T23:31:57.377+0000] {dagbag.py:545} INFO - Filling up the DagBag from /opt/airflow/dags/postgres_to_bigquery_dag.py
[2024-11-26T23:31:58.195+0000] {logging_mixin.py:188} INFO - [2024-11-26T23:31:58.188+0000] {dagbag.py:355} ERROR - Failed to import: /opt/airflow/dags/postgres_to_bigquery_dag.py
Traceback (most recent call last):
  File "/home/airflow/.local/lib/python3.12/site-packages/airflow/models/dagbag.py", line 351, in parse
    loader.exec_module(new_module)
  File "<frozen importlib._bootstrap_external>", line 995, in exec_module
  File "<frozen importlib._bootstrap>", line 488, in _call_with_frames_removed
  File "/opt/airflow/dags/postgres_to_bigquery_dag.py", line 40, in <module>
    credentials = service_account.Credentials.from_service_account_file(f"/opt/airflow/data/key/{getenv('key')}")
                  ^^^^^^^^^^^^^^^^^^^^^^^^^^^^^^^^^^^^^^^^^^^^^^^^^^^^^^^^^^^^^^^^^^^^^^^^^^^^^^^^^^^^^^^^^^^^^^^
  File "/home/airflow/.local/lib/python3.12/site-packages/google/oauth2/service_account.py", line 259, in from_service_account_file
    info, signer = _service_account_info.from_filename(
                   ^^^^^^^^^^^^^^^^^^^^^^^^^^^^^^^^^^^^
  File "/home/airflow/.local/lib/python3.12/site-packages/google/auth/_service_account_info.py", line 78, in from_filename
    with io.open(filename, "r", encoding="utf-8") as json_file:
         ^^^^^^^^^^^^^^^^^^^^^^^^^^^^^^^^^^^^^^^^
FileNotFoundError: [Errno 2] No such file or directory: '/opt/airflow/data/key/None'
[2024-11-26T23:31:58.196+0000] {processor.py:842} WARNING - No viable dags retrieved from /opt/airflow/dags/postgres_to_bigquery_dag.py
[2024-11-26T23:31:58.225+0000] {processor.py:183} INFO - Processing /opt/airflow/dags/postgres_to_bigquery_dag.py took 0.864 seconds
[2024-11-26T23:32:28.515+0000] {processor.py:161} INFO - Started process (PID=908) to work on /opt/airflow/dags/postgres_to_bigquery_dag.py
[2024-11-26T23:32:28.516+0000] {processor.py:830} INFO - Processing file /opt/airflow/dags/postgres_to_bigquery_dag.py for tasks to queue
[2024-11-26T23:32:28.519+0000] {logging_mixin.py:188} INFO - [2024-11-26T23:32:28.518+0000] {dagbag.py:545} INFO - Filling up the DagBag from /opt/airflow/dags/postgres_to_bigquery_dag.py
[2024-11-26T23:32:29.660+0000] {logging_mixin.py:188} INFO - [2024-11-26T23:32:29.654+0000] {dagbag.py:355} ERROR - Failed to import: /opt/airflow/dags/postgres_to_bigquery_dag.py
Traceback (most recent call last):
  File "/home/airflow/.local/lib/python3.12/site-packages/airflow/models/dagbag.py", line 351, in parse
    loader.exec_module(new_module)
  File "<frozen importlib._bootstrap_external>", line 995, in exec_module
  File "<frozen importlib._bootstrap>", line 488, in _call_with_frames_removed
  File "/opt/airflow/dags/postgres_to_bigquery_dag.py", line 40, in <module>
    credentials = service_account.Credentials.from_service_account_file(f"/opt/airflow/data/key/{getenv('key')}")
                  ^^^^^^^^^^^^^^^^^^^^^^^^^^^^^^^^^^^^^^^^^^^^^^^^^^^^^^^^^^^^^^^^^^^^^^^^^^^^^^^^^^^^^^^^^^^^^^^
  File "/home/airflow/.local/lib/python3.12/site-packages/google/oauth2/service_account.py", line 259, in from_service_account_file
    info, signer = _service_account_info.from_filename(
                   ^^^^^^^^^^^^^^^^^^^^^^^^^^^^^^^^^^^^
  File "/home/airflow/.local/lib/python3.12/site-packages/google/auth/_service_account_info.py", line 78, in from_filename
    with io.open(filename, "r", encoding="utf-8") as json_file:
         ^^^^^^^^^^^^^^^^^^^^^^^^^^^^^^^^^^^^^^^^
FileNotFoundError: [Errno 2] No such file or directory: '/opt/airflow/data/key/None'
[2024-11-26T23:32:29.661+0000] {processor.py:842} WARNING - No viable dags retrieved from /opt/airflow/dags/postgres_to_bigquery_dag.py
[2024-11-26T23:32:29.687+0000] {processor.py:183} INFO - Processing /opt/airflow/dags/postgres_to_bigquery_dag.py took 1.179 seconds
[2024-11-26T23:32:59.770+0000] {processor.py:161} INFO - Started process (PID=926) to work on /opt/airflow/dags/postgres_to_bigquery_dag.py
[2024-11-26T23:32:59.772+0000] {processor.py:830} INFO - Processing file /opt/airflow/dags/postgres_to_bigquery_dag.py for tasks to queue
[2024-11-26T23:32:59.774+0000] {logging_mixin.py:188} INFO - [2024-11-26T23:32:59.774+0000] {dagbag.py:545} INFO - Filling up the DagBag from /opt/airflow/dags/postgres_to_bigquery_dag.py
[2024-11-26T23:33:01.247+0000] {logging_mixin.py:188} INFO - [2024-11-26T23:33:01.242+0000] {dagbag.py:355} ERROR - Failed to import: /opt/airflow/dags/postgres_to_bigquery_dag.py
Traceback (most recent call last):
  File "/home/airflow/.local/lib/python3.12/site-packages/airflow/models/dagbag.py", line 351, in parse
    loader.exec_module(new_module)
  File "<frozen importlib._bootstrap_external>", line 995, in exec_module
  File "<frozen importlib._bootstrap>", line 488, in _call_with_frames_removed
  File "/opt/airflow/dags/postgres_to_bigquery_dag.py", line 40, in <module>
    credentials = service_account.Credentials.from_service_account_file(f"/opt/airflow/data/key/{getenv('key')}")
                  ^^^^^^^^^^^^^^^^^^^^^^^^^^^^^^^^^^^^^^^^^^^^^^^^^^^^^^^^^^^^^^^^^^^^^^^^^^^^^^^^^^^^^^^^^^^^^^^
  File "/home/airflow/.local/lib/python3.12/site-packages/google/oauth2/service_account.py", line 259, in from_service_account_file
    info, signer = _service_account_info.from_filename(
                   ^^^^^^^^^^^^^^^^^^^^^^^^^^^^^^^^^^^^
  File "/home/airflow/.local/lib/python3.12/site-packages/google/auth/_service_account_info.py", line 78, in from_filename
    with io.open(filename, "r", encoding="utf-8") as json_file:
         ^^^^^^^^^^^^^^^^^^^^^^^^^^^^^^^^^^^^^^^^
FileNotFoundError: [Errno 2] No such file or directory: '/opt/airflow/data/key/None'
[2024-11-26T23:33:01.248+0000] {processor.py:842} WARNING - No viable dags retrieved from /opt/airflow/dags/postgres_to_bigquery_dag.py
[2024-11-26T23:33:01.277+0000] {processor.py:183} INFO - Processing /opt/airflow/dags/postgres_to_bigquery_dag.py took 1.515 seconds
[2024-11-26T23:33:31.551+0000] {processor.py:161} INFO - Started process (PID=944) to work on /opt/airflow/dags/postgres_to_bigquery_dag.py
[2024-11-26T23:33:31.553+0000] {processor.py:830} INFO - Processing file /opt/airflow/dags/postgres_to_bigquery_dag.py for tasks to queue
[2024-11-26T23:33:31.556+0000] {logging_mixin.py:188} INFO - [2024-11-26T23:33:31.555+0000] {dagbag.py:545} INFO - Filling up the DagBag from /opt/airflow/dags/postgres_to_bigquery_dag.py
[2024-11-26T23:33:32.506+0000] {logging_mixin.py:188} INFO - [2024-11-26T23:33:32.500+0000] {dagbag.py:355} ERROR - Failed to import: /opt/airflow/dags/postgres_to_bigquery_dag.py
Traceback (most recent call last):
  File "/home/airflow/.local/lib/python3.12/site-packages/airflow/models/dagbag.py", line 351, in parse
    loader.exec_module(new_module)
  File "<frozen importlib._bootstrap_external>", line 995, in exec_module
  File "<frozen importlib._bootstrap>", line 488, in _call_with_frames_removed
  File "/opt/airflow/dags/postgres_to_bigquery_dag.py", line 40, in <module>
    credentials = service_account.Credentials.from_service_account_file(f"/opt/airflow/data/key/{getenv('key')}")
                  ^^^^^^^^^^^^^^^^^^^^^^^^^^^^^^^^^^^^^^^^^^^^^^^^^^^^^^^^^^^^^^^^^^^^^^^^^^^^^^^^^^^^^^^^^^^^^^^
  File "/home/airflow/.local/lib/python3.12/site-packages/google/oauth2/service_account.py", line 259, in from_service_account_file
    info, signer = _service_account_info.from_filename(
                   ^^^^^^^^^^^^^^^^^^^^^^^^^^^^^^^^^^^^
  File "/home/airflow/.local/lib/python3.12/site-packages/google/auth/_service_account_info.py", line 78, in from_filename
    with io.open(filename, "r", encoding="utf-8") as json_file:
         ^^^^^^^^^^^^^^^^^^^^^^^^^^^^^^^^^^^^^^^^
FileNotFoundError: [Errno 2] No such file or directory: '/opt/airflow/data/key/None'
[2024-11-26T23:33:32.507+0000] {processor.py:842} WARNING - No viable dags retrieved from /opt/airflow/dags/postgres_to_bigquery_dag.py
[2024-11-26T23:33:32.550+0000] {processor.py:183} INFO - Processing /opt/airflow/dags/postgres_to_bigquery_dag.py took 1.009 seconds
[2024-11-26T23:34:02.761+0000] {processor.py:161} INFO - Started process (PID=962) to work on /opt/airflow/dags/postgres_to_bigquery_dag.py
[2024-11-26T23:34:02.762+0000] {processor.py:830} INFO - Processing file /opt/airflow/dags/postgres_to_bigquery_dag.py for tasks to queue
[2024-11-26T23:34:02.765+0000] {logging_mixin.py:188} INFO - [2024-11-26T23:34:02.765+0000] {dagbag.py:545} INFO - Filling up the DagBag from /opt/airflow/dags/postgres_to_bigquery_dag.py
[2024-11-26T23:34:03.703+0000] {logging_mixin.py:188} INFO - [2024-11-26T23:34:03.698+0000] {dagbag.py:355} ERROR - Failed to import: /opt/airflow/dags/postgres_to_bigquery_dag.py
Traceback (most recent call last):
  File "/home/airflow/.local/lib/python3.12/site-packages/airflow/models/dagbag.py", line 351, in parse
    loader.exec_module(new_module)
  File "<frozen importlib._bootstrap_external>", line 995, in exec_module
  File "<frozen importlib._bootstrap>", line 488, in _call_with_frames_removed
  File "/opt/airflow/dags/postgres_to_bigquery_dag.py", line 40, in <module>
    credentials = service_account.Credentials.from_service_account_file(f"/opt/airflow/data/key/{getenv('key')}")
                  ^^^^^^^^^^^^^^^^^^^^^^^^^^^^^^^^^^^^^^^^^^^^^^^^^^^^^^^^^^^^^^^^^^^^^^^^^^^^^^^^^^^^^^^^^^^^^^^
  File "/home/airflow/.local/lib/python3.12/site-packages/google/oauth2/service_account.py", line 259, in from_service_account_file
    info, signer = _service_account_info.from_filename(
                   ^^^^^^^^^^^^^^^^^^^^^^^^^^^^^^^^^^^^
  File "/home/airflow/.local/lib/python3.12/site-packages/google/auth/_service_account_info.py", line 78, in from_filename
    with io.open(filename, "r", encoding="utf-8") as json_file:
         ^^^^^^^^^^^^^^^^^^^^^^^^^^^^^^^^^^^^^^^^
FileNotFoundError: [Errno 2] No such file or directory: '/opt/airflow/data/key/None'
[2024-11-26T23:34:03.704+0000] {processor.py:842} WARNING - No viable dags retrieved from /opt/airflow/dags/postgres_to_bigquery_dag.py
[2024-11-26T23:34:03.730+0000] {processor.py:183} INFO - Processing /opt/airflow/dags/postgres_to_bigquery_dag.py took 0.978 seconds
[2024-11-26T23:34:33.978+0000] {processor.py:161} INFO - Started process (PID=980) to work on /opt/airflow/dags/postgres_to_bigquery_dag.py
[2024-11-26T23:34:33.979+0000] {processor.py:830} INFO - Processing file /opt/airflow/dags/postgres_to_bigquery_dag.py for tasks to queue
[2024-11-26T23:34:33.982+0000] {logging_mixin.py:188} INFO - [2024-11-26T23:34:33.981+0000] {dagbag.py:545} INFO - Filling up the DagBag from /opt/airflow/dags/postgres_to_bigquery_dag.py
[2024-11-26T23:34:34.781+0000] {logging_mixin.py:188} INFO - [2024-11-26T23:34:34.773+0000] {dagbag.py:355} ERROR - Failed to import: /opt/airflow/dags/postgres_to_bigquery_dag.py
Traceback (most recent call last):
  File "/home/airflow/.local/lib/python3.12/site-packages/airflow/models/dagbag.py", line 351, in parse
    loader.exec_module(new_module)
  File "<frozen importlib._bootstrap_external>", line 995, in exec_module
  File "<frozen importlib._bootstrap>", line 488, in _call_with_frames_removed
  File "/opt/airflow/dags/postgres_to_bigquery_dag.py", line 40, in <module>
    credentials = service_account.Credentials.from_service_account_file(f"/opt/airflow/data/key/{getenv('key')}")
                  ^^^^^^^^^^^^^^^^^^^^^^^^^^^^^^^^^^^^^^^^^^^^^^^^^^^^^^^^^^^^^^^^^^^^^^^^^^^^^^^^^^^^^^^^^^^^^^^
  File "/home/airflow/.local/lib/python3.12/site-packages/google/oauth2/service_account.py", line 259, in from_service_account_file
    info, signer = _service_account_info.from_filename(
                   ^^^^^^^^^^^^^^^^^^^^^^^^^^^^^^^^^^^^
  File "/home/airflow/.local/lib/python3.12/site-packages/google/auth/_service_account_info.py", line 78, in from_filename
    with io.open(filename, "r", encoding="utf-8") as json_file:
         ^^^^^^^^^^^^^^^^^^^^^^^^^^^^^^^^^^^^^^^^
FileNotFoundError: [Errno 2] No such file or directory: '/opt/airflow/data/key/None'
[2024-11-26T23:34:34.782+0000] {processor.py:842} WARNING - No viable dags retrieved from /opt/airflow/dags/postgres_to_bigquery_dag.py
[2024-11-26T23:34:34.810+0000] {processor.py:183} INFO - Processing /opt/airflow/dags/postgres_to_bigquery_dag.py took 0.839 seconds
[2024-11-26T23:35:05.409+0000] {processor.py:161} INFO - Started process (PID=998) to work on /opt/airflow/dags/postgres_to_bigquery_dag.py
[2024-11-26T23:35:05.411+0000] {processor.py:830} INFO - Processing file /opt/airflow/dags/postgres_to_bigquery_dag.py for tasks to queue
[2024-11-26T23:35:05.414+0000] {logging_mixin.py:188} INFO - [2024-11-26T23:35:05.413+0000] {dagbag.py:545} INFO - Filling up the DagBag from /opt/airflow/dags/postgres_to_bigquery_dag.py
[2024-11-26T23:35:06.812+0000] {logging_mixin.py:188} INFO - [2024-11-26T23:35:06.804+0000] {dagbag.py:355} ERROR - Failed to import: /opt/airflow/dags/postgres_to_bigquery_dag.py
Traceback (most recent call last):
  File "/home/airflow/.local/lib/python3.12/site-packages/airflow/models/dagbag.py", line 351, in parse
    loader.exec_module(new_module)
  File "<frozen importlib._bootstrap_external>", line 995, in exec_module
  File "<frozen importlib._bootstrap>", line 488, in _call_with_frames_removed
  File "/opt/airflow/dags/postgres_to_bigquery_dag.py", line 40, in <module>
    credentials = service_account.Credentials.from_service_account_file(f"/opt/airflow/data/key/{getenv('key')}")
                  ^^^^^^^^^^^^^^^^^^^^^^^^^^^^^^^^^^^^^^^^^^^^^^^^^^^^^^^^^^^^^^^^^^^^^^^^^^^^^^^^^^^^^^^^^^^^^^^
  File "/home/airflow/.local/lib/python3.12/site-packages/google/oauth2/service_account.py", line 259, in from_service_account_file
    info, signer = _service_account_info.from_filename(
                   ^^^^^^^^^^^^^^^^^^^^^^^^^^^^^^^^^^^^
  File "/home/airflow/.local/lib/python3.12/site-packages/google/auth/_service_account_info.py", line 78, in from_filename
    with io.open(filename, "r", encoding="utf-8") as json_file:
         ^^^^^^^^^^^^^^^^^^^^^^^^^^^^^^^^^^^^^^^^
FileNotFoundError: [Errno 2] No such file or directory: '/opt/airflow/data/key/None'
[2024-11-26T23:35:06.814+0000] {processor.py:842} WARNING - No viable dags retrieved from /opt/airflow/dags/postgres_to_bigquery_dag.py
[2024-11-26T23:35:06.881+0000] {processor.py:183} INFO - Processing /opt/airflow/dags/postgres_to_bigquery_dag.py took 1.483 seconds
[2024-11-26T23:35:37.154+0000] {processor.py:161} INFO - Started process (PID=1016) to work on /opt/airflow/dags/postgres_to_bigquery_dag.py
[2024-11-26T23:35:37.156+0000] {processor.py:830} INFO - Processing file /opt/airflow/dags/postgres_to_bigquery_dag.py for tasks to queue
[2024-11-26T23:35:37.158+0000] {logging_mixin.py:188} INFO - [2024-11-26T23:35:37.158+0000] {dagbag.py:545} INFO - Filling up the DagBag from /opt/airflow/dags/postgres_to_bigquery_dag.py
[2024-11-26T23:35:38.199+0000] {logging_mixin.py:188} INFO - [2024-11-26T23:35:38.193+0000] {dagbag.py:355} ERROR - Failed to import: /opt/airflow/dags/postgres_to_bigquery_dag.py
Traceback (most recent call last):
  File "/home/airflow/.local/lib/python3.12/site-packages/airflow/models/dagbag.py", line 351, in parse
    loader.exec_module(new_module)
  File "<frozen importlib._bootstrap_external>", line 995, in exec_module
  File "<frozen importlib._bootstrap>", line 488, in _call_with_frames_removed
  File "/opt/airflow/dags/postgres_to_bigquery_dag.py", line 40, in <module>
    credentials = service_account.Credentials.from_service_account_file(f"/opt/airflow/data/key/{getenv('key')}")
                  ^^^^^^^^^^^^^^^^^^^^^^^^^^^^^^^^^^^^^^^^^^^^^^^^^^^^^^^^^^^^^^^^^^^^^^^^^^^^^^^^^^^^^^^^^^^^^^^
  File "/home/airflow/.local/lib/python3.12/site-packages/google/oauth2/service_account.py", line 259, in from_service_account_file
    info, signer = _service_account_info.from_filename(
                   ^^^^^^^^^^^^^^^^^^^^^^^^^^^^^^^^^^^^
  File "/home/airflow/.local/lib/python3.12/site-packages/google/auth/_service_account_info.py", line 78, in from_filename
    with io.open(filename, "r", encoding="utf-8") as json_file:
         ^^^^^^^^^^^^^^^^^^^^^^^^^^^^^^^^^^^^^^^^
FileNotFoundError: [Errno 2] No such file or directory: '/opt/airflow/data/key/None'
[2024-11-26T23:35:38.200+0000] {processor.py:842} WARNING - No viable dags retrieved from /opt/airflow/dags/postgres_to_bigquery_dag.py
[2024-11-26T23:35:38.229+0000] {processor.py:183} INFO - Processing /opt/airflow/dags/postgres_to_bigquery_dag.py took 1.083 seconds
[2024-11-26T23:36:08.512+0000] {processor.py:161} INFO - Started process (PID=1034) to work on /opt/airflow/dags/postgres_to_bigquery_dag.py
[2024-11-26T23:36:08.514+0000] {processor.py:830} INFO - Processing file /opt/airflow/dags/postgres_to_bigquery_dag.py for tasks to queue
[2024-11-26T23:36:08.518+0000] {logging_mixin.py:188} INFO - [2024-11-26T23:36:08.517+0000] {dagbag.py:545} INFO - Filling up the DagBag from /opt/airflow/dags/postgres_to_bigquery_dag.py
[2024-11-26T23:36:10.073+0000] {logging_mixin.py:188} INFO - [2024-11-26T23:36:10.066+0000] {dagbag.py:355} ERROR - Failed to import: /opt/airflow/dags/postgres_to_bigquery_dag.py
Traceback (most recent call last):
  File "/home/airflow/.local/lib/python3.12/site-packages/airflow/models/dagbag.py", line 351, in parse
    loader.exec_module(new_module)
  File "<frozen importlib._bootstrap_external>", line 995, in exec_module
  File "<frozen importlib._bootstrap>", line 488, in _call_with_frames_removed
  File "/opt/airflow/dags/postgres_to_bigquery_dag.py", line 40, in <module>
    credentials = service_account.Credentials.from_service_account_file(f"/opt/airflow/data/key/{getenv('key')}")
                  ^^^^^^^^^^^^^^^^^^^^^^^^^^^^^^^^^^^^^^^^^^^^^^^^^^^^^^^^^^^^^^^^^^^^^^^^^^^^^^^^^^^^^^^^^^^^^^^
  File "/home/airflow/.local/lib/python3.12/site-packages/google/oauth2/service_account.py", line 259, in from_service_account_file
    info, signer = _service_account_info.from_filename(
                   ^^^^^^^^^^^^^^^^^^^^^^^^^^^^^^^^^^^^
  File "/home/airflow/.local/lib/python3.12/site-packages/google/auth/_service_account_info.py", line 78, in from_filename
    with io.open(filename, "r", encoding="utf-8") as json_file:
         ^^^^^^^^^^^^^^^^^^^^^^^^^^^^^^^^^^^^^^^^
FileNotFoundError: [Errno 2] No such file or directory: '/opt/airflow/data/key/None'
[2024-11-26T23:36:10.074+0000] {processor.py:842} WARNING - No viable dags retrieved from /opt/airflow/dags/postgres_to_bigquery_dag.py
[2024-11-26T23:36:10.098+0000] {processor.py:183} INFO - Processing /opt/airflow/dags/postgres_to_bigquery_dag.py took 1.596 seconds
[2024-11-26T23:36:40.303+0000] {processor.py:161} INFO - Started process (PID=1052) to work on /opt/airflow/dags/postgres_to_bigquery_dag.py
[2024-11-26T23:36:40.305+0000] {processor.py:830} INFO - Processing file /opt/airflow/dags/postgres_to_bigquery_dag.py for tasks to queue
[2024-11-26T23:36:40.307+0000] {logging_mixin.py:188} INFO - [2024-11-26T23:36:40.307+0000] {dagbag.py:545} INFO - Filling up the DagBag from /opt/airflow/dags/postgres_to_bigquery_dag.py
[2024-11-26T23:36:41.148+0000] {logging_mixin.py:188} INFO - [2024-11-26T23:36:41.144+0000] {dagbag.py:355} ERROR - Failed to import: /opt/airflow/dags/postgres_to_bigquery_dag.py
Traceback (most recent call last):
  File "/home/airflow/.local/lib/python3.12/site-packages/airflow/models/dagbag.py", line 351, in parse
    loader.exec_module(new_module)
  File "<frozen importlib._bootstrap_external>", line 995, in exec_module
  File "<frozen importlib._bootstrap>", line 488, in _call_with_frames_removed
  File "/opt/airflow/dags/postgres_to_bigquery_dag.py", line 40, in <module>
    credentials = service_account.Credentials.from_service_account_file(f"/opt/airflow/data/key/{getenv('key')}")
                  ^^^^^^^^^^^^^^^^^^^^^^^^^^^^^^^^^^^^^^^^^^^^^^^^^^^^^^^^^^^^^^^^^^^^^^^^^^^^^^^^^^^^^^^^^^^^^^^
  File "/home/airflow/.local/lib/python3.12/site-packages/google/oauth2/service_account.py", line 259, in from_service_account_file
    info, signer = _service_account_info.from_filename(
                   ^^^^^^^^^^^^^^^^^^^^^^^^^^^^^^^^^^^^
  File "/home/airflow/.local/lib/python3.12/site-packages/google/auth/_service_account_info.py", line 78, in from_filename
    with io.open(filename, "r", encoding="utf-8") as json_file:
         ^^^^^^^^^^^^^^^^^^^^^^^^^^^^^^^^^^^^^^^^
FileNotFoundError: [Errno 2] No such file or directory: '/opt/airflow/data/key/None'
[2024-11-26T23:36:41.149+0000] {processor.py:842} WARNING - No viable dags retrieved from /opt/airflow/dags/postgres_to_bigquery_dag.py
[2024-11-26T23:36:41.173+0000] {processor.py:183} INFO - Processing /opt/airflow/dags/postgres_to_bigquery_dag.py took 0.877 seconds
[2024-11-26T23:37:11.411+0000] {processor.py:161} INFO - Started process (PID=1070) to work on /opt/airflow/dags/postgres_to_bigquery_dag.py
[2024-11-26T23:37:11.412+0000] {processor.py:830} INFO - Processing file /opt/airflow/dags/postgres_to_bigquery_dag.py for tasks to queue
[2024-11-26T23:37:11.415+0000] {logging_mixin.py:188} INFO - [2024-11-26T23:37:11.414+0000] {dagbag.py:545} INFO - Filling up the DagBag from /opt/airflow/dags/postgres_to_bigquery_dag.py
[2024-11-26T23:37:12.590+0000] {logging_mixin.py:188} INFO - [2024-11-26T23:37:12.583+0000] {dagbag.py:355} ERROR - Failed to import: /opt/airflow/dags/postgres_to_bigquery_dag.py
Traceback (most recent call last):
  File "/home/airflow/.local/lib/python3.12/site-packages/airflow/models/dagbag.py", line 351, in parse
    loader.exec_module(new_module)
  File "<frozen importlib._bootstrap_external>", line 995, in exec_module
  File "<frozen importlib._bootstrap>", line 488, in _call_with_frames_removed
  File "/opt/airflow/dags/postgres_to_bigquery_dag.py", line 40, in <module>
    credentials = service_account.Credentials.from_service_account_file(f"/opt/airflow/data/key/{getenv('key')}")
                  ^^^^^^^^^^^^^^^^^^^^^^^^^^^^^^^^^^^^^^^^^^^^^^^^^^^^^^^^^^^^^^^^^^^^^^^^^^^^^^^^^^^^^^^^^^^^^^^
  File "/home/airflow/.local/lib/python3.12/site-packages/google/oauth2/service_account.py", line 259, in from_service_account_file
    info, signer = _service_account_info.from_filename(
                   ^^^^^^^^^^^^^^^^^^^^^^^^^^^^^^^^^^^^
  File "/home/airflow/.local/lib/python3.12/site-packages/google/auth/_service_account_info.py", line 78, in from_filename
    with io.open(filename, "r", encoding="utf-8") as json_file:
         ^^^^^^^^^^^^^^^^^^^^^^^^^^^^^^^^^^^^^^^^
FileNotFoundError: [Errno 2] No such file or directory: '/opt/airflow/data/key/None'
[2024-11-26T23:37:12.592+0000] {processor.py:842} WARNING - No viable dags retrieved from /opt/airflow/dags/postgres_to_bigquery_dag.py
[2024-11-26T23:37:12.623+0000] {processor.py:183} INFO - Processing /opt/airflow/dags/postgres_to_bigquery_dag.py took 1.220 seconds
[2024-11-26T23:37:42.875+0000] {processor.py:161} INFO - Started process (PID=1088) to work on /opt/airflow/dags/postgres_to_bigquery_dag.py
[2024-11-26T23:37:42.876+0000] {processor.py:830} INFO - Processing file /opt/airflow/dags/postgres_to_bigquery_dag.py for tasks to queue
[2024-11-26T23:37:42.879+0000] {logging_mixin.py:188} INFO - [2024-11-26T23:37:42.878+0000] {dagbag.py:545} INFO - Filling up the DagBag from /opt/airflow/dags/postgres_to_bigquery_dag.py
[2024-11-26T23:37:43.606+0000] {logging_mixin.py:188} INFO - [2024-11-26T23:37:43.601+0000] {dagbag.py:355} ERROR - Failed to import: /opt/airflow/dags/postgres_to_bigquery_dag.py
Traceback (most recent call last):
  File "/home/airflow/.local/lib/python3.12/site-packages/airflow/models/dagbag.py", line 351, in parse
    loader.exec_module(new_module)
  File "<frozen importlib._bootstrap_external>", line 995, in exec_module
  File "<frozen importlib._bootstrap>", line 488, in _call_with_frames_removed
  File "/opt/airflow/dags/postgres_to_bigquery_dag.py", line 40, in <module>
    credentials = service_account.Credentials.from_service_account_file(f"/opt/airflow/data/key/{getenv('key')}")
                  ^^^^^^^^^^^^^^^^^^^^^^^^^^^^^^^^^^^^^^^^^^^^^^^^^^^^^^^^^^^^^^^^^^^^^^^^^^^^^^^^^^^^^^^^^^^^^^^
  File "/home/airflow/.local/lib/python3.12/site-packages/google/oauth2/service_account.py", line 259, in from_service_account_file
    info, signer = _service_account_info.from_filename(
                   ^^^^^^^^^^^^^^^^^^^^^^^^^^^^^^^^^^^^
  File "/home/airflow/.local/lib/python3.12/site-packages/google/auth/_service_account_info.py", line 78, in from_filename
    with io.open(filename, "r", encoding="utf-8") as json_file:
         ^^^^^^^^^^^^^^^^^^^^^^^^^^^^^^^^^^^^^^^^
FileNotFoundError: [Errno 2] No such file or directory: '/opt/airflow/data/key/None'
[2024-11-26T23:37:43.607+0000] {processor.py:842} WARNING - No viable dags retrieved from /opt/airflow/dags/postgres_to_bigquery_dag.py
[2024-11-26T23:37:43.634+0000] {processor.py:183} INFO - Processing /opt/airflow/dags/postgres_to_bigquery_dag.py took 0.766 seconds
[2024-11-26T23:38:13.778+0000] {processor.py:161} INFO - Started process (PID=1106) to work on /opt/airflow/dags/postgres_to_bigquery_dag.py
[2024-11-26T23:38:13.783+0000] {processor.py:830} INFO - Processing file /opt/airflow/dags/postgres_to_bigquery_dag.py for tasks to queue
[2024-11-26T23:38:13.789+0000] {logging_mixin.py:188} INFO - [2024-11-26T23:38:13.788+0000] {dagbag.py:545} INFO - Filling up the DagBag from /opt/airflow/dags/postgres_to_bigquery_dag.py
[2024-11-26T23:38:15.720+0000] {logging_mixin.py:188} INFO - [2024-11-26T23:38:15.715+0000] {dagbag.py:355} ERROR - Failed to import: /opt/airflow/dags/postgres_to_bigquery_dag.py
Traceback (most recent call last):
  File "/home/airflow/.local/lib/python3.12/site-packages/airflow/models/dagbag.py", line 351, in parse
    loader.exec_module(new_module)
  File "<frozen importlib._bootstrap_external>", line 995, in exec_module
  File "<frozen importlib._bootstrap>", line 488, in _call_with_frames_removed
  File "/opt/airflow/dags/postgres_to_bigquery_dag.py", line 40, in <module>
    credentials = service_account.Credentials.from_service_account_file(f"/opt/airflow/data/key/{getenv('key')}")
                  ^^^^^^^^^^^^^^^^^^^^^^^^^^^^^^^^^^^^^^^^^^^^^^^^^^^^^^^^^^^^^^^^^^^^^^^^^^^^^^^^^^^^^^^^^^^^^^^
  File "/home/airflow/.local/lib/python3.12/site-packages/google/oauth2/service_account.py", line 259, in from_service_account_file
    info, signer = _service_account_info.from_filename(
                   ^^^^^^^^^^^^^^^^^^^^^^^^^^^^^^^^^^^^
  File "/home/airflow/.local/lib/python3.12/site-packages/google/auth/_service_account_info.py", line 78, in from_filename
    with io.open(filename, "r", encoding="utf-8") as json_file:
         ^^^^^^^^^^^^^^^^^^^^^^^^^^^^^^^^^^^^^^^^
FileNotFoundError: [Errno 2] No such file or directory: '/opt/airflow/data/key/None'
[2024-11-26T23:38:15.722+0000] {processor.py:842} WARNING - No viable dags retrieved from /opt/airflow/dags/postgres_to_bigquery_dag.py
[2024-11-26T23:38:15.751+0000] {processor.py:183} INFO - Processing /opt/airflow/dags/postgres_to_bigquery_dag.py took 1.988 seconds
[2024-11-26T23:38:46.550+0000] {processor.py:161} INFO - Started process (PID=1125) to work on /opt/airflow/dags/postgres_to_bigquery_dag.py
[2024-11-26T23:38:46.551+0000] {processor.py:830} INFO - Processing file /opt/airflow/dags/postgres_to_bigquery_dag.py for tasks to queue
[2024-11-26T23:38:46.554+0000] {logging_mixin.py:188} INFO - [2024-11-26T23:38:46.554+0000] {dagbag.py:545} INFO - Filling up the DagBag from /opt/airflow/dags/postgres_to_bigquery_dag.py
[2024-11-26T23:38:48.219+0000] {logging_mixin.py:188} INFO - [2024-11-26T23:38:48.211+0000] {dagbag.py:355} ERROR - Failed to import: /opt/airflow/dags/postgres_to_bigquery_dag.py
Traceback (most recent call last):
  File "/home/airflow/.local/lib/python3.12/site-packages/airflow/models/dagbag.py", line 351, in parse
    loader.exec_module(new_module)
  File "<frozen importlib._bootstrap_external>", line 995, in exec_module
  File "<frozen importlib._bootstrap>", line 488, in _call_with_frames_removed
  File "/opt/airflow/dags/postgres_to_bigquery_dag.py", line 40, in <module>
    credentials = service_account.Credentials.from_service_account_file(f"/opt/airflow/data/key/{getenv('key')}")
                  ^^^^^^^^^^^^^^^^^^^^^^^^^^^^^^^^^^^^^^^^^^^^^^^^^^^^^^^^^^^^^^^^^^^^^^^^^^^^^^^^^^^^^^^^^^^^^^^
  File "/home/airflow/.local/lib/python3.12/site-packages/google/oauth2/service_account.py", line 259, in from_service_account_file
    info, signer = _service_account_info.from_filename(
                   ^^^^^^^^^^^^^^^^^^^^^^^^^^^^^^^^^^^^
  File "/home/airflow/.local/lib/python3.12/site-packages/google/auth/_service_account_info.py", line 78, in from_filename
    with io.open(filename, "r", encoding="utf-8") as json_file:
         ^^^^^^^^^^^^^^^^^^^^^^^^^^^^^^^^^^^^^^^^
FileNotFoundError: [Errno 2] No such file or directory: '/opt/airflow/data/key/None'
[2024-11-26T23:38:48.220+0000] {processor.py:842} WARNING - No viable dags retrieved from /opt/airflow/dags/postgres_to_bigquery_dag.py
[2024-11-26T23:38:48.271+0000] {processor.py:183} INFO - Processing /opt/airflow/dags/postgres_to_bigquery_dag.py took 1.734 seconds
[2024-11-26T23:39:19.599+0000] {processor.py:161} INFO - Started process (PID=1144) to work on /opt/airflow/dags/postgres_to_bigquery_dag.py
[2024-11-26T23:39:19.611+0000] {processor.py:830} INFO - Processing file /opt/airflow/dags/postgres_to_bigquery_dag.py for tasks to queue
[2024-11-26T23:39:19.631+0000] {logging_mixin.py:188} INFO - [2024-11-26T23:39:19.630+0000] {dagbag.py:545} INFO - Filling up the DagBag from /opt/airflow/dags/postgres_to_bigquery_dag.py
[2024-11-26T23:39:24.399+0000] {logging_mixin.py:188} INFO - [2024-11-26T23:39:24.378+0000] {dagbag.py:355} ERROR - Failed to import: /opt/airflow/dags/postgres_to_bigquery_dag.py
Traceback (most recent call last):
  File "/home/airflow/.local/lib/python3.12/site-packages/airflow/models/dagbag.py", line 351, in parse
    loader.exec_module(new_module)
  File "<frozen importlib._bootstrap_external>", line 995, in exec_module
  File "<frozen importlib._bootstrap>", line 488, in _call_with_frames_removed
  File "/opt/airflow/dags/postgres_to_bigquery_dag.py", line 40, in <module>
    credentials = service_account.Credentials.from_service_account_file(f"/opt/airflow/data/key/{getenv('key')}")
                  ^^^^^^^^^^^^^^^^^^^^^^^^^^^^^^^^^^^^^^^^^^^^^^^^^^^^^^^^^^^^^^^^^^^^^^^^^^^^^^^^^^^^^^^^^^^^^^^
  File "/home/airflow/.local/lib/python3.12/site-packages/google/oauth2/service_account.py", line 259, in from_service_account_file
    info, signer = _service_account_info.from_filename(
                   ^^^^^^^^^^^^^^^^^^^^^^^^^^^^^^^^^^^^
  File "/home/airflow/.local/lib/python3.12/site-packages/google/auth/_service_account_info.py", line 78, in from_filename
    with io.open(filename, "r", encoding="utf-8") as json_file:
         ^^^^^^^^^^^^^^^^^^^^^^^^^^^^^^^^^^^^^^^^
FileNotFoundError: [Errno 2] No such file or directory: '/opt/airflow/data/key/None'
[2024-11-26T23:39:24.404+0000] {processor.py:842} WARNING - No viable dags retrieved from /opt/airflow/dags/postgres_to_bigquery_dag.py
[2024-11-26T23:39:24.528+0000] {processor.py:183} INFO - Processing /opt/airflow/dags/postgres_to_bigquery_dag.py took 4.950 seconds
[2024-11-26T23:39:54.703+0000] {processor.py:161} INFO - Started process (PID=1163) to work on /opt/airflow/dags/postgres_to_bigquery_dag.py
[2024-11-26T23:39:54.705+0000] {processor.py:830} INFO - Processing file /opt/airflow/dags/postgres_to_bigquery_dag.py for tasks to queue
[2024-11-26T23:39:54.709+0000] {logging_mixin.py:188} INFO - [2024-11-26T23:39:54.708+0000] {dagbag.py:545} INFO - Filling up the DagBag from /opt/airflow/dags/postgres_to_bigquery_dag.py
[2024-11-26T23:39:57.040+0000] {logging_mixin.py:188} INFO - [2024-11-26T23:39:57.030+0000] {dagbag.py:355} ERROR - Failed to import: /opt/airflow/dags/postgres_to_bigquery_dag.py
Traceback (most recent call last):
  File "/home/airflow/.local/lib/python3.12/site-packages/airflow/models/dagbag.py", line 351, in parse
    loader.exec_module(new_module)
  File "<frozen importlib._bootstrap_external>", line 995, in exec_module
  File "<frozen importlib._bootstrap>", line 488, in _call_with_frames_removed
  File "/opt/airflow/dags/postgres_to_bigquery_dag.py", line 40, in <module>
    credentials = service_account.Credentials.from_service_account_file(f"/opt/airflow/data/key/{getenv('key')}")
                  ^^^^^^^^^^^^^^^^^^^^^^^^^^^^^^^^^^^^^^^^^^^^^^^^^^^^^^^^^^^^^^^^^^^^^^^^^^^^^^^^^^^^^^^^^^^^^^^
  File "/home/airflow/.local/lib/python3.12/site-packages/google/oauth2/service_account.py", line 259, in from_service_account_file
    info, signer = _service_account_info.from_filename(
                   ^^^^^^^^^^^^^^^^^^^^^^^^^^^^^^^^^^^^
  File "/home/airflow/.local/lib/python3.12/site-packages/google/auth/_service_account_info.py", line 78, in from_filename
    with io.open(filename, "r", encoding="utf-8") as json_file:
         ^^^^^^^^^^^^^^^^^^^^^^^^^^^^^^^^^^^^^^^^
FileNotFoundError: [Errno 2] No such file or directory: '/opt/airflow/data/key/None'
[2024-11-26T23:39:57.042+0000] {processor.py:842} WARNING - No viable dags retrieved from /opt/airflow/dags/postgres_to_bigquery_dag.py
[2024-11-26T23:39:57.162+0000] {processor.py:183} INFO - Processing /opt/airflow/dags/postgres_to_bigquery_dag.py took 2.477 seconds
[2024-11-26T23:40:28.256+0000] {processor.py:161} INFO - Started process (PID=1186) to work on /opt/airflow/dags/postgres_to_bigquery_dag.py
[2024-11-26T23:40:28.258+0000] {processor.py:830} INFO - Processing file /opt/airflow/dags/postgres_to_bigquery_dag.py for tasks to queue
[2024-11-26T23:40:28.262+0000] {logging_mixin.py:188} INFO - [2024-11-26T23:40:28.261+0000] {dagbag.py:545} INFO - Filling up the DagBag from /opt/airflow/dags/postgres_to_bigquery_dag.py
[2024-11-26T23:40:31.067+0000] {logging_mixin.py:188} INFO - [2024-11-26T23:40:31.062+0000] {dagbag.py:355} ERROR - Failed to import: /opt/airflow/dags/postgres_to_bigquery_dag.py
Traceback (most recent call last):
  File "/home/airflow/.local/lib/python3.12/site-packages/airflow/models/dagbag.py", line 351, in parse
    loader.exec_module(new_module)
  File "<frozen importlib._bootstrap_external>", line 995, in exec_module
  File "<frozen importlib._bootstrap>", line 488, in _call_with_frames_removed
  File "/opt/airflow/dags/postgres_to_bigquery_dag.py", line 40, in <module>
    credentials = service_account.Credentials.from_service_account_file(f"/opt/airflow/data/key/{getenv('key')}")
                  ^^^^^^^^^^^^^^^^^^^^^^^^^^^^^^^^^^^^^^^^^^^^^^^^^^^^^^^^^^^^^^^^^^^^^^^^^^^^^^^^^^^^^^^^^^^^^^^
  File "/home/airflow/.local/lib/python3.12/site-packages/google/oauth2/service_account.py", line 259, in from_service_account_file
    info, signer = _service_account_info.from_filename(
                   ^^^^^^^^^^^^^^^^^^^^^^^^^^^^^^^^^^^^
  File "/home/airflow/.local/lib/python3.12/site-packages/google/auth/_service_account_info.py", line 78, in from_filename
    with io.open(filename, "r", encoding="utf-8") as json_file:
         ^^^^^^^^^^^^^^^^^^^^^^^^^^^^^^^^^^^^^^^^
FileNotFoundError: [Errno 2] No such file or directory: '/opt/airflow/data/key/None'
[2024-11-26T23:40:31.069+0000] {processor.py:842} WARNING - No viable dags retrieved from /opt/airflow/dags/postgres_to_bigquery_dag.py
[2024-11-26T23:40:31.143+0000] {processor.py:183} INFO - Processing /opt/airflow/dags/postgres_to_bigquery_dag.py took 2.902 seconds
[2024-11-26T23:41:01.680+0000] {processor.py:161} INFO - Started process (PID=1204) to work on /opt/airflow/dags/postgres_to_bigquery_dag.py
[2024-11-26T23:41:01.682+0000] {processor.py:830} INFO - Processing file /opt/airflow/dags/postgres_to_bigquery_dag.py for tasks to queue
[2024-11-26T23:41:01.687+0000] {logging_mixin.py:188} INFO - [2024-11-26T23:41:01.686+0000] {dagbag.py:545} INFO - Filling up the DagBag from /opt/airflow/dags/postgres_to_bigquery_dag.py
[2024-11-26T23:41:03.355+0000] {logging_mixin.py:188} INFO - [2024-11-26T23:41:03.344+0000] {dagbag.py:355} ERROR - Failed to import: /opt/airflow/dags/postgres_to_bigquery_dag.py
Traceback (most recent call last):
  File "/home/airflow/.local/lib/python3.12/site-packages/airflow/models/dagbag.py", line 351, in parse
    loader.exec_module(new_module)
  File "<frozen importlib._bootstrap_external>", line 995, in exec_module
  File "<frozen importlib._bootstrap>", line 488, in _call_with_frames_removed
  File "/opt/airflow/dags/postgres_to_bigquery_dag.py", line 40, in <module>
    credentials = service_account.Credentials.from_service_account_file(f"/opt/airflow/data/key/{getenv('key')}")
                  ^^^^^^^^^^^^^^^^^^^^^^^^^^^^^^^^^^^^^^^^^^^^^^^^^^^^^^^^^^^^^^^^^^^^^^^^^^^^^^^^^^^^^^^^^^^^^^^
  File "/home/airflow/.local/lib/python3.12/site-packages/google/oauth2/service_account.py", line 259, in from_service_account_file
    info, signer = _service_account_info.from_filename(
                   ^^^^^^^^^^^^^^^^^^^^^^^^^^^^^^^^^^^^
  File "/home/airflow/.local/lib/python3.12/site-packages/google/auth/_service_account_info.py", line 78, in from_filename
    with io.open(filename, "r", encoding="utf-8") as json_file:
         ^^^^^^^^^^^^^^^^^^^^^^^^^^^^^^^^^^^^^^^^
FileNotFoundError: [Errno 2] No such file or directory: '/opt/airflow/data/key/None'
[2024-11-26T23:41:03.356+0000] {processor.py:842} WARNING - No viable dags retrieved from /opt/airflow/dags/postgres_to_bigquery_dag.py
[2024-11-26T23:41:03.393+0000] {processor.py:183} INFO - Processing /opt/airflow/dags/postgres_to_bigquery_dag.py took 1.733 seconds
[2024-11-26T23:41:33.794+0000] {processor.py:161} INFO - Started process (PID=1222) to work on /opt/airflow/dags/postgres_to_bigquery_dag.py
[2024-11-26T23:41:33.795+0000] {processor.py:830} INFO - Processing file /opt/airflow/dags/postgres_to_bigquery_dag.py for tasks to queue
[2024-11-26T23:41:33.797+0000] {logging_mixin.py:188} INFO - [2024-11-26T23:41:33.797+0000] {dagbag.py:545} INFO - Filling up the DagBag from /opt/airflow/dags/postgres_to_bigquery_dag.py
[2024-11-26T23:41:34.902+0000] {logging_mixin.py:188} INFO - [2024-11-26T23:41:34.896+0000] {dagbag.py:355} ERROR - Failed to import: /opt/airflow/dags/postgres_to_bigquery_dag.py
Traceback (most recent call last):
  File "/home/airflow/.local/lib/python3.12/site-packages/airflow/models/dagbag.py", line 351, in parse
    loader.exec_module(new_module)
  File "<frozen importlib._bootstrap_external>", line 995, in exec_module
  File "<frozen importlib._bootstrap>", line 488, in _call_with_frames_removed
  File "/opt/airflow/dags/postgres_to_bigquery_dag.py", line 40, in <module>
    credentials = service_account.Credentials.from_service_account_file(f"/opt/airflow/data/key/{getenv('key')}")
                  ^^^^^^^^^^^^^^^^^^^^^^^^^^^^^^^^^^^^^^^^^^^^^^^^^^^^^^^^^^^^^^^^^^^^^^^^^^^^^^^^^^^^^^^^^^^^^^^
  File "/home/airflow/.local/lib/python3.12/site-packages/google/oauth2/service_account.py", line 259, in from_service_account_file
    info, signer = _service_account_info.from_filename(
                   ^^^^^^^^^^^^^^^^^^^^^^^^^^^^^^^^^^^^
  File "/home/airflow/.local/lib/python3.12/site-packages/google/auth/_service_account_info.py", line 78, in from_filename
    with io.open(filename, "r", encoding="utf-8") as json_file:
         ^^^^^^^^^^^^^^^^^^^^^^^^^^^^^^^^^^^^^^^^
FileNotFoundError: [Errno 2] No such file or directory: '/opt/airflow/data/key/None'
[2024-11-26T23:41:34.904+0000] {processor.py:842} WARNING - No viable dags retrieved from /opt/airflow/dags/postgres_to_bigquery_dag.py
[2024-11-26T23:41:34.944+0000] {processor.py:183} INFO - Processing /opt/airflow/dags/postgres_to_bigquery_dag.py took 1.158 seconds
[2024-11-26T23:42:05.373+0000] {processor.py:161} INFO - Started process (PID=1240) to work on /opt/airflow/dags/postgres_to_bigquery_dag.py
[2024-11-26T23:42:05.376+0000] {processor.py:830} INFO - Processing file /opt/airflow/dags/postgres_to_bigquery_dag.py for tasks to queue
[2024-11-26T23:42:05.387+0000] {logging_mixin.py:188} INFO - [2024-11-26T23:42:05.380+0000] {dagbag.py:545} INFO - Filling up the DagBag from /opt/airflow/dags/postgres_to_bigquery_dag.py
[2024-11-26T23:42:06.721+0000] {logging_mixin.py:188} INFO - [2024-11-26T23:42:06.707+0000] {dagbag.py:355} ERROR - Failed to import: /opt/airflow/dags/postgres_to_bigquery_dag.py
Traceback (most recent call last):
  File "/home/airflow/.local/lib/python3.12/site-packages/airflow/models/dagbag.py", line 351, in parse
    loader.exec_module(new_module)
  File "<frozen importlib._bootstrap_external>", line 995, in exec_module
  File "<frozen importlib._bootstrap>", line 488, in _call_with_frames_removed
  File "/opt/airflow/dags/postgres_to_bigquery_dag.py", line 40, in <module>
    credentials = service_account.Credentials.from_service_account_file(f"/opt/airflow/data/key/{getenv('key')}")
                  ^^^^^^^^^^^^^^^^^^^^^^^^^^^^^^^^^^^^^^^^^^^^^^^^^^^^^^^^^^^^^^^^^^^^^^^^^^^^^^^^^^^^^^^^^^^^^^^
  File "/home/airflow/.local/lib/python3.12/site-packages/google/oauth2/service_account.py", line 259, in from_service_account_file
    info, signer = _service_account_info.from_filename(
                   ^^^^^^^^^^^^^^^^^^^^^^^^^^^^^^^^^^^^
  File "/home/airflow/.local/lib/python3.12/site-packages/google/auth/_service_account_info.py", line 78, in from_filename
    with io.open(filename, "r", encoding="utf-8") as json_file:
         ^^^^^^^^^^^^^^^^^^^^^^^^^^^^^^^^^^^^^^^^
FileNotFoundError: [Errno 2] No such file or directory: '/opt/airflow/data/key/None'
[2024-11-26T23:42:06.723+0000] {processor.py:842} WARNING - No viable dags retrieved from /opt/airflow/dags/postgres_to_bigquery_dag.py
[2024-11-26T23:42:06.771+0000] {processor.py:183} INFO - Processing /opt/airflow/dags/postgres_to_bigquery_dag.py took 1.412 seconds
[2024-11-26T23:42:37.122+0000] {processor.py:161} INFO - Started process (PID=1258) to work on /opt/airflow/dags/postgres_to_bigquery_dag.py
[2024-11-26T23:42:37.123+0000] {processor.py:830} INFO - Processing file /opt/airflow/dags/postgres_to_bigquery_dag.py for tasks to queue
[2024-11-26T23:42:37.126+0000] {logging_mixin.py:188} INFO - [2024-11-26T23:42:37.125+0000] {dagbag.py:545} INFO - Filling up the DagBag from /opt/airflow/dags/postgres_to_bigquery_dag.py
[2024-11-26T23:42:38.336+0000] {logging_mixin.py:188} INFO - [2024-11-26T23:42:38.331+0000] {dagbag.py:355} ERROR - Failed to import: /opt/airflow/dags/postgres_to_bigquery_dag.py
Traceback (most recent call last):
  File "/home/airflow/.local/lib/python3.12/site-packages/airflow/models/dagbag.py", line 351, in parse
    loader.exec_module(new_module)
  File "<frozen importlib._bootstrap_external>", line 995, in exec_module
  File "<frozen importlib._bootstrap>", line 488, in _call_with_frames_removed
  File "/opt/airflow/dags/postgres_to_bigquery_dag.py", line 40, in <module>
    credentials = service_account.Credentials.from_service_account_file(f"/opt/airflow/data/key/{getenv('key')}")
                  ^^^^^^^^^^^^^^^^^^^^^^^^^^^^^^^^^^^^^^^^^^^^^^^^^^^^^^^^^^^^^^^^^^^^^^^^^^^^^^^^^^^^^^^^^^^^^^^
  File "/home/airflow/.local/lib/python3.12/site-packages/google/oauth2/service_account.py", line 259, in from_service_account_file
    info, signer = _service_account_info.from_filename(
                   ^^^^^^^^^^^^^^^^^^^^^^^^^^^^^^^^^^^^
  File "/home/airflow/.local/lib/python3.12/site-packages/google/auth/_service_account_info.py", line 78, in from_filename
    with io.open(filename, "r", encoding="utf-8") as json_file:
         ^^^^^^^^^^^^^^^^^^^^^^^^^^^^^^^^^^^^^^^^
FileNotFoundError: [Errno 2] No such file or directory: '/opt/airflow/data/key/None'
[2024-11-26T23:42:38.337+0000] {processor.py:842} WARNING - No viable dags retrieved from /opt/airflow/dags/postgres_to_bigquery_dag.py
[2024-11-26T23:42:38.366+0000] {processor.py:183} INFO - Processing /opt/airflow/dags/postgres_to_bigquery_dag.py took 1.251 seconds
[2024-11-26T23:43:08.577+0000] {processor.py:161} INFO - Started process (PID=1276) to work on /opt/airflow/dags/postgres_to_bigquery_dag.py
[2024-11-26T23:43:08.578+0000] {processor.py:830} INFO - Processing file /opt/airflow/dags/postgres_to_bigquery_dag.py for tasks to queue
[2024-11-26T23:43:08.582+0000] {logging_mixin.py:188} INFO - [2024-11-26T23:43:08.581+0000] {dagbag.py:545} INFO - Filling up the DagBag from /opt/airflow/dags/postgres_to_bigquery_dag.py
[2024-11-26T23:43:10.382+0000] {logging_mixin.py:188} INFO - [2024-11-26T23:43:10.355+0000] {dagbag.py:355} ERROR - Failed to import: /opt/airflow/dags/postgres_to_bigquery_dag.py
Traceback (most recent call last):
  File "/home/airflow/.local/lib/python3.12/site-packages/airflow/models/dagbag.py", line 351, in parse
    loader.exec_module(new_module)
  File "<frozen importlib._bootstrap_external>", line 995, in exec_module
  File "<frozen importlib._bootstrap>", line 488, in _call_with_frames_removed
  File "/opt/airflow/dags/postgres_to_bigquery_dag.py", line 40, in <module>
    credentials = service_account.Credentials.from_service_account_file(f"/opt/airflow/data/key/{getenv('key')}")
                  ^^^^^^^^^^^^^^^^^^^^^^^^^^^^^^^^^^^^^^^^^^^^^^^^^^^^^^^^^^^^^^^^^^^^^^^^^^^^^^^^^^^^^^^^^^^^^^^
  File "/home/airflow/.local/lib/python3.12/site-packages/google/oauth2/service_account.py", line 259, in from_service_account_file
    info, signer = _service_account_info.from_filename(
                   ^^^^^^^^^^^^^^^^^^^^^^^^^^^^^^^^^^^^
  File "/home/airflow/.local/lib/python3.12/site-packages/google/auth/_service_account_info.py", line 78, in from_filename
    with io.open(filename, "r", encoding="utf-8") as json_file:
         ^^^^^^^^^^^^^^^^^^^^^^^^^^^^^^^^^^^^^^^^
FileNotFoundError: [Errno 2] No such file or directory: '/opt/airflow/data/key/None'
[2024-11-26T23:43:10.384+0000] {processor.py:842} WARNING - No viable dags retrieved from /opt/airflow/dags/postgres_to_bigquery_dag.py
[2024-11-26T23:43:10.423+0000] {processor.py:183} INFO - Processing /opt/airflow/dags/postgres_to_bigquery_dag.py took 1.863 seconds
[2024-11-26T23:43:40.797+0000] {processor.py:161} INFO - Started process (PID=1294) to work on /opt/airflow/dags/postgres_to_bigquery_dag.py
[2024-11-26T23:43:40.799+0000] {processor.py:830} INFO - Processing file /opt/airflow/dags/postgres_to_bigquery_dag.py for tasks to queue
[2024-11-26T23:43:40.802+0000] {logging_mixin.py:188} INFO - [2024-11-26T23:43:40.801+0000] {dagbag.py:545} INFO - Filling up the DagBag from /opt/airflow/dags/postgres_to_bigquery_dag.py
[2024-11-26T23:43:42.046+0000] {logging_mixin.py:188} INFO - [2024-11-26T23:43:42.034+0000] {dagbag.py:355} ERROR - Failed to import: /opt/airflow/dags/postgres_to_bigquery_dag.py
Traceback (most recent call last):
  File "/home/airflow/.local/lib/python3.12/site-packages/airflow/models/dagbag.py", line 351, in parse
    loader.exec_module(new_module)
  File "<frozen importlib._bootstrap_external>", line 995, in exec_module
  File "<frozen importlib._bootstrap>", line 488, in _call_with_frames_removed
  File "/opt/airflow/dags/postgres_to_bigquery_dag.py", line 40, in <module>
    credentials = service_account.Credentials.from_service_account_file(f"/opt/airflow/data/key/{getenv('key')}")
                  ^^^^^^^^^^^^^^^^^^^^^^^^^^^^^^^^^^^^^^^^^^^^^^^^^^^^^^^^^^^^^^^^^^^^^^^^^^^^^^^^^^^^^^^^^^^^^^^
  File "/home/airflow/.local/lib/python3.12/site-packages/google/oauth2/service_account.py", line 259, in from_service_account_file
    info, signer = _service_account_info.from_filename(
                   ^^^^^^^^^^^^^^^^^^^^^^^^^^^^^^^^^^^^
  File "/home/airflow/.local/lib/python3.12/site-packages/google/auth/_service_account_info.py", line 78, in from_filename
    with io.open(filename, "r", encoding="utf-8") as json_file:
         ^^^^^^^^^^^^^^^^^^^^^^^^^^^^^^^^^^^^^^^^
FileNotFoundError: [Errno 2] No such file or directory: '/opt/airflow/data/key/None'
[2024-11-26T23:43:42.048+0000] {processor.py:842} WARNING - No viable dags retrieved from /opt/airflow/dags/postgres_to_bigquery_dag.py
[2024-11-26T23:43:42.124+0000] {processor.py:183} INFO - Processing /opt/airflow/dags/postgres_to_bigquery_dag.py took 1.337 seconds
[2024-11-26T23:44:12.290+0000] {processor.py:161} INFO - Started process (PID=1312) to work on /opt/airflow/dags/postgres_to_bigquery_dag.py
[2024-11-26T23:44:12.291+0000] {processor.py:830} INFO - Processing file /opt/airflow/dags/postgres_to_bigquery_dag.py for tasks to queue
[2024-11-26T23:44:12.294+0000] {logging_mixin.py:188} INFO - [2024-11-26T23:44:12.294+0000] {dagbag.py:545} INFO - Filling up the DagBag from /opt/airflow/dags/postgres_to_bigquery_dag.py
[2024-11-26T23:44:14.564+0000] {logging_mixin.py:188} INFO - [2024-11-26T23:44:14.552+0000] {dagbag.py:355} ERROR - Failed to import: /opt/airflow/dags/postgres_to_bigquery_dag.py
Traceback (most recent call last):
  File "/home/airflow/.local/lib/python3.12/site-packages/airflow/models/dagbag.py", line 351, in parse
    loader.exec_module(new_module)
  File "<frozen importlib._bootstrap_external>", line 995, in exec_module
  File "<frozen importlib._bootstrap>", line 488, in _call_with_frames_removed
  File "/opt/airflow/dags/postgres_to_bigquery_dag.py", line 40, in <module>
    credentials = service_account.Credentials.from_service_account_file(f"/opt/airflow/data/key/{getenv('key')}")
                  ^^^^^^^^^^^^^^^^^^^^^^^^^^^^^^^^^^^^^^^^^^^^^^^^^^^^^^^^^^^^^^^^^^^^^^^^^^^^^^^^^^^^^^^^^^^^^^^
  File "/home/airflow/.local/lib/python3.12/site-packages/google/oauth2/service_account.py", line 259, in from_service_account_file
    info, signer = _service_account_info.from_filename(
                   ^^^^^^^^^^^^^^^^^^^^^^^^^^^^^^^^^^^^
  File "/home/airflow/.local/lib/python3.12/site-packages/google/auth/_service_account_info.py", line 78, in from_filename
    with io.open(filename, "r", encoding="utf-8") as json_file:
         ^^^^^^^^^^^^^^^^^^^^^^^^^^^^^^^^^^^^^^^^
FileNotFoundError: [Errno 2] No such file or directory: '/opt/airflow/data/key/None'
[2024-11-26T23:44:14.565+0000] {processor.py:842} WARNING - No viable dags retrieved from /opt/airflow/dags/postgres_to_bigquery_dag.py
[2024-11-26T23:44:14.608+0000] {processor.py:183} INFO - Processing /opt/airflow/dags/postgres_to_bigquery_dag.py took 2.331 seconds
[2024-11-26T23:44:45.011+0000] {processor.py:161} INFO - Started process (PID=1331) to work on /opt/airflow/dags/postgres_to_bigquery_dag.py
[2024-11-26T23:44:45.016+0000] {processor.py:830} INFO - Processing file /opt/airflow/dags/postgres_to_bigquery_dag.py for tasks to queue
[2024-11-26T23:44:45.020+0000] {logging_mixin.py:188} INFO - [2024-11-26T23:44:45.019+0000] {dagbag.py:545} INFO - Filling up the DagBag from /opt/airflow/dags/postgres_to_bigquery_dag.py
[2024-11-26T23:44:45.911+0000] {logging_mixin.py:188} INFO - [2024-11-26T23:44:45.906+0000] {dagbag.py:355} ERROR - Failed to import: /opt/airflow/dags/postgres_to_bigquery_dag.py
Traceback (most recent call last):
  File "/home/airflow/.local/lib/python3.12/site-packages/airflow/models/dagbag.py", line 351, in parse
    loader.exec_module(new_module)
  File "<frozen importlib._bootstrap_external>", line 995, in exec_module
  File "<frozen importlib._bootstrap>", line 488, in _call_with_frames_removed
  File "/opt/airflow/dags/postgres_to_bigquery_dag.py", line 40, in <module>
    credentials = service_account.Credentials.from_service_account_file(f"/opt/airflow/data/key/{getenv('key')}")
                  ^^^^^^^^^^^^^^^^^^^^^^^^^^^^^^^^^^^^^^^^^^^^^^^^^^^^^^^^^^^^^^^^^^^^^^^^^^^^^^^^^^^^^^^^^^^^^^^
  File "/home/airflow/.local/lib/python3.12/site-packages/google/oauth2/service_account.py", line 259, in from_service_account_file
    info, signer = _service_account_info.from_filename(
                   ^^^^^^^^^^^^^^^^^^^^^^^^^^^^^^^^^^^^
  File "/home/airflow/.local/lib/python3.12/site-packages/google/auth/_service_account_info.py", line 78, in from_filename
    with io.open(filename, "r", encoding="utf-8") as json_file:
         ^^^^^^^^^^^^^^^^^^^^^^^^^^^^^^^^^^^^^^^^
FileNotFoundError: [Errno 2] No such file or directory: '/opt/airflow/data/key/None'
[2024-11-26T23:44:45.912+0000] {processor.py:842} WARNING - No viable dags retrieved from /opt/airflow/dags/postgres_to_bigquery_dag.py
[2024-11-26T23:44:45.952+0000] {processor.py:183} INFO - Processing /opt/airflow/dags/postgres_to_bigquery_dag.py took 0.953 seconds
[2024-11-26T23:45:16.768+0000] {processor.py:161} INFO - Started process (PID=1349) to work on /opt/airflow/dags/postgres_to_bigquery_dag.py
[2024-11-26T23:45:16.770+0000] {processor.py:830} INFO - Processing file /opt/airflow/dags/postgres_to_bigquery_dag.py for tasks to queue
[2024-11-26T23:45:16.774+0000] {logging_mixin.py:188} INFO - [2024-11-26T23:45:16.774+0000] {dagbag.py:545} INFO - Filling up the DagBag from /opt/airflow/dags/postgres_to_bigquery_dag.py
[2024-11-26T23:45:18.113+0000] {logging_mixin.py:188} INFO - [2024-11-26T23:45:18.105+0000] {dagbag.py:355} ERROR - Failed to import: /opt/airflow/dags/postgres_to_bigquery_dag.py
Traceback (most recent call last):
  File "/home/airflow/.local/lib/python3.12/site-packages/airflow/models/dagbag.py", line 351, in parse
    loader.exec_module(new_module)
  File "<frozen importlib._bootstrap_external>", line 995, in exec_module
  File "<frozen importlib._bootstrap>", line 488, in _call_with_frames_removed
  File "/opt/airflow/dags/postgres_to_bigquery_dag.py", line 40, in <module>
    credentials = service_account.Credentials.from_service_account_file(f"/opt/airflow/data/key/{getenv('key')}")
                  ^^^^^^^^^^^^^^^^^^^^^^^^^^^^^^^^^^^^^^^^^^^^^^^^^^^^^^^^^^^^^^^^^^^^^^^^^^^^^^^^^^^^^^^^^^^^^^^
  File "/home/airflow/.local/lib/python3.12/site-packages/google/oauth2/service_account.py", line 259, in from_service_account_file
    info, signer = _service_account_info.from_filename(
                   ^^^^^^^^^^^^^^^^^^^^^^^^^^^^^^^^^^^^
  File "/home/airflow/.local/lib/python3.12/site-packages/google/auth/_service_account_info.py", line 78, in from_filename
    with io.open(filename, "r", encoding="utf-8") as json_file:
         ^^^^^^^^^^^^^^^^^^^^^^^^^^^^^^^^^^^^^^^^
FileNotFoundError: [Errno 2] No such file or directory: '/opt/airflow/data/key/None'
[2024-11-26T23:45:18.117+0000] {processor.py:842} WARNING - No viable dags retrieved from /opt/airflow/dags/postgres_to_bigquery_dag.py
[2024-11-26T23:45:18.171+0000] {processor.py:183} INFO - Processing /opt/airflow/dags/postgres_to_bigquery_dag.py took 1.418 seconds
[2024-11-26T23:45:49.094+0000] {processor.py:161} INFO - Started process (PID=1367) to work on /opt/airflow/dags/postgres_to_bigquery_dag.py
[2024-11-26T23:45:49.096+0000] {processor.py:830} INFO - Processing file /opt/airflow/dags/postgres_to_bigquery_dag.py for tasks to queue
[2024-11-26T23:45:49.099+0000] {logging_mixin.py:188} INFO - [2024-11-26T23:45:49.099+0000] {dagbag.py:545} INFO - Filling up the DagBag from /opt/airflow/dags/postgres_to_bigquery_dag.py
[2024-11-26T23:45:50.311+0000] {logging_mixin.py:188} INFO - [2024-11-26T23:45:50.307+0000] {dagbag.py:355} ERROR - Failed to import: /opt/airflow/dags/postgres_to_bigquery_dag.py
Traceback (most recent call last):
  File "/home/airflow/.local/lib/python3.12/site-packages/airflow/models/dagbag.py", line 351, in parse
    loader.exec_module(new_module)
  File "<frozen importlib._bootstrap_external>", line 995, in exec_module
  File "<frozen importlib._bootstrap>", line 488, in _call_with_frames_removed
  File "/opt/airflow/dags/postgres_to_bigquery_dag.py", line 40, in <module>
    credentials = service_account.Credentials.from_service_account_file(f"/opt/airflow/data/key/{getenv('key')}")
                  ^^^^^^^^^^^^^^^^^^^^^^^^^^^^^^^^^^^^^^^^^^^^^^^^^^^^^^^^^^^^^^^^^^^^^^^^^^^^^^^^^^^^^^^^^^^^^^^
  File "/home/airflow/.local/lib/python3.12/site-packages/google/oauth2/service_account.py", line 259, in from_service_account_file
    info, signer = _service_account_info.from_filename(
                   ^^^^^^^^^^^^^^^^^^^^^^^^^^^^^^^^^^^^
  File "/home/airflow/.local/lib/python3.12/site-packages/google/auth/_service_account_info.py", line 78, in from_filename
    with io.open(filename, "r", encoding="utf-8") as json_file:
         ^^^^^^^^^^^^^^^^^^^^^^^^^^^^^^^^^^^^^^^^
FileNotFoundError: [Errno 2] No such file or directory: '/opt/airflow/data/key/None'
[2024-11-26T23:45:50.312+0000] {processor.py:842} WARNING - No viable dags retrieved from /opt/airflow/dags/postgres_to_bigquery_dag.py
[2024-11-26T23:45:50.343+0000] {processor.py:183} INFO - Processing /opt/airflow/dags/postgres_to_bigquery_dag.py took 1.263 seconds
[2024-11-26T23:46:20.961+0000] {processor.py:161} INFO - Started process (PID=1385) to work on /opt/airflow/dags/postgres_to_bigquery_dag.py
[2024-11-26T23:46:20.963+0000] {processor.py:830} INFO - Processing file /opt/airflow/dags/postgres_to_bigquery_dag.py for tasks to queue
[2024-11-26T23:46:20.967+0000] {logging_mixin.py:188} INFO - [2024-11-26T23:46:20.966+0000] {dagbag.py:545} INFO - Filling up the DagBag from /opt/airflow/dags/postgres_to_bigquery_dag.py
[2024-11-26T23:46:22.816+0000] {logging_mixin.py:188} INFO - [2024-11-26T23:46:22.798+0000] {dagbag.py:355} ERROR - Failed to import: /opt/airflow/dags/postgres_to_bigquery_dag.py
Traceback (most recent call last):
  File "/home/airflow/.local/lib/python3.12/site-packages/airflow/models/dagbag.py", line 351, in parse
    loader.exec_module(new_module)
  File "<frozen importlib._bootstrap_external>", line 995, in exec_module
  File "<frozen importlib._bootstrap>", line 488, in _call_with_frames_removed
  File "/opt/airflow/dags/postgres_to_bigquery_dag.py", line 40, in <module>
    credentials = service_account.Credentials.from_service_account_file(f"/opt/airflow/data/key/{getenv('key')}")
                  ^^^^^^^^^^^^^^^^^^^^^^^^^^^^^^^^^^^^^^^^^^^^^^^^^^^^^^^^^^^^^^^^^^^^^^^^^^^^^^^^^^^^^^^^^^^^^^^
  File "/home/airflow/.local/lib/python3.12/site-packages/google/oauth2/service_account.py", line 259, in from_service_account_file
    info, signer = _service_account_info.from_filename(
                   ^^^^^^^^^^^^^^^^^^^^^^^^^^^^^^^^^^^^
  File "/home/airflow/.local/lib/python3.12/site-packages/google/auth/_service_account_info.py", line 78, in from_filename
    with io.open(filename, "r", encoding="utf-8") as json_file:
         ^^^^^^^^^^^^^^^^^^^^^^^^^^^^^^^^^^^^^^^^
FileNotFoundError: [Errno 2] No such file or directory: '/opt/airflow/data/key/None'
[2024-11-26T23:46:22.819+0000] {processor.py:842} WARNING - No viable dags retrieved from /opt/airflow/dags/postgres_to_bigquery_dag.py
[2024-11-26T23:46:22.905+0000] {processor.py:183} INFO - Processing /opt/airflow/dags/postgres_to_bigquery_dag.py took 1.963 seconds
[2024-11-26T23:46:53.278+0000] {processor.py:161} INFO - Started process (PID=1403) to work on /opt/airflow/dags/postgres_to_bigquery_dag.py
[2024-11-26T23:46:53.280+0000] {processor.py:830} INFO - Processing file /opt/airflow/dags/postgres_to_bigquery_dag.py for tasks to queue
[2024-11-26T23:46:53.284+0000] {logging_mixin.py:188} INFO - [2024-11-26T23:46:53.283+0000] {dagbag.py:545} INFO - Filling up the DagBag from /opt/airflow/dags/postgres_to_bigquery_dag.py
[2024-11-26T23:46:54.528+0000] {logging_mixin.py:188} INFO - [2024-11-26T23:46:54.521+0000] {dagbag.py:355} ERROR - Failed to import: /opt/airflow/dags/postgres_to_bigquery_dag.py
Traceback (most recent call last):
  File "/home/airflow/.local/lib/python3.12/site-packages/airflow/models/dagbag.py", line 351, in parse
    loader.exec_module(new_module)
  File "<frozen importlib._bootstrap_external>", line 995, in exec_module
  File "<frozen importlib._bootstrap>", line 488, in _call_with_frames_removed
  File "/opt/airflow/dags/postgres_to_bigquery_dag.py", line 40, in <module>
    credentials = service_account.Credentials.from_service_account_file(f"/opt/airflow/data/key/{getenv('key')}")
                  ^^^^^^^^^^^^^^^^^^^^^^^^^^^^^^^^^^^^^^^^^^^^^^^^^^^^^^^^^^^^^^^^^^^^^^^^^^^^^^^^^^^^^^^^^^^^^^^
  File "/home/airflow/.local/lib/python3.12/site-packages/google/oauth2/service_account.py", line 259, in from_service_account_file
    info, signer = _service_account_info.from_filename(
                   ^^^^^^^^^^^^^^^^^^^^^^^^^^^^^^^^^^^^
  File "/home/airflow/.local/lib/python3.12/site-packages/google/auth/_service_account_info.py", line 78, in from_filename
    with io.open(filename, "r", encoding="utf-8") as json_file:
         ^^^^^^^^^^^^^^^^^^^^^^^^^^^^^^^^^^^^^^^^
FileNotFoundError: [Errno 2] No such file or directory: '/opt/airflow/data/key/None'
[2024-11-26T23:46:54.529+0000] {processor.py:842} WARNING - No viable dags retrieved from /opt/airflow/dags/postgres_to_bigquery_dag.py
[2024-11-26T23:46:54.566+0000] {processor.py:183} INFO - Processing /opt/airflow/dags/postgres_to_bigquery_dag.py took 1.297 seconds
[2024-11-26T23:47:24.874+0000] {processor.py:161} INFO - Started process (PID=1421) to work on /opt/airflow/dags/postgres_to_bigquery_dag.py
[2024-11-26T23:47:24.876+0000] {processor.py:830} INFO - Processing file /opt/airflow/dags/postgres_to_bigquery_dag.py for tasks to queue
[2024-11-26T23:47:24.881+0000] {logging_mixin.py:188} INFO - [2024-11-26T23:47:24.880+0000] {dagbag.py:545} INFO - Filling up the DagBag from /opt/airflow/dags/postgres_to_bigquery_dag.py
[2024-11-26T23:47:26.802+0000] {logging_mixin.py:188} INFO - [2024-11-26T23:47:26.789+0000] {dagbag.py:355} ERROR - Failed to import: /opt/airflow/dags/postgres_to_bigquery_dag.py
Traceback (most recent call last):
  File "/home/airflow/.local/lib/python3.12/site-packages/airflow/models/dagbag.py", line 351, in parse
    loader.exec_module(new_module)
  File "<frozen importlib._bootstrap_external>", line 995, in exec_module
  File "<frozen importlib._bootstrap>", line 488, in _call_with_frames_removed
  File "/opt/airflow/dags/postgres_to_bigquery_dag.py", line 40, in <module>
    credentials = service_account.Credentials.from_service_account_file(f"/opt/airflow/data/key/{getenv('key')}")
                  ^^^^^^^^^^^^^^^^^^^^^^^^^^^^^^^^^^^^^^^^^^^^^^^^^^^^^^^^^^^^^^^^^^^^^^^^^^^^^^^^^^^^^^^^^^^^^^^
  File "/home/airflow/.local/lib/python3.12/site-packages/google/oauth2/service_account.py", line 259, in from_service_account_file
    info, signer = _service_account_info.from_filename(
                   ^^^^^^^^^^^^^^^^^^^^^^^^^^^^^^^^^^^^
  File "/home/airflow/.local/lib/python3.12/site-packages/google/auth/_service_account_info.py", line 78, in from_filename
    with io.open(filename, "r", encoding="utf-8") as json_file:
         ^^^^^^^^^^^^^^^^^^^^^^^^^^^^^^^^^^^^^^^^
FileNotFoundError: [Errno 2] No such file or directory: '/opt/airflow/data/key/None'
[2024-11-26T23:47:26.804+0000] {processor.py:842} WARNING - No viable dags retrieved from /opt/airflow/dags/postgres_to_bigquery_dag.py
[2024-11-26T23:47:26.851+0000] {processor.py:183} INFO - Processing /opt/airflow/dags/postgres_to_bigquery_dag.py took 1.986 seconds
[2024-11-26T23:47:57.281+0000] {processor.py:161} INFO - Started process (PID=1439) to work on /opt/airflow/dags/postgres_to_bigquery_dag.py
[2024-11-26T23:47:57.283+0000] {processor.py:830} INFO - Processing file /opt/airflow/dags/postgres_to_bigquery_dag.py for tasks to queue
[2024-11-26T23:47:57.288+0000] {logging_mixin.py:188} INFO - [2024-11-26T23:47:57.287+0000] {dagbag.py:545} INFO - Filling up the DagBag from /opt/airflow/dags/postgres_to_bigquery_dag.py
[2024-11-26T23:47:58.534+0000] {logging_mixin.py:188} INFO - [2024-11-26T23:47:58.529+0000] {dagbag.py:355} ERROR - Failed to import: /opt/airflow/dags/postgres_to_bigquery_dag.py
Traceback (most recent call last):
  File "/home/airflow/.local/lib/python3.12/site-packages/airflow/models/dagbag.py", line 351, in parse
    loader.exec_module(new_module)
  File "<frozen importlib._bootstrap_external>", line 995, in exec_module
  File "<frozen importlib._bootstrap>", line 488, in _call_with_frames_removed
  File "/opt/airflow/dags/postgres_to_bigquery_dag.py", line 40, in <module>
    credentials = service_account.Credentials.from_service_account_file(f"/opt/airflow/data/key/{getenv('key')}")
                  ^^^^^^^^^^^^^^^^^^^^^^^^^^^^^^^^^^^^^^^^^^^^^^^^^^^^^^^^^^^^^^^^^^^^^^^^^^^^^^^^^^^^^^^^^^^^^^^
  File "/home/airflow/.local/lib/python3.12/site-packages/google/oauth2/service_account.py", line 259, in from_service_account_file
    info, signer = _service_account_info.from_filename(
                   ^^^^^^^^^^^^^^^^^^^^^^^^^^^^^^^^^^^^
  File "/home/airflow/.local/lib/python3.12/site-packages/google/auth/_service_account_info.py", line 78, in from_filename
    with io.open(filename, "r", encoding="utf-8") as json_file:
         ^^^^^^^^^^^^^^^^^^^^^^^^^^^^^^^^^^^^^^^^
FileNotFoundError: [Errno 2] No such file or directory: '/opt/airflow/data/key/None'
[2024-11-26T23:47:58.535+0000] {processor.py:842} WARNING - No viable dags retrieved from /opt/airflow/dags/postgres_to_bigquery_dag.py
[2024-11-26T23:47:58.558+0000] {processor.py:183} INFO - Processing /opt/airflow/dags/postgres_to_bigquery_dag.py took 1.290 seconds
[2024-11-26T23:48:28.941+0000] {processor.py:161} INFO - Started process (PID=1457) to work on /opt/airflow/dags/postgres_to_bigquery_dag.py
[2024-11-26T23:48:28.943+0000] {processor.py:830} INFO - Processing file /opt/airflow/dags/postgres_to_bigquery_dag.py for tasks to queue
[2024-11-26T23:48:28.957+0000] {logging_mixin.py:188} INFO - [2024-11-26T23:48:28.951+0000] {dagbag.py:545} INFO - Filling up the DagBag from /opt/airflow/dags/postgres_to_bigquery_dag.py
[2024-11-26T23:48:31.628+0000] {logging_mixin.py:188} INFO - [2024-11-26T23:48:31.617+0000] {dagbag.py:355} ERROR - Failed to import: /opt/airflow/dags/postgres_to_bigquery_dag.py
Traceback (most recent call last):
  File "/home/airflow/.local/lib/python3.12/site-packages/airflow/models/dagbag.py", line 351, in parse
    loader.exec_module(new_module)
  File "<frozen importlib._bootstrap_external>", line 995, in exec_module
  File "<frozen importlib._bootstrap>", line 488, in _call_with_frames_removed
  File "/opt/airflow/dags/postgres_to_bigquery_dag.py", line 40, in <module>
    credentials = service_account.Credentials.from_service_account_file(f"/opt/airflow/data/key/{getenv('key')}")
                  ^^^^^^^^^^^^^^^^^^^^^^^^^^^^^^^^^^^^^^^^^^^^^^^^^^^^^^^^^^^^^^^^^^^^^^^^^^^^^^^^^^^^^^^^^^^^^^^
  File "/home/airflow/.local/lib/python3.12/site-packages/google/oauth2/service_account.py", line 259, in from_service_account_file
    info, signer = _service_account_info.from_filename(
                   ^^^^^^^^^^^^^^^^^^^^^^^^^^^^^^^^^^^^
  File "/home/airflow/.local/lib/python3.12/site-packages/google/auth/_service_account_info.py", line 78, in from_filename
    with io.open(filename, "r", encoding="utf-8") as json_file:
         ^^^^^^^^^^^^^^^^^^^^^^^^^^^^^^^^^^^^^^^^
FileNotFoundError: [Errno 2] No such file or directory: '/opt/airflow/data/key/None'
[2024-11-26T23:48:31.631+0000] {processor.py:842} WARNING - No viable dags retrieved from /opt/airflow/dags/postgres_to_bigquery_dag.py
[2024-11-26T23:48:31.676+0000] {processor.py:183} INFO - Processing /opt/airflow/dags/postgres_to_bigquery_dag.py took 2.746 seconds
[2024-11-26T23:49:02.317+0000] {processor.py:161} INFO - Started process (PID=1485) to work on /opt/airflow/dags/postgres_to_bigquery_dag.py
[2024-11-26T23:49:02.339+0000] {processor.py:830} INFO - Processing file /opt/airflow/dags/postgres_to_bigquery_dag.py for tasks to queue
[2024-11-26T23:49:02.354+0000] {logging_mixin.py:188} INFO - [2024-11-26T23:49:02.353+0000] {dagbag.py:545} INFO - Filling up the DagBag from /opt/airflow/dags/postgres_to_bigquery_dag.py
[2024-11-26T23:49:04.064+0000] {logging_mixin.py:188} INFO - [2024-11-26T23:49:04.058+0000] {dagbag.py:355} ERROR - Failed to import: /opt/airflow/dags/postgres_to_bigquery_dag.py
Traceback (most recent call last):
  File "/home/airflow/.local/lib/python3.12/site-packages/airflow/models/dagbag.py", line 351, in parse
    loader.exec_module(new_module)
  File "<frozen importlib._bootstrap_external>", line 995, in exec_module
  File "<frozen importlib._bootstrap>", line 488, in _call_with_frames_removed
  File "/opt/airflow/dags/postgres_to_bigquery_dag.py", line 40, in <module>
    credentials = service_account.Credentials.from_service_account_file(f"/opt/airflow/data/key/{getenv('key')}")
                  ^^^^^^^^^^^^^^^^^^^^^^^^^^^^^^^^^^^^^^^^^^^^^^^^^^^^^^^^^^^^^^^^^^^^^^^^^^^^^^^^^^^^^^^^^^^^^^^
  File "/home/airflow/.local/lib/python3.12/site-packages/google/oauth2/service_account.py", line 259, in from_service_account_file
    info, signer = _service_account_info.from_filename(
                   ^^^^^^^^^^^^^^^^^^^^^^^^^^^^^^^^^^^^
  File "/home/airflow/.local/lib/python3.12/site-packages/google/auth/_service_account_info.py", line 78, in from_filename
    with io.open(filename, "r", encoding="utf-8") as json_file:
         ^^^^^^^^^^^^^^^^^^^^^^^^^^^^^^^^^^^^^^^^
FileNotFoundError: [Errno 2] No such file or directory: '/opt/airflow/data/key/None'
[2024-11-26T23:49:04.065+0000] {processor.py:842} WARNING - No viable dags retrieved from /opt/airflow/dags/postgres_to_bigquery_dag.py
[2024-11-26T23:49:04.121+0000] {processor.py:183} INFO - Processing /opt/airflow/dags/postgres_to_bigquery_dag.py took 1.826 seconds
[2024-11-26T23:49:34.406+0000] {processor.py:161} INFO - Started process (PID=1505) to work on /opt/airflow/dags/postgres_to_bigquery_dag.py
[2024-11-26T23:49:34.407+0000] {processor.py:830} INFO - Processing file /opt/airflow/dags/postgres_to_bigquery_dag.py for tasks to queue
[2024-11-26T23:49:34.409+0000] {logging_mixin.py:188} INFO - [2024-11-26T23:49:34.409+0000] {dagbag.py:545} INFO - Filling up the DagBag from /opt/airflow/dags/postgres_to_bigquery_dag.py
[2024-11-26T23:49:35.344+0000] {logging_mixin.py:188} INFO - [2024-11-26T23:49:35.340+0000] {dagbag.py:355} ERROR - Failed to import: /opt/airflow/dags/postgres_to_bigquery_dag.py
Traceback (most recent call last):
  File "/home/airflow/.local/lib/python3.12/site-packages/airflow/models/dagbag.py", line 351, in parse
    loader.exec_module(new_module)
  File "<frozen importlib._bootstrap_external>", line 995, in exec_module
  File "<frozen importlib._bootstrap>", line 488, in _call_with_frames_removed
  File "/opt/airflow/dags/postgres_to_bigquery_dag.py", line 40, in <module>
    credentials = service_account.Credentials.from_service_account_file(f"/opt/airflow/data/key/{getenv('key')}")
                  ^^^^^^^^^^^^^^^^^^^^^^^^^^^^^^^^^^^^^^^^^^^^^^^^^^^^^^^^^^^^^^^^^^^^^^^^^^^^^^^^^^^^^^^^^^^^^^^
  File "/home/airflow/.local/lib/python3.12/site-packages/google/oauth2/service_account.py", line 259, in from_service_account_file
    info, signer = _service_account_info.from_filename(
                   ^^^^^^^^^^^^^^^^^^^^^^^^^^^^^^^^^^^^
  File "/home/airflow/.local/lib/python3.12/site-packages/google/auth/_service_account_info.py", line 78, in from_filename
    with io.open(filename, "r", encoding="utf-8") as json_file:
         ^^^^^^^^^^^^^^^^^^^^^^^^^^^^^^^^^^^^^^^^
FileNotFoundError: [Errno 2] No such file or directory: '/opt/airflow/data/key/None'
[2024-11-26T23:49:35.346+0000] {processor.py:842} WARNING - No viable dags retrieved from /opt/airflow/dags/postgres_to_bigquery_dag.py
[2024-11-26T23:49:35.370+0000] {processor.py:183} INFO - Processing /opt/airflow/dags/postgres_to_bigquery_dag.py took 0.971 seconds
[2024-11-26T23:50:05.838+0000] {processor.py:161} INFO - Started process (PID=1521) to work on /opt/airflow/dags/postgres_to_bigquery_dag.py
[2024-11-26T23:50:05.840+0000] {processor.py:830} INFO - Processing file /opt/airflow/dags/postgres_to_bigquery_dag.py for tasks to queue
[2024-11-26T23:50:05.843+0000] {logging_mixin.py:188} INFO - [2024-11-26T23:50:05.843+0000] {dagbag.py:545} INFO - Filling up the DagBag from /opt/airflow/dags/postgres_to_bigquery_dag.py
[2024-11-26T23:50:07.028+0000] {logging_mixin.py:188} INFO - [2024-11-26T23:50:07.020+0000] {dagbag.py:355} ERROR - Failed to import: /opt/airflow/dags/postgres_to_bigquery_dag.py
Traceback (most recent call last):
  File "/home/airflow/.local/lib/python3.12/site-packages/airflow/models/dagbag.py", line 351, in parse
    loader.exec_module(new_module)
  File "<frozen importlib._bootstrap_external>", line 995, in exec_module
  File "<frozen importlib._bootstrap>", line 488, in _call_with_frames_removed
  File "/opt/airflow/dags/postgres_to_bigquery_dag.py", line 40, in <module>
    credentials = service_account.Credentials.from_service_account_file(f"/opt/airflow/data/key/{getenv('key')}")
                  ^^^^^^^^^^^^^^^^^^^^^^^^^^^^^^^^^^^^^^^^^^^^^^^^^^^^^^^^^^^^^^^^^^^^^^^^^^^^^^^^^^^^^^^^^^^^^^^
  File "/home/airflow/.local/lib/python3.12/site-packages/google/oauth2/service_account.py", line 259, in from_service_account_file
    info, signer = _service_account_info.from_filename(
                   ^^^^^^^^^^^^^^^^^^^^^^^^^^^^^^^^^^^^
  File "/home/airflow/.local/lib/python3.12/site-packages/google/auth/_service_account_info.py", line 78, in from_filename
    with io.open(filename, "r", encoding="utf-8") as json_file:
         ^^^^^^^^^^^^^^^^^^^^^^^^^^^^^^^^^^^^^^^^
FileNotFoundError: [Errno 2] No such file or directory: '/opt/airflow/data/key/None'
[2024-11-26T23:50:07.029+0000] {processor.py:842} WARNING - No viable dags retrieved from /opt/airflow/dags/postgres_to_bigquery_dag.py
[2024-11-26T23:50:07.059+0000] {processor.py:183} INFO - Processing /opt/airflow/dags/postgres_to_bigquery_dag.py took 1.234 seconds
[2024-11-26T23:50:37.487+0000] {processor.py:161} INFO - Started process (PID=1541) to work on /opt/airflow/dags/postgres_to_bigquery_dag.py
[2024-11-26T23:50:37.489+0000] {processor.py:830} INFO - Processing file /opt/airflow/dags/postgres_to_bigquery_dag.py for tasks to queue
[2024-11-26T23:50:37.493+0000] {logging_mixin.py:188} INFO - [2024-11-26T23:50:37.492+0000] {dagbag.py:545} INFO - Filling up the DagBag from /opt/airflow/dags/postgres_to_bigquery_dag.py
[2024-11-26T23:50:38.529+0000] {logging_mixin.py:188} INFO - [2024-11-26T23:50:38.522+0000] {dagbag.py:355} ERROR - Failed to import: /opt/airflow/dags/postgres_to_bigquery_dag.py
Traceback (most recent call last):
  File "/home/airflow/.local/lib/python3.12/site-packages/airflow/models/dagbag.py", line 351, in parse
    loader.exec_module(new_module)
  File "<frozen importlib._bootstrap_external>", line 995, in exec_module
  File "<frozen importlib._bootstrap>", line 488, in _call_with_frames_removed
  File "/opt/airflow/dags/postgres_to_bigquery_dag.py", line 40, in <module>
    credentials = service_account.Credentials.from_service_account_file(f"/opt/airflow/data/key/{getenv('key')}")
                  ^^^^^^^^^^^^^^^^^^^^^^^^^^^^^^^^^^^^^^^^^^^^^^^^^^^^^^^^^^^^^^^^^^^^^^^^^^^^^^^^^^^^^^^^^^^^^^^
  File "/home/airflow/.local/lib/python3.12/site-packages/google/oauth2/service_account.py", line 259, in from_service_account_file
    info, signer = _service_account_info.from_filename(
                   ^^^^^^^^^^^^^^^^^^^^^^^^^^^^^^^^^^^^
  File "/home/airflow/.local/lib/python3.12/site-packages/google/auth/_service_account_info.py", line 78, in from_filename
    with io.open(filename, "r", encoding="utf-8") as json_file:
         ^^^^^^^^^^^^^^^^^^^^^^^^^^^^^^^^^^^^^^^^
FileNotFoundError: [Errno 2] No such file or directory: '/opt/airflow/data/key/None'
[2024-11-26T23:50:38.531+0000] {processor.py:842} WARNING - No viable dags retrieved from /opt/airflow/dags/postgres_to_bigquery_dag.py
[2024-11-26T23:50:38.580+0000] {processor.py:183} INFO - Processing /opt/airflow/dags/postgres_to_bigquery_dag.py took 1.101 seconds
[2024-11-26T23:51:08.967+0000] {processor.py:161} INFO - Started process (PID=1556) to work on /opt/airflow/dags/postgres_to_bigquery_dag.py
[2024-11-26T23:51:08.969+0000] {processor.py:830} INFO - Processing file /opt/airflow/dags/postgres_to_bigquery_dag.py for tasks to queue
[2024-11-26T23:51:08.974+0000] {logging_mixin.py:188} INFO - [2024-11-26T23:51:08.973+0000] {dagbag.py:545} INFO - Filling up the DagBag from /opt/airflow/dags/postgres_to_bigquery_dag.py
[2024-11-26T23:51:10.770+0000] {logging_mixin.py:188} INFO - [2024-11-26T23:51:10.763+0000] {dagbag.py:355} ERROR - Failed to import: /opt/airflow/dags/postgres_to_bigquery_dag.py
Traceback (most recent call last):
  File "/home/airflow/.local/lib/python3.12/site-packages/airflow/models/dagbag.py", line 351, in parse
    loader.exec_module(new_module)
  File "<frozen importlib._bootstrap_external>", line 995, in exec_module
  File "<frozen importlib._bootstrap>", line 488, in _call_with_frames_removed
  File "/opt/airflow/dags/postgres_to_bigquery_dag.py", line 40, in <module>
    credentials = service_account.Credentials.from_service_account_file(f"/opt/airflow/data/key/{getenv('key')}")
                  ^^^^^^^^^^^^^^^^^^^^^^^^^^^^^^^^^^^^^^^^^^^^^^^^^^^^^^^^^^^^^^^^^^^^^^^^^^^^^^^^^^^^^^^^^^^^^^^
  File "/home/airflow/.local/lib/python3.12/site-packages/google/oauth2/service_account.py", line 259, in from_service_account_file
    info, signer = _service_account_info.from_filename(
                   ^^^^^^^^^^^^^^^^^^^^^^^^^^^^^^^^^^^^
  File "/home/airflow/.local/lib/python3.12/site-packages/google/auth/_service_account_info.py", line 78, in from_filename
    with io.open(filename, "r", encoding="utf-8") as json_file:
         ^^^^^^^^^^^^^^^^^^^^^^^^^^^^^^^^^^^^^^^^
FileNotFoundError: [Errno 2] No such file or directory: '/opt/airflow/data/key/None'
[2024-11-26T23:51:10.777+0000] {processor.py:842} WARNING - No viable dags retrieved from /opt/airflow/dags/postgres_to_bigquery_dag.py
[2024-11-26T23:51:10.840+0000] {processor.py:183} INFO - Processing /opt/airflow/dags/postgres_to_bigquery_dag.py took 1.888 seconds
[2024-11-26T23:51:41.238+0000] {processor.py:161} INFO - Started process (PID=1578) to work on /opt/airflow/dags/postgres_to_bigquery_dag.py
[2024-11-26T23:51:41.241+0000] {processor.py:830} INFO - Processing file /opt/airflow/dags/postgres_to_bigquery_dag.py for tasks to queue
[2024-11-26T23:51:41.244+0000] {logging_mixin.py:188} INFO - [2024-11-26T23:51:41.243+0000] {dagbag.py:545} INFO - Filling up the DagBag from /opt/airflow/dags/postgres_to_bigquery_dag.py
[2024-11-26T23:51:42.191+0000] {logging_mixin.py:188} INFO - [2024-11-26T23:51:42.183+0000] {dagbag.py:355} ERROR - Failed to import: /opt/airflow/dags/postgres_to_bigquery_dag.py
Traceback (most recent call last):
  File "/home/airflow/.local/lib/python3.12/site-packages/airflow/models/dagbag.py", line 351, in parse
    loader.exec_module(new_module)
  File "<frozen importlib._bootstrap_external>", line 995, in exec_module
  File "<frozen importlib._bootstrap>", line 488, in _call_with_frames_removed
  File "/opt/airflow/dags/postgres_to_bigquery_dag.py", line 40, in <module>
    credentials = service_account.Credentials.from_service_account_file(f"/opt/airflow/data/key/{getenv('key')}")
                  ^^^^^^^^^^^^^^^^^^^^^^^^^^^^^^^^^^^^^^^^^^^^^^^^^^^^^^^^^^^^^^^^^^^^^^^^^^^^^^^^^^^^^^^^^^^^^^^
  File "/home/airflow/.local/lib/python3.12/site-packages/google/oauth2/service_account.py", line 259, in from_service_account_file
    info, signer = _service_account_info.from_filename(
                   ^^^^^^^^^^^^^^^^^^^^^^^^^^^^^^^^^^^^
  File "/home/airflow/.local/lib/python3.12/site-packages/google/auth/_service_account_info.py", line 78, in from_filename
    with io.open(filename, "r", encoding="utf-8") as json_file:
         ^^^^^^^^^^^^^^^^^^^^^^^^^^^^^^^^^^^^^^^^
FileNotFoundError: [Errno 2] No such file or directory: '/opt/airflow/data/key/None'
[2024-11-26T23:51:42.193+0000] {processor.py:842} WARNING - No viable dags retrieved from /opt/airflow/dags/postgres_to_bigquery_dag.py
[2024-11-26T23:51:42.237+0000] {processor.py:183} INFO - Processing /opt/airflow/dags/postgres_to_bigquery_dag.py took 1.009 seconds
[2024-11-26T23:52:12.775+0000] {processor.py:161} INFO - Started process (PID=1595) to work on /opt/airflow/dags/postgres_to_bigquery_dag.py
[2024-11-26T23:52:12.787+0000] {processor.py:830} INFO - Processing file /opt/airflow/dags/postgres_to_bigquery_dag.py for tasks to queue
[2024-11-26T23:52:12.793+0000] {logging_mixin.py:188} INFO - [2024-11-26T23:52:12.792+0000] {dagbag.py:545} INFO - Filling up the DagBag from /opt/airflow/dags/postgres_to_bigquery_dag.py
[2024-11-26T23:52:14.930+0000] {logging_mixin.py:188} INFO - [2024-11-26T23:52:14.903+0000] {dagbag.py:355} ERROR - Failed to import: /opt/airflow/dags/postgres_to_bigquery_dag.py
Traceback (most recent call last):
  File "/home/airflow/.local/lib/python3.12/site-packages/airflow/models/dagbag.py", line 351, in parse
    loader.exec_module(new_module)
  File "<frozen importlib._bootstrap_external>", line 995, in exec_module
  File "<frozen importlib._bootstrap>", line 488, in _call_with_frames_removed
  File "/opt/airflow/dags/postgres_to_bigquery_dag.py", line 40, in <module>
    credentials = service_account.Credentials.from_service_account_file(f"/opt/airflow/data/key/{getenv('key')}")
                  ^^^^^^^^^^^^^^^^^^^^^^^^^^^^^^^^^^^^^^^^^^^^^^^^^^^^^^^^^^^^^^^^^^^^^^^^^^^^^^^^^^^^^^^^^^^^^^^
  File "/home/airflow/.local/lib/python3.12/site-packages/google/oauth2/service_account.py", line 259, in from_service_account_file
    info, signer = _service_account_info.from_filename(
                   ^^^^^^^^^^^^^^^^^^^^^^^^^^^^^^^^^^^^
  File "/home/airflow/.local/lib/python3.12/site-packages/google/auth/_service_account_info.py", line 78, in from_filename
    with io.open(filename, "r", encoding="utf-8") as json_file:
         ^^^^^^^^^^^^^^^^^^^^^^^^^^^^^^^^^^^^^^^^
FileNotFoundError: [Errno 2] No such file or directory: '/opt/airflow/data/key/None'
[2024-11-26T23:52:14.933+0000] {processor.py:842} WARNING - No viable dags retrieved from /opt/airflow/dags/postgres_to_bigquery_dag.py
[2024-11-26T23:52:14.999+0000] {processor.py:183} INFO - Processing /opt/airflow/dags/postgres_to_bigquery_dag.py took 2.252 seconds
[2024-11-26T23:52:45.423+0000] {processor.py:161} INFO - Started process (PID=1614) to work on /opt/airflow/dags/postgres_to_bigquery_dag.py
[2024-11-26T23:52:45.424+0000] {processor.py:830} INFO - Processing file /opt/airflow/dags/postgres_to_bigquery_dag.py for tasks to queue
[2024-11-26T23:52:45.429+0000] {logging_mixin.py:188} INFO - [2024-11-26T23:52:45.427+0000] {dagbag.py:545} INFO - Filling up the DagBag from /opt/airflow/dags/postgres_to_bigquery_dag.py
[2024-11-26T23:52:46.598+0000] {logging_mixin.py:188} INFO - [2024-11-26T23:52:46.592+0000] {dagbag.py:355} ERROR - Failed to import: /opt/airflow/dags/postgres_to_bigquery_dag.py
Traceback (most recent call last):
  File "/home/airflow/.local/lib/python3.12/site-packages/airflow/models/dagbag.py", line 351, in parse
    loader.exec_module(new_module)
  File "<frozen importlib._bootstrap_external>", line 995, in exec_module
  File "<frozen importlib._bootstrap>", line 488, in _call_with_frames_removed
  File "/opt/airflow/dags/postgres_to_bigquery_dag.py", line 40, in <module>
    credentials = service_account.Credentials.from_service_account_file(f"/opt/airflow/data/key/{getenv('key')}")
                  ^^^^^^^^^^^^^^^^^^^^^^^^^^^^^^^^^^^^^^^^^^^^^^^^^^^^^^^^^^^^^^^^^^^^^^^^^^^^^^^^^^^^^^^^^^^^^^^
  File "/home/airflow/.local/lib/python3.12/site-packages/google/oauth2/service_account.py", line 259, in from_service_account_file
    info, signer = _service_account_info.from_filename(
                   ^^^^^^^^^^^^^^^^^^^^^^^^^^^^^^^^^^^^
  File "/home/airflow/.local/lib/python3.12/site-packages/google/auth/_service_account_info.py", line 78, in from_filename
    with io.open(filename, "r", encoding="utf-8") as json_file:
         ^^^^^^^^^^^^^^^^^^^^^^^^^^^^^^^^^^^^^^^^
FileNotFoundError: [Errno 2] No such file or directory: '/opt/airflow/data/key/None'
[2024-11-26T23:52:46.599+0000] {processor.py:842} WARNING - No viable dags retrieved from /opt/airflow/dags/postgres_to_bigquery_dag.py
[2024-11-26T23:52:46.636+0000] {processor.py:183} INFO - Processing /opt/airflow/dags/postgres_to_bigquery_dag.py took 1.230 seconds
[2024-11-26T23:53:16.838+0000] {processor.py:161} INFO - Started process (PID=1632) to work on /opt/airflow/dags/postgres_to_bigquery_dag.py
[2024-11-26T23:53:16.853+0000] {processor.py:830} INFO - Processing file /opt/airflow/dags/postgres_to_bigquery_dag.py for tasks to queue
[2024-11-26T23:53:16.856+0000] {logging_mixin.py:188} INFO - [2024-11-26T23:53:16.856+0000] {dagbag.py:545} INFO - Filling up the DagBag from /opt/airflow/dags/postgres_to_bigquery_dag.py
[2024-11-26T23:53:18.208+0000] {logging_mixin.py:188} INFO - [2024-11-26T23:53:18.202+0000] {dagbag.py:355} ERROR - Failed to import: /opt/airflow/dags/postgres_to_bigquery_dag.py
Traceback (most recent call last):
  File "/home/airflow/.local/lib/python3.12/site-packages/airflow/models/dagbag.py", line 351, in parse
    loader.exec_module(new_module)
  File "<frozen importlib._bootstrap_external>", line 995, in exec_module
  File "<frozen importlib._bootstrap>", line 488, in _call_with_frames_removed
  File "/opt/airflow/dags/postgres_to_bigquery_dag.py", line 40, in <module>
    credentials = service_account.Credentials.from_service_account_file(f"/opt/airflow/data/key/{getenv('key')}")
                  ^^^^^^^^^^^^^^^^^^^^^^^^^^^^^^^^^^^^^^^^^^^^^^^^^^^^^^^^^^^^^^^^^^^^^^^^^^^^^^^^^^^^^^^^^^^^^^^
  File "/home/airflow/.local/lib/python3.12/site-packages/google/oauth2/service_account.py", line 259, in from_service_account_file
    info, signer = _service_account_info.from_filename(
                   ^^^^^^^^^^^^^^^^^^^^^^^^^^^^^^^^^^^^
  File "/home/airflow/.local/lib/python3.12/site-packages/google/auth/_service_account_info.py", line 78, in from_filename
    with io.open(filename, "r", encoding="utf-8") as json_file:
         ^^^^^^^^^^^^^^^^^^^^^^^^^^^^^^^^^^^^^^^^
FileNotFoundError: [Errno 2] No such file or directory: '/opt/airflow/data/key/None'
[2024-11-26T23:53:18.210+0000] {processor.py:842} WARNING - No viable dags retrieved from /opt/airflow/dags/postgres_to_bigquery_dag.py
[2024-11-26T23:53:18.271+0000] {processor.py:183} INFO - Processing /opt/airflow/dags/postgres_to_bigquery_dag.py took 1.452 seconds
[2024-11-26T23:53:48.697+0000] {processor.py:161} INFO - Started process (PID=1650) to work on /opt/airflow/dags/postgres_to_bigquery_dag.py
[2024-11-26T23:53:48.699+0000] {processor.py:830} INFO - Processing file /opt/airflow/dags/postgres_to_bigquery_dag.py for tasks to queue
[2024-11-26T23:53:48.702+0000] {logging_mixin.py:188} INFO - [2024-11-26T23:53:48.701+0000] {dagbag.py:545} INFO - Filling up the DagBag from /opt/airflow/dags/postgres_to_bigquery_dag.py
[2024-11-26T23:53:49.775+0000] {logging_mixin.py:188} INFO - [2024-11-26T23:53:49.761+0000] {dagbag.py:355} ERROR - Failed to import: /opt/airflow/dags/postgres_to_bigquery_dag.py
Traceback (most recent call last):
  File "/home/airflow/.local/lib/python3.12/site-packages/airflow/models/dagbag.py", line 351, in parse
    loader.exec_module(new_module)
  File "<frozen importlib._bootstrap_external>", line 995, in exec_module
  File "<frozen importlib._bootstrap>", line 488, in _call_with_frames_removed
  File "/opt/airflow/dags/postgres_to_bigquery_dag.py", line 40, in <module>
    credentials = service_account.Credentials.from_service_account_file(f"/opt/airflow/data/key/{getenv('key')}")
                  ^^^^^^^^^^^^^^^^^^^^^^^^^^^^^^^^^^^^^^^^^^^^^^^^^^^^^^^^^^^^^^^^^^^^^^^^^^^^^^^^^^^^^^^^^^^^^^^
  File "/home/airflow/.local/lib/python3.12/site-packages/google/oauth2/service_account.py", line 259, in from_service_account_file
    info, signer = _service_account_info.from_filename(
                   ^^^^^^^^^^^^^^^^^^^^^^^^^^^^^^^^^^^^
  File "/home/airflow/.local/lib/python3.12/site-packages/google/auth/_service_account_info.py", line 78, in from_filename
    with io.open(filename, "r", encoding="utf-8") as json_file:
         ^^^^^^^^^^^^^^^^^^^^^^^^^^^^^^^^^^^^^^^^
FileNotFoundError: [Errno 2] No such file or directory: '/opt/airflow/data/key/None'
[2024-11-26T23:53:49.777+0000] {processor.py:842} WARNING - No viable dags retrieved from /opt/airflow/dags/postgres_to_bigquery_dag.py
[2024-11-26T23:53:49.838+0000] {processor.py:183} INFO - Processing /opt/airflow/dags/postgres_to_bigquery_dag.py took 1.148 seconds
[2024-11-26T23:54:20.326+0000] {processor.py:161} INFO - Started process (PID=1668) to work on /opt/airflow/dags/postgres_to_bigquery_dag.py
[2024-11-26T23:54:20.332+0000] {processor.py:830} INFO - Processing file /opt/airflow/dags/postgres_to_bigquery_dag.py for tasks to queue
[2024-11-26T23:54:20.339+0000] {logging_mixin.py:188} INFO - [2024-11-26T23:54:20.337+0000] {dagbag.py:545} INFO - Filling up the DagBag from /opt/airflow/dags/postgres_to_bigquery_dag.py
[2024-11-26T23:54:21.705+0000] {logging_mixin.py:188} INFO - [2024-11-26T23:54:21.694+0000] {dagbag.py:355} ERROR - Failed to import: /opt/airflow/dags/postgres_to_bigquery_dag.py
Traceback (most recent call last):
  File "/home/airflow/.local/lib/python3.12/site-packages/airflow/models/dagbag.py", line 351, in parse
    loader.exec_module(new_module)
  File "<frozen importlib._bootstrap_external>", line 995, in exec_module
  File "<frozen importlib._bootstrap>", line 488, in _call_with_frames_removed
  File "/opt/airflow/dags/postgres_to_bigquery_dag.py", line 40, in <module>
    credentials = service_account.Credentials.from_service_account_file(f"/opt/airflow/data/key/{getenv('key')}")
                  ^^^^^^^^^^^^^^^^^^^^^^^^^^^^^^^^^^^^^^^^^^^^^^^^^^^^^^^^^^^^^^^^^^^^^^^^^^^^^^^^^^^^^^^^^^^^^^^
  File "/home/airflow/.local/lib/python3.12/site-packages/google/oauth2/service_account.py", line 259, in from_service_account_file
    info, signer = _service_account_info.from_filename(
                   ^^^^^^^^^^^^^^^^^^^^^^^^^^^^^^^^^^^^
  File "/home/airflow/.local/lib/python3.12/site-packages/google/auth/_service_account_info.py", line 78, in from_filename
    with io.open(filename, "r", encoding="utf-8") as json_file:
         ^^^^^^^^^^^^^^^^^^^^^^^^^^^^^^^^^^^^^^^^
FileNotFoundError: [Errno 2] No such file or directory: '/opt/airflow/data/key/None'
[2024-11-26T23:54:21.707+0000] {processor.py:842} WARNING - No viable dags retrieved from /opt/airflow/dags/postgres_to_bigquery_dag.py
[2024-11-26T23:54:21.753+0000] {processor.py:183} INFO - Processing /opt/airflow/dags/postgres_to_bigquery_dag.py took 1.448 seconds
[2024-11-26T23:54:52.126+0000] {processor.py:161} INFO - Started process (PID=1686) to work on /opt/airflow/dags/postgres_to_bigquery_dag.py
[2024-11-26T23:54:52.127+0000] {processor.py:830} INFO - Processing file /opt/airflow/dags/postgres_to_bigquery_dag.py for tasks to queue
[2024-11-26T23:54:52.130+0000] {logging_mixin.py:188} INFO - [2024-11-26T23:54:52.130+0000] {dagbag.py:545} INFO - Filling up the DagBag from /opt/airflow/dags/postgres_to_bigquery_dag.py
[2024-11-26T23:54:53.298+0000] {logging_mixin.py:188} INFO - [2024-11-26T23:54:53.293+0000] {dagbag.py:355} ERROR - Failed to import: /opt/airflow/dags/postgres_to_bigquery_dag.py
Traceback (most recent call last):
  File "/home/airflow/.local/lib/python3.12/site-packages/airflow/models/dagbag.py", line 351, in parse
    loader.exec_module(new_module)
  File "<frozen importlib._bootstrap_external>", line 995, in exec_module
  File "<frozen importlib._bootstrap>", line 488, in _call_with_frames_removed
  File "/opt/airflow/dags/postgres_to_bigquery_dag.py", line 40, in <module>
    credentials = service_account.Credentials.from_service_account_file(f"/opt/airflow/data/key/{getenv('key')}")
                  ^^^^^^^^^^^^^^^^^^^^^^^^^^^^^^^^^^^^^^^^^^^^^^^^^^^^^^^^^^^^^^^^^^^^^^^^^^^^^^^^^^^^^^^^^^^^^^^
  File "/home/airflow/.local/lib/python3.12/site-packages/google/oauth2/service_account.py", line 259, in from_service_account_file
    info, signer = _service_account_info.from_filename(
                   ^^^^^^^^^^^^^^^^^^^^^^^^^^^^^^^^^^^^
  File "/home/airflow/.local/lib/python3.12/site-packages/google/auth/_service_account_info.py", line 78, in from_filename
    with io.open(filename, "r", encoding="utf-8") as json_file:
         ^^^^^^^^^^^^^^^^^^^^^^^^^^^^^^^^^^^^^^^^
FileNotFoundError: [Errno 2] No such file or directory: '/opt/airflow/data/key/None'
[2024-11-26T23:54:53.299+0000] {processor.py:842} WARNING - No viable dags retrieved from /opt/airflow/dags/postgres_to_bigquery_dag.py
[2024-11-26T23:54:53.324+0000] {processor.py:183} INFO - Processing /opt/airflow/dags/postgres_to_bigquery_dag.py took 1.215 seconds
[2024-11-26T23:55:23.857+0000] {processor.py:161} INFO - Started process (PID=1705) to work on /opt/airflow/dags/postgres_to_bigquery_dag.py
[2024-11-26T23:55:23.859+0000] {processor.py:830} INFO - Processing file /opt/airflow/dags/postgres_to_bigquery_dag.py for tasks to queue
[2024-11-26T23:55:23.862+0000] {logging_mixin.py:188} INFO - [2024-11-26T23:55:23.862+0000] {dagbag.py:545} INFO - Filling up the DagBag from /opt/airflow/dags/postgres_to_bigquery_dag.py
[2024-11-26T23:55:25.225+0000] {logging_mixin.py:188} INFO - [2024-11-26T23:55:25.206+0000] {dagbag.py:355} ERROR - Failed to import: /opt/airflow/dags/postgres_to_bigquery_dag.py
Traceback (most recent call last):
  File "/home/airflow/.local/lib/python3.12/site-packages/airflow/models/dagbag.py", line 351, in parse
    loader.exec_module(new_module)
  File "<frozen importlib._bootstrap_external>", line 995, in exec_module
  File "<frozen importlib._bootstrap>", line 488, in _call_with_frames_removed
  File "/opt/airflow/dags/postgres_to_bigquery_dag.py", line 40, in <module>
    credentials = service_account.Credentials.from_service_account_file(f"/opt/airflow/data/key/{getenv('key')}")
                  ^^^^^^^^^^^^^^^^^^^^^^^^^^^^^^^^^^^^^^^^^^^^^^^^^^^^^^^^^^^^^^^^^^^^^^^^^^^^^^^^^^^^^^^^^^^^^^^
  File "/home/airflow/.local/lib/python3.12/site-packages/google/oauth2/service_account.py", line 259, in from_service_account_file
    info, signer = _service_account_info.from_filename(
                   ^^^^^^^^^^^^^^^^^^^^^^^^^^^^^^^^^^^^
  File "/home/airflow/.local/lib/python3.12/site-packages/google/auth/_service_account_info.py", line 78, in from_filename
    with io.open(filename, "r", encoding="utf-8") as json_file:
         ^^^^^^^^^^^^^^^^^^^^^^^^^^^^^^^^^^^^^^^^
FileNotFoundError: [Errno 2] No such file or directory: '/opt/airflow/data/key/None'
[2024-11-26T23:55:25.227+0000] {processor.py:842} WARNING - No viable dags retrieved from /opt/airflow/dags/postgres_to_bigquery_dag.py
[2024-11-26T23:55:25.270+0000] {processor.py:183} INFO - Processing /opt/airflow/dags/postgres_to_bigquery_dag.py took 1.425 seconds
[2024-11-26T23:55:55.587+0000] {processor.py:161} INFO - Started process (PID=1723) to work on /opt/airflow/dags/postgres_to_bigquery_dag.py
[2024-11-26T23:55:55.588+0000] {processor.py:830} INFO - Processing file /opt/airflow/dags/postgres_to_bigquery_dag.py for tasks to queue
[2024-11-26T23:55:55.591+0000] {logging_mixin.py:188} INFO - [2024-11-26T23:55:55.591+0000] {dagbag.py:545} INFO - Filling up the DagBag from /opt/airflow/dags/postgres_to_bigquery_dag.py
[2024-11-26T23:55:56.415+0000] {logging_mixin.py:188} INFO - [2024-11-26T23:55:56.410+0000] {dagbag.py:355} ERROR - Failed to import: /opt/airflow/dags/postgres_to_bigquery_dag.py
Traceback (most recent call last):
  File "/home/airflow/.local/lib/python3.12/site-packages/airflow/models/dagbag.py", line 351, in parse
    loader.exec_module(new_module)
  File "<frozen importlib._bootstrap_external>", line 995, in exec_module
  File "<frozen importlib._bootstrap>", line 488, in _call_with_frames_removed
  File "/opt/airflow/dags/postgres_to_bigquery_dag.py", line 40, in <module>
    credentials = service_account.Credentials.from_service_account_file(f"/opt/airflow/data/key/{getenv('key')}")
                  ^^^^^^^^^^^^^^^^^^^^^^^^^^^^^^^^^^^^^^^^^^^^^^^^^^^^^^^^^^^^^^^^^^^^^^^^^^^^^^^^^^^^^^^^^^^^^^^
  File "/home/airflow/.local/lib/python3.12/site-packages/google/oauth2/service_account.py", line 259, in from_service_account_file
    info, signer = _service_account_info.from_filename(
                   ^^^^^^^^^^^^^^^^^^^^^^^^^^^^^^^^^^^^
  File "/home/airflow/.local/lib/python3.12/site-packages/google/auth/_service_account_info.py", line 78, in from_filename
    with io.open(filename, "r", encoding="utf-8") as json_file:
         ^^^^^^^^^^^^^^^^^^^^^^^^^^^^^^^^^^^^^^^^
FileNotFoundError: [Errno 2] No such file or directory: '/opt/airflow/data/key/None'
[2024-11-26T23:55:56.416+0000] {processor.py:842} WARNING - No viable dags retrieved from /opt/airflow/dags/postgres_to_bigquery_dag.py
[2024-11-26T23:55:56.442+0000] {processor.py:183} INFO - Processing /opt/airflow/dags/postgres_to_bigquery_dag.py took 0.866 seconds
[2024-11-26T23:56:26.718+0000] {processor.py:161} INFO - Started process (PID=1741) to work on /opt/airflow/dags/postgres_to_bigquery_dag.py
[2024-11-26T23:56:26.720+0000] {processor.py:830} INFO - Processing file /opt/airflow/dags/postgres_to_bigquery_dag.py for tasks to queue
[2024-11-26T23:56:26.723+0000] {logging_mixin.py:188} INFO - [2024-11-26T23:56:26.723+0000] {dagbag.py:545} INFO - Filling up the DagBag from /opt/airflow/dags/postgres_to_bigquery_dag.py
[2024-11-26T23:56:27.759+0000] {logging_mixin.py:188} INFO - [2024-11-26T23:56:27.754+0000] {dagbag.py:355} ERROR - Failed to import: /opt/airflow/dags/postgres_to_bigquery_dag.py
Traceback (most recent call last):
  File "/home/airflow/.local/lib/python3.12/site-packages/airflow/models/dagbag.py", line 351, in parse
    loader.exec_module(new_module)
  File "<frozen importlib._bootstrap_external>", line 995, in exec_module
  File "<frozen importlib._bootstrap>", line 488, in _call_with_frames_removed
  File "/opt/airflow/dags/postgres_to_bigquery_dag.py", line 40, in <module>
    credentials = service_account.Credentials.from_service_account_file(f"/opt/airflow/data/key/{getenv('key')}")
                  ^^^^^^^^^^^^^^^^^^^^^^^^^^^^^^^^^^^^^^^^^^^^^^^^^^^^^^^^^^^^^^^^^^^^^^^^^^^^^^^^^^^^^^^^^^^^^^^
  File "/home/airflow/.local/lib/python3.12/site-packages/google/oauth2/service_account.py", line 259, in from_service_account_file
    info, signer = _service_account_info.from_filename(
                   ^^^^^^^^^^^^^^^^^^^^^^^^^^^^^^^^^^^^
  File "/home/airflow/.local/lib/python3.12/site-packages/google/auth/_service_account_info.py", line 78, in from_filename
    with io.open(filename, "r", encoding="utf-8") as json_file:
         ^^^^^^^^^^^^^^^^^^^^^^^^^^^^^^^^^^^^^^^^
FileNotFoundError: [Errno 2] No such file or directory: '/opt/airflow/data/key/None'
[2024-11-26T23:56:27.760+0000] {processor.py:842} WARNING - No viable dags retrieved from /opt/airflow/dags/postgres_to_bigquery_dag.py
[2024-11-26T23:56:27.788+0000] {processor.py:183} INFO - Processing /opt/airflow/dags/postgres_to_bigquery_dag.py took 1.081 seconds
[2024-11-26T23:56:58.050+0000] {processor.py:161} INFO - Started process (PID=1759) to work on /opt/airflow/dags/postgres_to_bigquery_dag.py
[2024-11-26T23:56:58.051+0000] {processor.py:830} INFO - Processing file /opt/airflow/dags/postgres_to_bigquery_dag.py for tasks to queue
[2024-11-26T23:56:58.054+0000] {logging_mixin.py:188} INFO - [2024-11-26T23:56:58.053+0000] {dagbag.py:545} INFO - Filling up the DagBag from /opt/airflow/dags/postgres_to_bigquery_dag.py
[2024-11-26T23:56:59.134+0000] {logging_mixin.py:188} INFO - [2024-11-26T23:56:59.128+0000] {dagbag.py:355} ERROR - Failed to import: /opt/airflow/dags/postgres_to_bigquery_dag.py
Traceback (most recent call last):
  File "/home/airflow/.local/lib/python3.12/site-packages/airflow/models/dagbag.py", line 351, in parse
    loader.exec_module(new_module)
  File "<frozen importlib._bootstrap_external>", line 995, in exec_module
  File "<frozen importlib._bootstrap>", line 488, in _call_with_frames_removed
  File "/opt/airflow/dags/postgres_to_bigquery_dag.py", line 40, in <module>
    credentials = service_account.Credentials.from_service_account_file(f"/opt/airflow/data/key/{getenv('key')}")
                  ^^^^^^^^^^^^^^^^^^^^^^^^^^^^^^^^^^^^^^^^^^^^^^^^^^^^^^^^^^^^^^^^^^^^^^^^^^^^^^^^^^^^^^^^^^^^^^^
  File "/home/airflow/.local/lib/python3.12/site-packages/google/oauth2/service_account.py", line 259, in from_service_account_file
    info, signer = _service_account_info.from_filename(
                   ^^^^^^^^^^^^^^^^^^^^^^^^^^^^^^^^^^^^
  File "/home/airflow/.local/lib/python3.12/site-packages/google/auth/_service_account_info.py", line 78, in from_filename
    with io.open(filename, "r", encoding="utf-8") as json_file:
         ^^^^^^^^^^^^^^^^^^^^^^^^^^^^^^^^^^^^^^^^
FileNotFoundError: [Errno 2] No such file or directory: '/opt/airflow/data/key/None'
[2024-11-26T23:56:59.135+0000] {processor.py:842} WARNING - No viable dags retrieved from /opt/airflow/dags/postgres_to_bigquery_dag.py
[2024-11-26T23:56:59.165+0000] {processor.py:183} INFO - Processing /opt/airflow/dags/postgres_to_bigquery_dag.py took 1.122 seconds
[2024-11-26T23:57:29.518+0000] {processor.py:161} INFO - Started process (PID=1777) to work on /opt/airflow/dags/postgres_to_bigquery_dag.py
[2024-11-26T23:57:29.519+0000] {processor.py:830} INFO - Processing file /opt/airflow/dags/postgres_to_bigquery_dag.py for tasks to queue
[2024-11-26T23:57:29.522+0000] {logging_mixin.py:188} INFO - [2024-11-26T23:57:29.522+0000] {dagbag.py:545} INFO - Filling up the DagBag from /opt/airflow/dags/postgres_to_bigquery_dag.py
[2024-11-26T23:57:30.889+0000] {logging_mixin.py:188} INFO - [2024-11-26T23:57:30.884+0000] {dagbag.py:355} ERROR - Failed to import: /opt/airflow/dags/postgres_to_bigquery_dag.py
Traceback (most recent call last):
  File "/home/airflow/.local/lib/python3.12/site-packages/airflow/models/dagbag.py", line 351, in parse
    loader.exec_module(new_module)
  File "<frozen importlib._bootstrap_external>", line 995, in exec_module
  File "<frozen importlib._bootstrap>", line 488, in _call_with_frames_removed
  File "/opt/airflow/dags/postgres_to_bigquery_dag.py", line 40, in <module>
    credentials = service_account.Credentials.from_service_account_file(f"/opt/airflow/data/key/{getenv('key')}")
                  ^^^^^^^^^^^^^^^^^^^^^^^^^^^^^^^^^^^^^^^^^^^^^^^^^^^^^^^^^^^^^^^^^^^^^^^^^^^^^^^^^^^^^^^^^^^^^^^
  File "/home/airflow/.local/lib/python3.12/site-packages/google/oauth2/service_account.py", line 259, in from_service_account_file
    info, signer = _service_account_info.from_filename(
                   ^^^^^^^^^^^^^^^^^^^^^^^^^^^^^^^^^^^^
  File "/home/airflow/.local/lib/python3.12/site-packages/google/auth/_service_account_info.py", line 78, in from_filename
    with io.open(filename, "r", encoding="utf-8") as json_file:
         ^^^^^^^^^^^^^^^^^^^^^^^^^^^^^^^^^^^^^^^^
FileNotFoundError: [Errno 2] No such file or directory: '/opt/airflow/data/key/None'
[2024-11-26T23:57:30.890+0000] {processor.py:842} WARNING - No viable dags retrieved from /opt/airflow/dags/postgres_to_bigquery_dag.py
[2024-11-26T23:57:30.925+0000] {processor.py:183} INFO - Processing /opt/airflow/dags/postgres_to_bigquery_dag.py took 1.416 seconds
[2024-11-26T23:58:01.250+0000] {processor.py:161} INFO - Started process (PID=1801) to work on /opt/airflow/dags/postgres_to_bigquery_dag.py
[2024-11-26T23:58:01.252+0000] {processor.py:830} INFO - Processing file /opt/airflow/dags/postgres_to_bigquery_dag.py for tasks to queue
[2024-11-26T23:58:01.254+0000] {logging_mixin.py:188} INFO - [2024-11-26T23:58:01.253+0000] {dagbag.py:545} INFO - Filling up the DagBag from /opt/airflow/dags/postgres_to_bigquery_dag.py
[2024-11-26T23:58:02.381+0000] {logging_mixin.py:188} INFO - [2024-11-26T23:58:02.366+0000] {dagbag.py:355} ERROR - Failed to import: /opt/airflow/dags/postgres_to_bigquery_dag.py
Traceback (most recent call last):
  File "/home/airflow/.local/lib/python3.12/site-packages/airflow/models/dagbag.py", line 351, in parse
    loader.exec_module(new_module)
  File "<frozen importlib._bootstrap_external>", line 995, in exec_module
  File "<frozen importlib._bootstrap>", line 488, in _call_with_frames_removed
  File "/opt/airflow/dags/postgres_to_bigquery_dag.py", line 40, in <module>
    credentials = service_account.Credentials.from_service_account_file(f"/opt/airflow/data/key/{getenv('key')}")
                  ^^^^^^^^^^^^^^^^^^^^^^^^^^^^^^^^^^^^^^^^^^^^^^^^^^^^^^^^^^^^^^^^^^^^^^^^^^^^^^^^^^^^^^^^^^^^^^^
  File "/home/airflow/.local/lib/python3.12/site-packages/google/oauth2/service_account.py", line 259, in from_service_account_file
    info, signer = _service_account_info.from_filename(
                   ^^^^^^^^^^^^^^^^^^^^^^^^^^^^^^^^^^^^
  File "/home/airflow/.local/lib/python3.12/site-packages/google/auth/_service_account_info.py", line 78, in from_filename
    with io.open(filename, "r", encoding="utf-8") as json_file:
         ^^^^^^^^^^^^^^^^^^^^^^^^^^^^^^^^^^^^^^^^
FileNotFoundError: [Errno 2] No such file or directory: '/opt/airflow/data/key/None'
[2024-11-26T23:58:02.389+0000] {processor.py:842} WARNING - No viable dags retrieved from /opt/airflow/dags/postgres_to_bigquery_dag.py
[2024-11-26T23:58:02.427+0000] {processor.py:183} INFO - Processing /opt/airflow/dags/postgres_to_bigquery_dag.py took 1.184 seconds
[2024-11-26T23:58:32.723+0000] {processor.py:161} INFO - Started process (PID=1819) to work on /opt/airflow/dags/postgres_to_bigquery_dag.py
[2024-11-26T23:58:32.725+0000] {processor.py:830} INFO - Processing file /opt/airflow/dags/postgres_to_bigquery_dag.py for tasks to queue
[2024-11-26T23:58:32.728+0000] {logging_mixin.py:188} INFO - [2024-11-26T23:58:32.728+0000] {dagbag.py:545} INFO - Filling up the DagBag from /opt/airflow/dags/postgres_to_bigquery_dag.py
[2024-11-26T23:58:33.589+0000] {logging_mixin.py:188} INFO - [2024-11-26T23:58:33.580+0000] {dagbag.py:355} ERROR - Failed to import: /opt/airflow/dags/postgres_to_bigquery_dag.py
Traceback (most recent call last):
  File "/home/airflow/.local/lib/python3.12/site-packages/airflow/models/dagbag.py", line 351, in parse
    loader.exec_module(new_module)
  File "<frozen importlib._bootstrap_external>", line 995, in exec_module
  File "<frozen importlib._bootstrap>", line 488, in _call_with_frames_removed
  File "/opt/airflow/dags/postgres_to_bigquery_dag.py", line 40, in <module>
    credentials = service_account.Credentials.from_service_account_file(f"/opt/airflow/data/key/{getenv('key')}")
                  ^^^^^^^^^^^^^^^^^^^^^^^^^^^^^^^^^^^^^^^^^^^^^^^^^^^^^^^^^^^^^^^^^^^^^^^^^^^^^^^^^^^^^^^^^^^^^^^
  File "/home/airflow/.local/lib/python3.12/site-packages/google/oauth2/service_account.py", line 259, in from_service_account_file
    info, signer = _service_account_info.from_filename(
                   ^^^^^^^^^^^^^^^^^^^^^^^^^^^^^^^^^^^^
  File "/home/airflow/.local/lib/python3.12/site-packages/google/auth/_service_account_info.py", line 78, in from_filename
    with io.open(filename, "r", encoding="utf-8") as json_file:
         ^^^^^^^^^^^^^^^^^^^^^^^^^^^^^^^^^^^^^^^^
FileNotFoundError: [Errno 2] No such file or directory: '/opt/airflow/data/key/None'
[2024-11-26T23:58:33.590+0000] {processor.py:842} WARNING - No viable dags retrieved from /opt/airflow/dags/postgres_to_bigquery_dag.py
[2024-11-26T23:58:33.620+0000] {processor.py:183} INFO - Processing /opt/airflow/dags/postgres_to_bigquery_dag.py took 0.909 seconds
[2024-11-26T23:59:03.891+0000] {processor.py:161} INFO - Started process (PID=1837) to work on /opt/airflow/dags/postgres_to_bigquery_dag.py
[2024-11-26T23:59:03.892+0000] {processor.py:830} INFO - Processing file /opt/airflow/dags/postgres_to_bigquery_dag.py for tasks to queue
[2024-11-26T23:59:03.895+0000] {logging_mixin.py:188} INFO - [2024-11-26T23:59:03.894+0000] {dagbag.py:545} INFO - Filling up the DagBag from /opt/airflow/dags/postgres_to_bigquery_dag.py
[2024-11-26T23:59:04.962+0000] {logging_mixin.py:188} INFO - [2024-11-26T23:59:04.951+0000] {dagbag.py:355} ERROR - Failed to import: /opt/airflow/dags/postgres_to_bigquery_dag.py
Traceback (most recent call last):
  File "/home/airflow/.local/lib/python3.12/site-packages/airflow/models/dagbag.py", line 351, in parse
    loader.exec_module(new_module)
  File "<frozen importlib._bootstrap_external>", line 995, in exec_module
  File "<frozen importlib._bootstrap>", line 488, in _call_with_frames_removed
  File "/opt/airflow/dags/postgres_to_bigquery_dag.py", line 40, in <module>
    credentials = service_account.Credentials.from_service_account_file(f"/opt/airflow/data/key/{getenv('key')}")
                  ^^^^^^^^^^^^^^^^^^^^^^^^^^^^^^^^^^^^^^^^^^^^^^^^^^^^^^^^^^^^^^^^^^^^^^^^^^^^^^^^^^^^^^^^^^^^^^^
  File "/home/airflow/.local/lib/python3.12/site-packages/google/oauth2/service_account.py", line 259, in from_service_account_file
    info, signer = _service_account_info.from_filename(
                   ^^^^^^^^^^^^^^^^^^^^^^^^^^^^^^^^^^^^
  File "/home/airflow/.local/lib/python3.12/site-packages/google/auth/_service_account_info.py", line 78, in from_filename
    with io.open(filename, "r", encoding="utf-8") as json_file:
         ^^^^^^^^^^^^^^^^^^^^^^^^^^^^^^^^^^^^^^^^
FileNotFoundError: [Errno 2] No such file or directory: '/opt/airflow/data/key/None'
[2024-11-26T23:59:04.964+0000] {processor.py:842} WARNING - No viable dags retrieved from /opt/airflow/dags/postgres_to_bigquery_dag.py
[2024-11-26T23:59:04.995+0000] {processor.py:183} INFO - Processing /opt/airflow/dags/postgres_to_bigquery_dag.py took 1.113 seconds
[2024-11-26T23:59:35.281+0000] {processor.py:161} INFO - Started process (PID=1855) to work on /opt/airflow/dags/postgres_to_bigquery_dag.py
[2024-11-26T23:59:35.283+0000] {processor.py:830} INFO - Processing file /opt/airflow/dags/postgres_to_bigquery_dag.py for tasks to queue
[2024-11-26T23:59:35.285+0000] {logging_mixin.py:188} INFO - [2024-11-26T23:59:35.285+0000] {dagbag.py:545} INFO - Filling up the DagBag from /opt/airflow/dags/postgres_to_bigquery_dag.py
[2024-11-26T23:59:36.189+0000] {logging_mixin.py:188} INFO - [2024-11-26T23:59:36.183+0000] {dagbag.py:355} ERROR - Failed to import: /opt/airflow/dags/postgres_to_bigquery_dag.py
Traceback (most recent call last):
  File "/home/airflow/.local/lib/python3.12/site-packages/airflow/models/dagbag.py", line 351, in parse
    loader.exec_module(new_module)
  File "<frozen importlib._bootstrap_external>", line 995, in exec_module
  File "<frozen importlib._bootstrap>", line 488, in _call_with_frames_removed
  File "/opt/airflow/dags/postgres_to_bigquery_dag.py", line 40, in <module>
    credentials = service_account.Credentials.from_service_account_file(f"/opt/airflow/data/key/{getenv('key')}")
                  ^^^^^^^^^^^^^^^^^^^^^^^^^^^^^^^^^^^^^^^^^^^^^^^^^^^^^^^^^^^^^^^^^^^^^^^^^^^^^^^^^^^^^^^^^^^^^^^
  File "/home/airflow/.local/lib/python3.12/site-packages/google/oauth2/service_account.py", line 259, in from_service_account_file
    info, signer = _service_account_info.from_filename(
                   ^^^^^^^^^^^^^^^^^^^^^^^^^^^^^^^^^^^^
  File "/home/airflow/.local/lib/python3.12/site-packages/google/auth/_service_account_info.py", line 78, in from_filename
    with io.open(filename, "r", encoding="utf-8") as json_file:
         ^^^^^^^^^^^^^^^^^^^^^^^^^^^^^^^^^^^^^^^^
FileNotFoundError: [Errno 2] No such file or directory: '/opt/airflow/data/key/None'
[2024-11-26T23:59:36.191+0000] {processor.py:842} WARNING - No viable dags retrieved from /opt/airflow/dags/postgres_to_bigquery_dag.py
[2024-11-26T23:59:36.229+0000] {processor.py:183} INFO - Processing /opt/airflow/dags/postgres_to_bigquery_dag.py took 0.955 seconds
